Workbook

Sheet PVP VaP - Pyme
B2: OFERTA TÁCTICA EMPRESAS | H2: Pago Único | J2: CAPTA | M2: PORTABILIDAD
B4: 45627 | C4: 01/12 al 31/12 | J4: - | M4: ENTRADA PRO | O4: NORMAL PRO | Q4: VALOR PRO | S4: PREMIUM PRO | U4: TOP PRO
B5: 1. CONDICIONES DE LA OFERTA VENTA A PLAZOS (según tarifa y situación del cliente) | D5: Tarifas | H5: Todas Tarifas | J5: - | M5: T. Optima Plus Empresas T. Optima Plus Empresas Big + Empresas Voz y Empresas 1 | O5: T. Optima Plus Empresas T. Optima Plus Empresas Big + Empresas 5 y Empresas Intranet | Q5: T. Optima Plus Empresas T. Optima Plus Empresas Big + Empresas 20 | S5: T. Optima Plus Empresas T. Optima Plus Empresas Big + Empresas Infinita | U5: T. Optima Plus Empresas T. Optima Plus Empresas Big + Empresas Internacional
D13: Ampliaciones (meses antigüedad) | H13: Todos | J13: cliente -4 M, solo accede a Pago Único | M13: + 4 M | O13: + 4 M | Q13: + 4 M | S13: + 4 M | U13: + 4 M
D14: Origen (Portabilidad / Migración) | H14: Pos | J14: Capta de cliente nuevo, solo accede a Pago Único | M14: Pospago | O14: Pospago | Q14: Pospago | S14: Pospago | U14: Pospago
D15: CP Tarifa | H15: 24 M | J15: - | M15: 24 M | O15: 24 M | Q15: 24 M | S15: 24 M | U15: 24 M
D16: CP Terminal | H16: - | J16: - | M16: 24 M | O16: 24 M | Q16: 24 M | S16: 24 M | U16: 24 M | AN16: DIFERENCIAS Vs MES ANTERIOR
AN17: 6 | AO17: 7 | AP17: 8 | AQ17: 9 | AR17: 10 | AS17: 11 | AT17: 12 | AU17: 13 | AV17: 14 | AW17: 15 | AX17: 16 | AY17: 17 | AZ17: 18 | BA17: 19 | BB17: 20
B18: 2. PRECIO DEL TERMINAL POR GRUPO DE TARIFAS | H18: Pago Único | J18: PVPR CAPTA (tarifas móvil y convergentes) | M18: PVPR PORTABILIDAD | X18: DxC Pago Único | Z18: DxC CAPTA (tarifas móvil y convergentes) | AC18: DxC PORTABILIDAD | AN18: Pago Único | AP18: PVPR CAPTA (tarifas móvil y convergentes) | AS18: PVPR PORTABILIDAD
M20: GRUPOS DE TARIFAS MÓVIL | AC20: GRUPOS DE TARIFAS MÓVIL | AS20: GRUPOS DE TARIFAS MÓVIL
J22: - | M22: ENTRADA PRO | O22: NORMAL PRO | Q22: VALOR PRO | S22: PREMIUM PRO | U22: TOP PRO | Z22: - | AC22: ENTRADA PRO | AE22: NORMAL PRO | AG22: VALOR PRO | AI22: PREMIUM PRO | AK22: TOP PRO | AP22: ENTRADA PRO | AS22: ENTRADA PRO | AU22: NORMAL PRO | AW22: VALOR PRO | AY22: PREMIUM PRO | BA22: TOP PRO
B24: MARCA | C24: Modelo (Novedades) | D24: Precio Cesión | E24: Canon Digital | F24: Gama | G24: Meses Cuota | H24: Pago Unico (sin IVA) | J24: Pago Inicial (sin IVA) | K24: Cuota Mes (sin IVA) | M24: Pago Inicial (sin IVA) | N24: Cuota Mes (sin IVA) | O24: Pago Inicial (sin IVA) | P24: Cuota Mes (sin IVA) | Q24: Pago Inicial (sin IVA) | R24: Cuota Mes (sin IVA) | S24: Pago Inicial (sin IVA) | T24: Cuota Mes (sin IVA) | U24: Pago Inicial (sin IVA) | V24: Cuota Mes (sin IVA) | X24: DxC Pago Unico | Z24: DxC Precio | AA24: DxC VaP | AC24: DxC Precio | AD24: DxC VaP | AE24: DxC Precio | AF24: DxC VaP | AG24: DxC Precio | AH24: DxC VaP | AI24: DxC Precio | AJ24: DxC VaP | AK24: DxC Precio | AL24: DxC VaP | AN24: Pago Unico (sin IVA) | AP24: Pago Inicial (sin IVA) | AQ24: Cuota Mes (sin IVA) | AS24: Pago Inicial (sin IVA) | AT24: Cuota Mes (sin IVA) | AU24: Pago Inicial (sin IVA) | AV24: Cuota Mes (sin IVA) | AW24: Pago Inicial (sin IVA) | AX24: Cuota Mes (sin IVA) | AY24: Pago Inicial (sin IVA) | AZ24: Cuota Mes (sin IVA) | BA24: Pago Inicial (sin IVA) | BB24: Cuota Mes (sin IVA)
B25: ORANGE | C25: AD HOC H3 CESIÓN | D25: 0 | E25: 1.1 | F25: FIXED STYLE | G25: - | H25: - | J25: - | K25: - | M25: - | N25: - | O25: - | P25: - | Q25: - | R25: - | S25: - | T25: - | U25: - | V25: - | X25: 0 | Z25: 0 | AA25: 0 | AC25: 0 | AD25: 0 | AE25: 0 | AF25: 0 | AG25: 0 | AH25: 0 | AI25: 0 | AJ25: 0 | AK25: 0 | AL25: 0 | AN25: 0 | AP25: 0 | AQ25: 0 | AS25: 0 | AT25: 0 | AU25: 0 | AV25: 0 | AW25: 0 | AX25: 0 | AY25: 0 | AZ25: 0 | BA25: 0 | BB25: 0
B26: ORANGE | C26: ADOC D30 | D26: 239 | E26: 3.75 | F26: FIXED STYLE | G26: 24 | H26: 280 | J26: - | K26: - | M26: 0 | N26: 7.3 | O26: 0 | P26: 5.9 | Q26: 0 | R26: 2.5 | S26: 0 | T26: 0 | U26: 0 | V26: 0 | X26: -41 | Z26: 0 | AA26: 0 | AC26: 64 | AD26: 175 | AE26: 97 | AF26: 142 | AG26: 179 | AH26: 60 | AI26: 239 | AJ26: 0 | AK26: 239 | AL26: 0 | AN26: 0 | AP26: 0 | AQ26: 0 | AS26: 0 | AT26: 0 | AU26: 0 | AV26: 0 | AW26: 0 | AX26: 0 | AY26: 0 | AZ26: 0 | BA26: 0 | BB26: 0
B27: ORANGE | C27: ADOC D30 CESIÓN | D27: 0 | E27: 3.75 | F27: FIXED STYLE | G27: - | H27: - | J27: - | K27: - | M27: - | N27: - | O27: - | P27: - | Q27: - | R27: - | S27: - | T27: - | U27: - | V27: - | X27: 0 | Z27: 0 | AA27: 0 | AC27: 0 | AD27: 0 | AE27: 0 | AF27: 0 | AG27: 0 | AH27: 0 | AI27: 0 | AJ27: 0 | AK27: 0 | AL27: 0 | AN27: 0 | AP27: 0 | AQ27: 0 | AS27: 0 | AT27: 0 | AU27: 0 | AV27: 0 | AW27: 0 | AX27: 0 | AY27: 0 | AZ27: 0 | BA27: 0 | BB27: 0
B28: AD HOC | C28: ADOC SC01 | D28: 64 | E28: 1.1 | F28: VOZ | G28: - | H28: - | J28: - | K28: - | M28: - | N28: - | O28: - | P28: - | Q28: - | R28: - | S28: - | T28: - | U28: - | V28: - | X28: 0 | Z28: 0 | AA28: 0 | AC28: 0 | AD28: 0 | AE28: 0 | AF28: 0 | AG28: 0 | AH28: 0 | AI28: 0 | AJ28: 0 | AK28: 0 | AL28: 0 | AN28: 0 | AP28: 0 | AQ28: 0 | AS28: 0 | AT28: 0 | AU28: 0 | AV28: 0 | AW28: 0 | AX28: 0 | AY28: 0 | AZ28: 0 | BA28: 0 | BB28: 0
B29: ADOC | C29: ADOC SC04 | D29: 77 | E29: 1.1 | F29: VOZ | G29: 24 | H29: 93 | J29: - | K29: - | M29: 0 | N29: 0 | O29: 0 | P29: 0 | Q29: 0 | R29: 0 | S29: 0 | T29: 0 | U29: 0 | V29: 0 | X29: -16 | Z29: 0 | AA29: 0 | AC29: 77 | AD29: 0 | AE29: 77 | AF29: 0 | AG29: 77 | AH29: 0 | AI29: 77 | AJ29: 0 | AK29: 77 | AL29: 0 | AN29: 0 | AP29: 0 | AQ29: 0 | AS29: 0 | AT29: 0 | AU29: 0 | AV29: 0 | AW29: 0 | AX29: 0 | AY29: 0 | AZ29: 0 | BA29: 0 | BB29: 0
B30: APPLE | C30: APPLE AIRPODS 4 | D30: 137 | E30: 0 | F30: OC_AURICULARES | G30: 24 | H30: 165 | J30: - | K30: - | M30: 0 | N30: 4 | O30: 0 | P30: 2.6 | Q30: 0 | R30: 0 | S30: 0 | T30: 0 | U30: 0 | V30: 0 | X30: -28 | Z30: 0 | AA30: 0 | AC30: 41 | AD30: 96 | AE30: 75 | AF30: 62 | AG30: 137 | AH30: 0 | AI30: 137 | AJ30: 0 | AK30: 137 | AL30: 0 | AN30: 0 | AP30: 0 | AQ30: 0 | AS30: 0 | AT30: 0 | AU30: 0 | AV30: 0 | AW30: 0 | AX30: 0 | AY30: 0 | AZ30: 0 | BA30: 0 | BB30: 0
B31: APPLE | C31: APPLE AIRPODS 4 CON CANCELACION ACTIVA RUIDO | D31: 184 | E31: 0 | F31: OC_AURICULARES | G31: 24 | H31: 222 | J31: - | K31: - | M31: 0 | N31: 5.6 | O31: 0 | P31: 4.2 | Q31: 0 | R31: 0 | S31: 0 | T31: 0 | U31: 0 | V31: 0 | X31: -38 | Z31: 0 | AA31: 0 | AC31: 50 | AD31: 134 | AE31: 83 | AF31: 101 | AG31: 184 | AH31: 0 | AI31: 184 | AJ31: 0 | AK31: 184 | AL31: 0 | AN31: 0 | AP31: 0 | AQ31: 0 | AS31: 0 | AT31: 0 | AU31: 0 | AV31: 0 | AW31: 0 | AX31: 0 | AY31: 0 | AZ31: 0 | BA31: 0 | BB31: 0
B32: APPLE | C32: APPLE AIRPODS PRO 2a GENERACION MAGSAFE USBC | D32: 279 | E32: 0 | F32: OC_AURICULARES | G32: 24 | H32: 336 | J32: - | K32: - | M32: 0 | N32: 8.1 | O32: 0 | P32: 6.7 | Q32: 0 | R32: 3.4 | S32: 0 | T32: 1.8 | U32: 0 | V32: 0 | X32: -57 | Z32: 0 | AA32: 0 | AC32: 85 | AD32: 194 | AE32: 118 | AF32: 161 | AG32: 197 | AH32: 82 | AI32: 236 | AJ32: 43 | AK32: 279 | AL32: 0 | AN32: 0 | AP32: 0 | AQ32: 0 | AS32: 0 | AT32: 0 | AU32: 0 | AV32: 0 | AW32: 0 | AX32: 0 | AY32: 0 | AZ32: 0 | BA32: 0 | BB32: 0
B33: APPLE | C33: APPLE WATCH S10 CELLULAR 42MM | D33: 532 | E33: 2.5 | F33: OC_SMART WATCH | G33: 24 | H33: 643 | J33: - | K33: - | M33: 39 | N33: 16.4 | O33: 19 | P33: 15.6 | Q33: 0 | R33: 13.1 | S33: 0 | T33: 11.5 | U33: 0 | V33: 6.8 | X33: -111 | Z33: 0 | AA33: 0 | AC33: 99 | AD33: 394 | AE33: 139 | AF33: 374 | AG33: 218 | AH33: 314 | AI33: 256 | AJ33: 276 | AK33: 369 | AL33: 163 | AN33: 0 | AP33: 0 | AQ33: 0 | AS33: 0 | AT33: 0 | AU33: 0 | AV33: 0 | AW33: 0 | AX33: 0 | AY33: 0 | AZ33: 0 | BA33: 0 | BB33: 0
B34: APPLE | C34: APPLE WATCH S10 CELLULAR 46MM | D34: 555 | E34: 2.5 | F34: OC_SMART WATCH | G34: 24 | H34: 671 | J34: - | K34: - | M34: 39 | N34: 17.4 | O34: 19 | P34: 16.6 | Q34: 0 | R34: 14.1 | S34: 0 | T34: 12.4 | U34: 0 | V34: 7.8 | X34: -116 | Z34: 0 | AA34: 0 | AC34: 98 | AD34: 418 | AE34: 138 | AF34: 398 | AG34: 217 | AH34: 338 | AI34: 257 | AJ34: 298 | AK34: 368 | AL34: 187 | AN34: 0 | AP34: 0 | AQ34: 0 | AS34: 0 | AT34: 0 | AU34: 0 | AV34: 0 | AW34: 0 | AX34: 0 | AY34: 0 | AZ34: 0 | BA34: 0 | BB34: 0
B35: APPLE | C35: APPLE WATCH S9 CELLULAR 45MM | D35: 555 | E35: 2.5 | F35: OC_SMART WATCH | G35: 24 | H35: 671 | J35: - | K35: - | M35: 39 | N35: 17.4 | O35: 19 | P35: 16.6 | Q35: 0 | R35: 14.1 | S35: 0 | T35: 12.4 | U35: 0 | V35: 7.8 | X35: -116 | Z35: 0 | AA35: 0 | AC35: 98 | AD35: 418 | AE35: 138 | AF35: 398 | AG35: 217 | AH35: 338 | AI35: 257 | AJ35: 298 | AK35: 368 | AL35: 187 | AN35: 0 | AP35: 0 | AQ35: 0 | AS35: 0 | AT35: 0 | AU35: 0 | AV35: 0 | AW35: 0 | AX35: 0 | AY35: 0 | AZ35: 0 | BA35: 0 | BB35: 0
B36: AD HOC | C36: AURICULARES AD HOC BT01 | D36: 71 | E36: 0 | F36: OC_AURICULARES | G36: 24 | H36: 57.024793 | J36: - | K36: - | M36: 0 | N36: 0 | O36: 0 | P36: 0 | Q36: 0 | R36: 0 | S36: 0 | T36: 0 | U36: 0 | V36: 0 | X36: 14 | Z36: 0 | AA36: 0 | AC36: 71 | AD36: 0 | AE36: 71 | AF36: 0 | AG36: 71 | AH36: 0 | AI36: 71 | AJ36: 0 | AK36: 71 | AL36: 0 | AN36: 0 | AP36: 0 | AQ36: 0 | AS36: 0 | AT36: 0 | AU36: 0 | AV36: 0 | AW36: 0 | AX36: 0 | AY36: 0 | AZ36: 0 | BA36: 0 | BB36: 0
B37: AD HOC | C37: AURICULARES AD HOC HC01 | D37: 49 | E37: 0 | F37: OC_AURICULARES | G37: 24 | H37: 35.53719 | J37: - | K37: - | M37: 0 | N37: 0 | O37: 0 | P37: 0 | Q37: 0 | R37: 0 | S37: 0 | T37: 0 | U37: 0 | V37: 0 | X37: 13 | Z37: 0 | AA37: 0 | AC37: 49 | AD37: 0 | AE37: 49 | AF37: 0 | AG37: 49 | AH37: 0 | AI37: 49 | AJ37: 0 | AK37: 49 | AL37: 0 | AN37: 0 | AP37: 0 | AQ37: 0 | AS37: 0 | AT37: 0 | AU37: 0 | AV37: 0 | AW37: 0 | AX37: 0 | AY37: 0 | AZ37: 0 | BA37: 0 | BB37: 0
B38: SAMSUNG | C38: AURICULARES SAMSUNG GALAXY BUDS 3 | D38: 172 | E38: 0 | F38: OC_AURICULARES | G38: 24 | H38: 158 | J38: - | K38: - | M38: 0 | N38: 3.7 | O38: 0 | P38: 2.3 | Q38: 0 | R38: 0 | S38: 0 | T38: 0 | U38: 0 | V38: 0 | X38: 14 | Z38: 0 | AA38: 0 | AC38: 83 | AD38: 89 | AE38: 117 | AF38: 55 | AG38: 172 | AH38: 0 | AI38: 172 | AJ38: 0 | AK38: 172 | AL38: 0 | AN38: 0 | AP38: 0 | AQ38: 0 | AS38: 0 | AT38: 0 | AU38: 0 | AV38: 0 | AW38: 0 | AX38: 0 | AY38: 0 | AZ38: 0 | BA38: 0 | BB38: 0
B39: SAMSUNG | C39: AURICULARES SAMSUNG GALAXY BUDS 3 PRO | D39: 240 | E39: 0 | F39: OC_AURICULARES | G39: 24 | H39: 227 | J39: - | K39: - | M39: 0 | N39: 5.8 | O39: 0 | P39: 4.4 | Q39: 0 | R39: 1 | S39: 0 | T39: 0 | U39: 0 | V39: 0 | X39: 13 | Z39: 0 | AA39: 0 | AC39: 101 | AD39: 139 | AE39: 134 | AF39: 106 | AG39: 216 | AH39: 24 | AI39: 240 | AJ39: 0 | AK39: 240 | AL39: 0 | AN39: 0 | AP39: 0 | AQ39: 0 | AS39: 0 | AT39: 0 | AU39: 0 | AV39: 0 | AW39: 0 | AX39: 0 | AY39: 0 | AZ39: 0 | BA39: 0 | BB39: 0
B40: SPC | C40: AURICULARES SPC BRAVE PRO | D40: 44 | E40: 0 | F40: OC_AURICULARES | G40: 24 | H40: 47.933884 | J40: - | K40: - | M40: 0 | N40: 0 | O40: 0 | P40: 0 | Q40: 0 | R40: 0 | S40: 0 | T40: 0 | U40: 0 | V40: 0 | X40: -4 | Z40: 0 | AA40: 0 | AC40: 44 | AD40: 0 | AE40: 44 | AF40: 0 | AG40: 44 | AH40: 0 | AI40: 44 | AJ40: 0 | AK40: 44 | AL40: 0 | AN40: 0 | AP40: 0 | AQ40: 0 | AS40: 0 | AT40: 0 | AU40: 0 | AV40: 0 | AW40: 0 | AX40: 0 | AY40: 0 | AZ40: 0 | BA40: 0 | BB40: 0
... B46: GOOGLE | C46: GOOGLE PIXEL 9 128GB 5G | D46: 823 | E46: 3.25 | F46: SMARTPHONE | G46: 24 | H46: 795 | J46: - | K46: - | M46: 39 | N46: 21.9 | O46: 19 | P46: 21 | Q46: 0 | R46: 18.5 | S46: 0 | T46: 15.8 | U46: 0 | V46: 10.9 | X46: 28 | Z46: 0 | AA46: 0 | AC46: 258 | AD46: 526 | AE46: 300 | AF46: 504 | AG46: 379 | AH46: 444 | AI46: 444 | AJ46: 379 | AK46: 561 | AL46: 262 | AN46: 0 | AP46: 0 | AQ46: 0 | AS46: 0 | AT46: 0 | AU46: 0 | AV46: 0 | AW46: 0 | AX46: 0 | AY46: 0 | AZ46: 0 | BA46: 0 | BB46: 0
B47: GOOGLE | C47: GOOGLE PIXEL 9 PRO 256GB 5G | D47: 1062 | E47: 3.25 | F47: SMARTPHONE | G47: 24 | H47: 1060 | J47: - | K47: - | M47: - | N47: - | O47: 49 | P47: 26.9 | Q47: 39 | R47: 24 | S47: 0 | T47: 23 | U47: 0 | V47: 18.1 | X47: 2 | Z47: 0 | AA47: 0 | AC47: 0 | AD47: 0 | AE47: 367 | AF47: 646 | AG47: 447 | AH47: 576 | AI47: 510 | AJ47: 552 | AK47: 628 | AL47: 434 | AN47: 0 | AP47: 0 | AQ47: 0 | AS47: 0 | AT47: 0 | AU47: 0 | AV47: 0 | AW47: 0 | AX47: 0 | AY47: 0 | AZ47: 0 | BA47: 0 | BB47: 0
B48: GOOGLE | C48: GOOGLE PIXEL 9 PRO XL 512GB 5G | D48: 1234 | E48: 3.25 | F48: SMARTPHONE | G48: 24 | H48: 1233 | J48: - | K48: - | M48: - | N48: - | O48: 79 | P48: 31.9 | Q48: 39 | R48: 30.2 | S48: 0 | T48: 29.2 | U48: 0 | V48: 24.3 | X48: 1 | Z48: 0 | AA48: 0 | AC48: 0 | AD48: 0 | AE48: 389 | AF48: 766 | AG48: 470 | AH48: 725 | AI48: 533 | AJ48: 701 | AK48: 651 | AL48: 583 | AN48: 0 | AP48: 0 | AQ48: 0 | AS48: 0 | AT48: 0 | AU48: 0 | AV48: 0 | AW48: 0 | AX48: 0 | AY48: 0 | AZ48: 0 | BA48: 0 | BB48: 0
B49: HONOR | C49: HONOR 200 512GB 5G | D49: 539 | E49: 3.25 | F49: SMARTPHONE | G49: 24 | H49: 518 | J49: - | K49: - | M49: 0 | N49: 9.2 | O49: 0 | P49: 7.8 | Q49: 0 | R49: 4.4 | S49: 0 | T49: 2.8 | U49: 0 | V49: 0 | X49: 21 | Z49: 0 | AA49: 0 | AC49: 318 | AD49: 221 | AE49: 352 | AF49: 187 | AG49: 433 | AH49: 106 | AI49: 472 | AJ49: 67 | AK49: 539 | AL49: 0 | AN49: 0 | AP49: 0 | AQ49: 0 | AS49: 0 | AT49: 0 | AU49: 0 | AV49: 0 | AW49: 0 | AX49: 0 | AY49: 0 | AZ49: 0 | BA49: 0 | BB49: 0
B50: HONOR | C50: HONOR 200 LITE 256GB 5G | D50: 309 | E50: 3.25 | F50: SMARTPHONE | G50: 24 | H50: 291 | J50: - | K50: - | M50: 0 | N50: 5.2 | O50: 0 | P50: 3.8 | Q50: 0 | R50: 0 | S50: 0 | T50: 0 | U50: 0 | V50: 0 | X50: 18 | Z50: 0 | AA50: 0 | AC50: 184 | AD50: 125 | AE50: 218 | AF50: 91 | AG50: 309 | AH50: 0 | AI50: 309 | AJ50: 0 | AK50: 309 | AL50: 0 | AN50: 0 | AP50: 0 | AQ50: 0 | AS50: 0 | AT50: 0 | AU50: 0 | AV50: 0 | AW50: 0 | AX50: 0 | AY50: 0 | AZ50: 0 | BA50: 0 | BB50: 0
B51: HONOR | C51: HONOR 200 PRO 512GB 5G | D51: 661 | E51: 3.25 | F51: SMARTPHONE | G51: 24 | H51: 663 | J51: - | K51: - | M51: 39 | N51: 15.4 | O51: 19 | P51: 14.6 | Q51: 0 | R51: 12.1 | S51: 0 | T51: 10.4 | U51: 0 | V51: 5.8 | X51: -2 | Z51: 0 | AA51: 0 | AC51: 252 | AD51: 370 | AE51: 292 | AF51: 350 | AG51: 371 | AH51: 290 | AI51: 411 | AJ51: 250 | AK51: 522 | AL51: 139 | AN51: 0 | AP51: 0 | AQ51: 0 | AS51: 0 | AT51: 0 | AU51: 0 | AV51: 0 | AW51: 0 | AX51: 0 | AY51: 0 | AZ51: 0 | BA51: 0 | BB51: 0
B52: HONOR | C52: HONOR 200 SMART 256GB 5G | D52: 181 | E52: 3.25 | F52: SMARTPHONE | G52: 24 | H52: 119 | J52: - | K52: - | M52: 0 | N52: 2.8 | O52: 0 | P52: 1.4 | Q52: 0 | R52: 0 | S52: 0 | T52: 0 | U52: 0 | V52: 0 | X52: 62 | Z52: 0 | AA52: 0 | AC52: 114 | AD52: 67 | AE52: 147 | AF52: 34 | AG52: 181 | AH52: 0 | AI52: 181 | AJ52: 0 | AK52: 181 | AL52: 0 | AN52: 0 | AP52: 0 | AQ52: 0 | AS52: 0 | AT52: 0 | AU52: 0 | AV52: 0 | AW52: 0 | AX52: 0 | AY52: 0 | AZ52: 0 | BA52: 0 | BB52: 0
B53: HONOR | C53: HONOR 90 SMART 5G | D53: 218 | E53: 3.25 | F53: SMARTPHONE | G53: 24 | H53: 226 | J53: - | K53: - | M53: 0 | N53: 4.1 | O53: 0 | P53: 2.7 | Q53: 0 | R53: 0 | S53: 0 | T53: 0 | U53: 0 | V53: 0 | X53: -8 | Z53: 0 | AA53: 0 | AC53: 120 | AD53: 98 | AE53: 153 | AF53: 65 | AG53: 218 | AH53: 0 | AI53: 218 | AJ53: 0 | AK53: 218 | AL53: 0 | AN53: 0 | AP53: 0 | AQ53: 0 | AS53: 0 | AT53: 0 | AU53: 0 | AV53: 0 | AW53: 0 | AX53: 0 | AY53: 0 | AZ53: 0 | BA53: 0 | BB53: 0
B54: HONOR | C54: HONOR MAGIC V3 512GB 5G | D54: 1653 | E54: 3.25 | F54: SMARTPHONE | G54: 24 | H54: 1431 | J54: - | K54: - | M54: - | N54: - | O54: 129 | P54: 36.8 | Q54: 99 | R54: 34.8 | S54: 49 | T54: 34.2 | U54: 29 | V54: 30.2 | X54: 222 | Z54: 0 | AA54: 0 | AC54: 0 | AD54: 0 | AE54: 641 | AF54: 883 | AG54: 719 | AH54: 835 | AI54: 783 | AJ54: 821 | AK54: 899 | AL54: 725 | AN54: 0 | AP54: 0 | AQ54: 0 | AS54: 0 | AT54: 0 | AU54: 0 | AV54: 0 | AW54: 0 | AX54: 0 | AY54: 0 | AZ54: 1.7 | BA54: 0 | BB54: 0
B55: HONOR | C55: HONOR MAGIC6 LITE 256GB 5G | D55: 358 | E55: 3.25 | F55: SMARTPHONE | G55: 24 | H55: 360 | J55: - | K55: - | M55: 0 | N55: 9 | O55: 0 | P55: 7.6 | Q55: 0 | R55: 4.2 | S55: 0 | T55: 2.6 | U55: 0 | V55: 0 | X55: -2 | Z55: 0 | AA55: 0 | AC55: 142 | AD55: 216 | AE55: 176 | AF55: 182 | AG55: 257 | AH55: 101 | AI55: 296 | AJ55: 62 | AK55: 358 | AL55: 0 | AN55: 0 | AP55: 0 | AQ55: 0 | AS55: 0 | AT55: 0 | AU55: 0 | AV55: 0 | AW55: 0 | AX55: 0 | AY55: 0 | AZ55: 0 | BA55: 0 | BB55: 0
B56: HONOR | C56: HONOR MAGIC6 PRO 5G | D56: 1074 | E56: 3.25 | F56: SMARTPHONE | G56: 24 | H56: 978 | J56: - | K56: - | M56: - | N56: - | O56: 39 | P56: 25 | Q56: 39 | R56: 21.7 | S56: 0 | T56: 20.7 | U56: 0 | V56: 15.8 | X56: 96 | Z56: 0 | AA56: 0 | AC56: 0 | AD56: 0 | AE56: 435 | AF56: 600 | AG56: 514 | AH56: 521 | AI56: 577 | AJ56: 497 | AK56: 695 | AL56: 379 | AN56: 0 | AP56: 0 | AQ56: 0 | AS56: 0 | AT56: 0 | AU56: 0 | AV56: 0 | AW56: 0 | AX56: 0 | AY56: 0 | AZ56: 0 | BA56: 0 | BB56: 0
B57: HONOR | C57: HONOR PAD X9 WIFI | D57: 204 | E57: 3.75 | F57: TABLET | G57: 24 | H57: 210 | J57: - | K57: - | M57: 0 | N57: 5.2 | O57: 0 | P57: 3.8 | Q57: 0 | R57: 0 | S57: 0 | T57: 0 | U57: 0 | V57: 0 | X57: -6 | Z57: 0 | AA57: 0 | AC57: 79 | AD57: 125 | AE57: 113 | AF57: 91 | AG57: 204 | AH57: 0 | AI57: 204 | AJ57: 0 | AK57: 204 | AL57: 0 | AN57: 0 | AP57: 0 | AQ57: 0 | AS57: 0 | AT57: 0 | AU57: 0 | AV57: 0 | AW57: 0 | AX57: 0 | AY57: 0 | AZ57: 0 | BA57: 0 | BB57: 0
...

Sheet PVP VaP IEW Pro - Pyme
B2: OFERTA TÁCTICA EMPRESAS | H2: Pago Único | J2: CAPTA | M2: PORTABILIDAD
B4: ='PVP VaP - Pyme'!B4 -> 45627 | C4: ='PVP VaP - Pyme'!C4 -> 01/12 al 31/12 | J4: - | M4: ENTRADA PRO | O4: NORMAL PRO | Q4: VALOR PRO | S4: PREMIUM PRO
B5: 1. CONDICIONES DE LA OFERTA VENTA A PLAZOS (según tarifa y situación del cliente) | D5: Tarifas | H5: Todas Tarifas | J5: Todas Tarifas | M5: Internet Movil 3GB Empresa | O5: Internet Movil 10GB Empresa | Q5: Internet Movil 25GB Empresa Fibra Oro (**) | S5: Internet Movil 90GB Empresa Internet 4G en tu Negocio (excepto router) Internet Empresa Ilimitado
D13: Ampliaciones (meses antigüedad) | H13: - | J13: - | M13: + 4 M - 4 M doble capta | O13: + 4 M - 4 M doble capta | Q13: + 4 M - 4 M doble capta | S13: + 4 M - 4 M doble capta
D14: Origen (Portabilidad / Migración) | H14: Capta Pos / Pre Migra | J14: (*) Capta de cliente nuevo o de cliente -4 M, solo tienen acceso a Pago Único | M14: Pos / Migra | O14: Pos / Migra | Q14: Pos / Migra | S14: Pos / Migra
D15: CP Tarifa | H15: - | J15: - | M15: 12 M / 24 M | O15: 12 M / 24 M | Q15: 12 M / 24 M | S15: 12 M / 24 M
D16: (*) Para Capta de cliente nuevo o cliente de -4 meses que activen en el mismo acto comercial tarifas de voz y tarifas de IEW Pro, aplican las condiciones de Portabilidad origen Pospago
D17: (**) La tarifa Fibra Oro solo puede activarse con el router Alctel Airbox 4G MW40 2018
B18: 2. PRECIO DEL TERMINAL POR GRUPO DE TARIFAS | H18: Pago Único | J18: PVPR CAPTA | M18: PVPR PORTABILIDAD | V18: DxC Pago Único | X18: DxC CAPTA | AA18: DxC PORTABILIDAD
M20: GRUPOS DE TARIFAS IEW Pro | AA20: GRUPOS DE TARIFAS IEW Pro
J22: - | M22: ENTRADA PRO | O22: NORMAL PRO | Q22: VALOR PRO | S22: PREMIUM PRO | X22: - | AA22: ENTRADA PRO | AC22: NORMAL PRO | AE22: VALOR PRO | AG22: PREMIUM PRO
B24: MARCA | C24: Modelo (Novedades) | D24: Precio Cesión | E24: Canon Digital | F24: Gama | G24: Meses Cuota | H24: Pago Unico (sin IVA) | J24: Pago Inicial (sin IVA) | K24: Cuota Mes (sin IVA) | M24: Pago Inicial (sin IVA) | N24: Cuota Mes (sin IVA) | O24: Pago Inicial (sin IVA) | P24: Cuota Mes (sin IVA) | Q24: Pago Inicial (sin IVA) | R24: Cuota Mes (sin IVA) | S24: Pago Inicial (sin IVA) | T24: Cuota Mes (sin IVA) | V24: DxC Pago Unico | X24: DxC Precio | Y24: DxC VaP | AA24: DxC Precio | AB24: DxC VaP | AC24: DxC Precio | AD24: DxC VaP | AE24: DxC Precio | AF24: DxC VaP | AG24: DxC Precio | AH24: DxC VaP
B25: ALCATEL | C25: ALCATEL AIRBOX 4G MW45 | D25: 49 | E25: 0 | F25: MBB | G25: 12 | H25: 42.14876 | J25: - | K25: - | M25: 0 | N25: 3 | O25: 0 | P25: 1 | Q25: 0 | R25: 1 | S25: 0 | T25: 0 | V25: 6.8512397 | X25: - | Y25: - | AA25: 13 | AB25: 36 | AC25: 37 | AD25: 12 | AE25: 37 | AF25: 12 | AG25: 49 | AH25: 0
B26: ALCATEL | C26: ALCATEL AIRBOX 4G MW70 | D26: 59 | E26: 0 | F26: MBB | G26: 12 | H26: 61.157025 | J26: - | K26: - | M26: 0 | N26: 4 | O26: 0 | P26: 3 | Q26: 0 | R26: 3 | S26: 0 | T26: 1 | V26: -2.1570248 | X26: - | Y26: - | AA26: 11 | AB26: 48 | AC26: 23 | AD26: 36 | AE26: 23 | AF26: 36 | AG26: 47 | AH26: 12
B27: HUAWEI | C27: FLYBOX HUAWEI B535 232A 4G | D27: 132 | E27: 0 | F27: MBB | G27: 12 | H27: 59 | J27: - | K27: - | M27: 0 | N27: 4 | O27: 0 | P27: 3 | Q27: 0 | R27: 3 | S27: 0 | T27: 1 | V27: 73 | X27: - | Y27: - | AA27: 84 | AB27: 48 | AC27: 96 | AD27: 36 | AE27: 96 | AF27: 36 | AG27: 120 | AH27: 12
B28: HUAWEI | C28: FLYBOX HUAWEI B535 232A 4G (1) | D28: 0 | E28: 0 | F28: MBB | G28: 12 | H28: 0 | J28: - | K28: - | M28: - | N28: - | O28: - | P28: - | Q28: - | R28: - | S28: 0 | T28: 0 | V28: 0 | X28: - | Y28: - | AA28: - | AB28: - | AC28: - | AD28: - | AE28: - | AF28: - | AG28: 0 | AH28: 0
B29: HUAWEI | C29: HUAWEI AIRBOX E5576-320 IEW 4G | D29: 66 | E29: 0 | F29: MBB | G29: 12 | H29: 57.024793 | J29: - | K29: - | M29: 0 | N29: 3 | O29: 0 | P29: 2 | Q29: 0 | R29: 2 | S29: 0 | T29: 0 | V29: 8.9752066 | X29: - | Y29: - | AA29: 30 | AB29: 36 | AC29: 42 | AD29: 24 | AE29: 42 | AF29: 24 | AG29: 66 | AH29: 0
B30: TP-LINK | C30: ROUTER TPLINK MR200 IEW 4G | D30: 58 | E30: 0 | F30: MBB | G30: 12 | H30: 48 | J30: - | K30: - | M30: 0 | N30: 4 | O30: 0 | P30: 2 | Q30: 0 | R30: 2 | S30: 0 | T30: 1 | V30: 10 | X30: - | Y30: - | AA30: 10 | AB30: 48 | AC30: 34 | AD30: 24 | AE30: 34 | AF30: 24 | AG30: 46 | AH30: 12
B31: TP-LINK | C31: ROUTER TPLINK MR200 IEW 4G (2) | D31: 58 | E31: 0 | F31: MBB | G31: - | H31: 48 | J31: - | K31: - | M31: - | N31: - | O31: - | P31: - | Q31: - | R31: - | S31: - | T31: - | V31: 10 | X31: - | Y31: - | AA31: - | AB31: - | AC31: - | AD31: - | AE31: - | AF31: - | AG31: - | AH31: -
B32: TP-LINK | C32: TP-LINK FLYBOX 4G (1) | D32: 0 | E32: 0 | F32: MBB | G32: 12 | H32: 0 | J32: - | K32: - | M32: - | N32: - | O32: - | P32: - | Q32: - | R32: - | S32: 0 | T32: 0 | V32: 0 | X32: - | Y32: - | AA32: - | AB32: - | AC32: - | AD32: - | AE32: - | AF32: - | AG32: 0 | AH32: 0
B33: ZTE | C33: ZTE AIRBOX MF920U 4G | D33: 66 | E33: 0 | F33: MBB | G33: 12 | H33: 45.454545 | J33: - | K33: - | M33: 0 | N33: 3 | O33: 0 | P33: 2 | Q33: 0 | R33: 2 | S33: 0 | T33: 0 | V33: 20.545455 | X33: - | Y33: - | AA33: 30 | AB33: 36 | AC33: 42 | AD33: 24 | AE33: 42 | AF33: 24 | AG33: 66 | AH33: 0
B34: ZTE | C34: ZTE AIRBOX MU5001 5G | D34: 244 | E34: 0 | F34: MBB | G34: 24 | H34: 295 | J34: - | K34: - | M34: 39 | N34: 7 | O34: 0 | P34: 7 | Q34: 0 | R34: 7 | S34: 0 | T34: 6 | V34: -51 | AA34: 37 | AB34: 168 | AC34: 76 | AD34: 168 | AE34: 76 | AF34: 168 | AG34: 100 | AH34: 144
B35: ZTE | C35: ZTE FLYBOX MC801A 5G | D35: 200 | E35: 0 | F35: MBB | G35: 24 | H35: 242 | J35: - | K35: - | M35: 29 | N35: 6 | O35: 0 | P35: 6 | Q35: 0 | R35: 6 | S35: 0 | T35: 6 | V35: -42 | X35: - | Y35: - | AA35: 27 | AB35: 144 | AC35: 56 | AD35: 144 | AE35: 56 | AF35: 144 | AG35: 56 | AH35: 144
B36: NOKIA | C36: FLYBOX NOKIA FASTMILE 5G | D36: 207 | E36: 0 | F36: MBB | G36: 24 | H36: 177.68595 | J36: - | K36: - | M36: 29 | N36: 5 | O36: 0 | P36: 5 | Q36: 0 | R36: 5 | S36: 0 | T36: 5 | V36: 29.31405 | X36: - | Y36: - | AA36: 58 | AB36: 120 | AC36: 87 | AD36: 120 | AE36: 87 | AF36: 120 | AG36: 87 | AH36: 120
B37: HUAWEI | C37: FLYBOX HUAWEI H153-381 5G | D37: 248 | E37: 0 | F37: MBB | G37: 24 | H37: 132 | J37: - | K37: - | M37: 0 | N37: 4 | O37: 0 | P37: 4 | Q37: 0 | R37: 4 | S37: 0 | T37: 3 | V37: 116 | X37: - | Y37: - | AA37: 152 | AB37: 96 | AC37: 152 | AD37: 96 | AE37: 152 | AF37: 96 | AG37: 176 | AH37: 72
B38: SAMSUNG | C38: SAMSUNG GALAXY TAB A9 8,7" WIFI | D38: 182 | E38: 3.75 | F38: TABLET | G38: 24 | H38: 161.98347 | J38: - | K38: - | M38: 29 | N38: 4 | O38: 0 | P38: 5 | Q38: 0 | R38: 5 | S38: 0 | T38: 4 | V38: 20.016529 | X38: - | Y38: - | AA38: 57 | AB38: 96 | AC38: 62 | AD38: 120 | AE38: 62 | AF38: 120 | AG38: 86 | AH38: 96
B39: XIAOMI | C39: XIAOMI REDMI PAD SE 8.7" WIFI 4+128GB | D39: 167 | E39: 3.75 | F39: TABLET | G39: 24 | H39: 123.1405 | J39: - | K39: - | M39: 0 | N39: 4 | O39: 0 | P39: 4 | Q39: 0 | R39: 4 | S39: 0 | T39: 3 | V39: 43.859504 | X39: - | Y39: - | AA39: 71 | AB39: 96 | AC39: 71 | AD39: 96 | AE39: 71 | AF39: 96 | AG39: 95 | AH39: 72
B42: Condiciones especiales para Fibra Oro
B43: ZTE | C43: ZTE AIRBOX MF920U 4G | D43: 66 | E43: 0 | F43: MBB | G43: 12 | H43: 47.11 | J43: - | K43: - | M43: - | N43: - | O43: - | P43: - | Q43: 0 | R43: 0 | S43: - | T43: - | V43: 18.89 | X43: - | Y43: - | AA43: - | AB43: - | AC43: - | AD43: - | AE43: 66 | AF43: 0 | AG43: - | AH43: -
B44: ALCATEL | C44: ALCATEL AIRBOX 4G MW45 | D44: 49 | E44: 0 | F44: MBB | G44: 12 | H44: 43.801653 | J44: - | K44: - | M44: - | N44: - | O44: - | P44: - | Q44: 0 | R44: 0 | S44: - | T44: - | V44: 5.1983471 | X44: - | Y44: - | AA44: - | AB44: - | AC44: - | AD44: - | AE44: 49 | AF44: 0 | AG44: - | AH44: -
C48: (1) Solo oferta en VaP (cesión) para 4G en tu Negocio e Internet Empresas Ilimitado
C49: (2) Solo oferta en Pago único para 4G en tu Negocio e Internet Empresas Ilimitado

Sheet PVP Subv - Optima Pyme
B2: OFERTA TÁCTICA EMPRESAS | I2: CAPTA | O2: PORTABILIDAD
B4: ='PVP VaP - Pyme'!B4 -> 45627 | C4: ='PVP VaP - Pyme'!C4 -> 01/12 al 31/12 | I4: ENTRADA PRO | J4: NORMAL PRO | K4: VALOR PRO | L4: PREMIUM PRO | M4: TOP PRO | O4: ENTRADA PRO | P4: NORMAL PRO | Q4: VALOR PRO | R4: PREMIUM PRO | S4: TOP PRO
B5: 1. CONDICIONES DE LA OFERTA SUBVENCIONADA (según tarifa y situación del cliente) | D5: Tarifas | I5: T. Optima Plus Empresas T. Optima Plus Empresas Big + Empresas Voz y Empresas 1 | J5: T. Optima Plus Empresas T. Optima Plus Empresas Big + Empresas 5 y Empresas Intranet | K5: T. Optima Plus Empresas T. Optima Plus Empresas Big + Empresas 20 | L5: T. Optima Plus Empresas T. Optima Plus Empresas Big + Empresas Infinita | M5: T. Optima Plus Empresas T. Optima Plus Empresas Big + Empresas Internacional | O5: T. Optima Plus Empresas T. Optima Plus Empresas Big + Empresas Voz y Empresas 1 | P5: T. Optima Plus Empresas T. Optima Plus Empresas Big + Empresas 5 y Empresas Intranet | Q5: T. Optima Plus Empresas T. Optima Plus Empresas Big + Empresas 20 | R5: T. Optima Plus Empresas T. Optima Plus Empresas Big + Empresas Infinita | S5: T. Optima Plus Empresas T. Optima Plus Empresas Big + Empresas Internacional
D12: Ampliaciones (meses antigüedad) | I12: Todos | J12: Todos | K12: Todos | L12: Todos | M12: Todos | O12: Todos | P12: Todos | Q12: Todos | R12: Todos | S12: Todos
D13: Origen (Portabilidad / Migración) | I13: Capta Prepago Migracion | J13: Capta Prepago Migracion | K13: Capta Prepago Migracion | L13: Capta Prepago Migracion | M13: Capta Prepago Migracion | O13: Pospago | P13: Pospago | Q13: Pospago | R13: Pospago | S13: Pospago
D14: CP Tarifa | I14: CMPT24AG | J14: CMPT24AG | K14: CMPT24AG | L14: CMPT24AG | M14: CMPT24AG | O14: CMPT24AG | P14: CMPT24AG | Q14: CMPT24AG | R14: CMPT24AG | S14: CMPT24AG
D15: CP Terminal | I15: CPTE224 | J15: CPTE324 | K15: CPTE324 | L15: CPTE424 | M15: CPTE424 | O15: CPTE224 | P15: CPTE324 | Q15: CPTE324 | R15: CPTE424 | S15: CPTE424
I16: Las condiciones de los modulos Entrada Pro y Normal Pro aplican para los terminales VOZ y FIX tanto si activan sólo voz como si activan el paquete de voz + datos | U16: DIFERENCIAS Vs MES ANTERIOR
B19: 2. PRECIO DEL TERMINAL POR GRUPO DE TARIFAS | I19: DxC CAPTA | O19: DxC PORTABILIDAD | U19: DxC CAPTA | AA19: DxC PORTABILIDAD | AG19: PVPR CAPTA | AM19: PVPR PORTABILIDAD
I21: GRUPOS DE TARIFAS MOVIL | O21: GRUPOS DE TARIFAS MOVIL | U21: GRUPOS DE TARIFAS MOVIL | AA21: GRUPOS DE TARIFAS MOVIL | AG21: GRUPOS DE TARIFAS MOVIL | AM21: GRUPOS DE TARIFAS MOVIL
I23: ENTRADA PRO | J23: NORMAL PRO | K23: VALOR PRO | L23: PREMIUM PRO | M23: TOP PRO | O23: ENTRADA PRO | P23: NORMAL PRO | Q23: VALOR PRO | R23: PREMIUM PRO | S23: TOP PRO | U23: ENTRADA PRO | V23: NORMAL PRO | W23: VALOR PRO | X23: PREMIUM PRO | Y23: TOP PRO | AA23: ENTRADA PRO | AB23: NORMAL PRO | AC23: VALOR PRO | AD23: PREMIUM PRO | AE23: TOP PRO | AG23: ENTRADA PRO | AH23: NORMAL PRO | AI23: VALOR PRO | AJ23: PREMIUM PRO | AK23: TOP PRO | AM23: ENTRADA PRO | AN23: NORMAL PRO | AO23: VALOR PRO | AP23: PREMIUM PRO | AQ23: TOP PRO
B25: MARCA | C25: Modelo (Novedades) | D25: Precio Cesión | E25: Canon Digital | F25: Gama | I25: DxC (sin IVA) | J25: DxC (sin IVA) | K25: DxC (sin IVA) | L25: DxC (sin IVA) | M25: DxC (sin IVA) | O25: DxC (sin IVA) | P25: DxC (sin IVA) | Q25: DxC (sin IVA) | R25: DxC (sin IVA) | S25: DxC (sin IVA) | U25: DxC (sin IVA) | V25: DxC (sin IVA) | W25: DxC (sin IVA) | X25: DxC (sin IVA) | Y25: DxC (sin IVA) | AA25: DxC (sin IVA) | AB25: DxC (sin IVA) | AC25: DxC (sin IVA) | AD25: DxC (sin IVA) | AE25: DxC (sin IVA) | AG25: PVP (sin IVA) | AH25: PVP (sin IVA) | AI25: PVP (sin IVA) | AJ25: PVP (sin IVA) | AK25: PVP (sin IVA) | AM25: PVP (sin IVA) | AN25: PVP (sin IVA) | AO25: PVP (sin IVA) | AP25: PVP (sin IVA) | AQ25: PVP (sin IVA)
B26: ORANGE | C26: AD HOC H3 CESIÓN | D26: 0 | E26: 1.1 | F26: FIXED STYLE | I26: 0 | J26: 0 | K26: 0 | L26: 0 | M26: 0 | O26: 0 | P26: 0 | Q26: 0 | R26: 0 | S26: 0 | U26: 0 | V26: 0 | W26: 0 | X26: 0 | Y26: 0 | AA26: 0 | AB26: 0 | AC26: 0 | AD26: 0 | AE26: 0 | AG26: - | AH26: - | AI26: - | AJ26: - | AK26: - | AM26: - | AN26: - | AO26: - | AP26: - | AQ26: -
B27: ORANGE | C27: ADOC D30 | D27: 239 | E27: 3.75 | F27: FIXED STYLE | I27: 116 | J27: 166 | K27: 215 | L27: 239 | M27: 239 | O27: 116 | P27: 166 | Q27: 215 | R27: 239 | S27: 239 | U27: 0 | V27: 0 | W27: 0 | X27: 0 | Y27: 0 | AA27: 0 | AB27: 0 | AC27: 0 | AD27: 0 | AE27: 0 | AG27: 123 | AH27: 73 | AI27: 24 | AJ27: 0 | AK27: 0 | AM27: 123 | AN27: 73 | AO27: 24 | AP27: 0 | AQ27: 0
B28: ORANGE | C28: ADOC D30 CESIÓN | D28: 0 | E28: 3.75 | F28: FIXED STYLE | I28: 0 | J28: 0 | K28: 0 | L28: 0 | M28: 0 | O28: 0 | P28: 0 | Q28: 0 | R28: 0 | S28: 0 | U28: 0 | V28: 0 | W28: 0 | X28: 0 | Y28: 0 | AA28: 0 | AB28: 0 | AC28: 0 | AD28: 0 | AE28: 0 | AG28: - | AH28: - | AI28: - | AJ28: - | AK28: - | AM28: - | AN28: - | AO28: - | AP28: - | AQ28: -
B29: AD HOC | C29: ADOC SC01 | D29: 64 | E29: 1.1 | F29: VOZ | I29: 64 | J29: 64 | K29: 0 | L29: 0 | M29: 0 | O29: 64 | P29: 64 | Q29: 0 | R29: 0 | S29: 0 | U29: 0 | V29: 0 | W29: 0 | X29: 0 | Y29: 0 | AA29: 0 | AB29: 0 | AC29: 0 | AD29: 0 | AE29: 0 | AG29: 0 | AH29: 0 | AI29: - | AJ29: - | AK29: - | AM29: 0 | AN29: 0 | AO29: - | AP29: - | AQ29: -
B30: ADOC | C30: ADOC SC04 | D30: 77 | E30: 1.1 | F30: VOZ | I30: 77 | J30: 77 | K30: 0 | L30: 0 | M30: 0 | O30: 77 | P30: 77 | Q30: 0 | R30: 0 | S30: 0 | U30: 0 | V30: 0 | W30: 0 | X30: 0 | Y30: 0 | AA30: 0 | AB30: 0 | AC30: 0 | AD30: 0 | AE30: 0 | AG30: 0 | AH30: 0 | AI30: - | AJ30: - | AK30: - | AM30: 0 | AN30: 0 | AO30: - | AP30: - | AQ30: -
B31: APPLE | C31: APPLE AIRPODS 4 | D31: 137 | E31: 0 | F31: OC_AURICULARES | I31: 52 | J31: 72 | K31: 95 | L31: 112 | M31: 145 | O31: 97 | P31: 127 | Q31: 176 | R31: 224 | S31: 224 | U31: 0 | V31: 0 | W31: 0 | X31: 0 | Y31: 0 | AA31: 0 | AB31: 0 | AC31: 0 | AD31: 0 | AE31: 0 | AG31: 85 | AH31: 65 | AI31: 42 | AJ31: 25 | AK31: -8 | AM31: 40 | AN31: 10 | AO31: -39 | AP31: -86.54 | AQ31: -86.54
B32: APPLE | C32: APPLE AIRPODS 4 CON CANCELACION ACTIVA RUIDO | D32: 184 | E32: 0 | F32: OC_AURICULARES | I32: 52 | J32: 72 | K32: 95 | L32: 112 | M32: 145 | O32: 97 | P32: 127 | Q32: 176 | R32: 241 | S32: 250 | U32: 0 | V32: 0 | W32: 0 | X32: 0 | Y32: 0 | AA32: 0 | AB32: 0 | AC32: 0 | AD32: 0 | AE32: 0 | AG32: 132 | AH32: 112 | AI32: 89 | AJ32: 72 | AK32: 39 | AM32: 87 | AN32: 57 | AO32: 8 | AP32: -57 | AQ32: -66.08
B33: APPLE | C33: APPLE AIRPODS PRO 2a GENERACION MAGSAFE USBC | D33: 279 | E33: 0 | F33: OC_AURICULARES | I33: 89 | J33: 109 | K33: 132 | L33: 149 | M33: 182 | O33: 134 | P33: 164 | Q33: 213 | R33: 278 | S33: 373 | U33: 0 | V33: 0 | W33: 0 | X33: 0 | Y33: 0 | AA33: 0 | AB33: 0 | AC33: 0 | AD33: 0 | AE33: 0 | AG33: 190.46 | AH33: 170.46 | AI33: 147.46 | AJ33: 130.46 | AK33: 97.46 | AM33: 145.46 | AN33: 115.46 | AO33: 66.46 | AP33: 1.46 | AQ33: -94.23
B34: APPLE | C34: APPLE WATCH S10 CELLULAR 42MM | D34: 532 | E34: 2.5 | F34: OC_SMART WATCH | I34: 52 | J34: 138 | K34: 161 | L34: 178 | M34: 211 | O34: 97 | P34: 193 | Q34: 242 | R34: 307 | S34: 419 | U34: 0 | V34: 0 | W34: 0 | X34: 0 | Y34: 0 | AA34: 0 | AB34: 0 | AC34: 0 | AD34: 0 | AE34: 0 | AG34: 480 | AH34: 393.81 | AI34: 370.81 | AJ34: 353.81 | AK34: 320.81 | AM34: 435 | AN34: 338.81 | AO34: 289.81 | AP34: 224.81 | AQ34: 112.81
B35: APPLE | C35: APPLE WATCH S10 CELLULAR 46MM | D35: 555 | E35: 2.5 | F35: OC_SMART WATCH | I35: 52 | J35: 139 | K35: 162 | L35: 179 | M35: 212 | O35: 97 | P35: 194 | Q35: 243 | R35: 308 | S35: 420 | U35: 0 | V35: 0 | W35: 0 | X35: 0 | Y35: 0 | AA35: 0 | AB35: 0 | AC35: 0 | AD35: 0 | AE35: 0 | AG35: 503 | AH35: 416.25 | AI35: 393.25 | AJ35: 376.25 | AK35: 343.25 | AM35: 458 | AN35: 361.25 | AO35: 312.25 | AP35: 247.25 | AQ35: 135.25
B36: APPLE | C36: APPLE WATCH S9 CELLULAR 45MM | D36: 555 | E36: 2.5 | F36: OC_SMART WATCH | I36: 52 | J36: 139 | K36: 162 | L36: 179 | M36: 212 | O36: 97 | P36: 194 | Q36: 243 | R36: 308 | S36: 420 | U36: 0 | V36: 0 | W36: 0 | X36: 0 | Y36: 0 | AA36: 0 | AB36: 0 | AC36: 0 | AD36: 0 | AE36: 0 | AG36: 503 | AH36: 416.25 | AI36: 393.25 | AJ36: 376.25 | AK36: 343.25 | AM36: 458 | AN36: 361.25 | AO36: 312.25 | AP36: 247.25 | AQ36: 135.25
B37: AD HOC | C37: AURICULARES AD HOC BT01 | D37: 71 | E37: 0 | F37: OC_AURICULARES | I37: 71 | J37: 71 | K37: 71 | L37: 71 | M37: 71 | O37: 71 | P37: 71 | Q37: 71 | R37: 71 | S37: 71 | U37: 0 | V37: 0 | W37: 0 | X37: 0 | Y37: 0 | AA37: 0 | AB37: 0 | AC37: 0 | AD37: 0 | AE37: 0 | AG37: 0 | AH37: 0 | AI37: 0 | AJ37: 0 | AK37: 0 | AM37: 0 | AN37: 0 | AO37: 0 | AP37: 0 | AQ37: 0
B38: AD HOC | C38: AURICULARES AD HOC HC01 | D38: 49 | E38: 0 | F38: OC_AURICULARES | I38: 49 | J38: 49 | K38: 49 | L38: 49 | M38: 49 | O38: 49 | P38: 49 | Q38: 49 | R38: 49 | S38: 49 | U38: 0 | V38: 0 | W38: 0 | X38: 0 | Y38: 0 | AA38: 0 | AB38: 0 | AC38: 0 | AD38: 0 | AE38: 0 | AG38: 0 | AH38: 0 | AI38: 0 | AJ38: 0 | AK38: 0 | AM38: 0 | AN38: 0 | AO38: 0 | AP38: 0 | AQ38: 0
B39: SAMSUNG | C39: AURICULARES SAMSUNG GALAXY BUDS 3 | D39: 172 | E39: 0 | F39: OC_AURICULARES | I39: 82 | J39: 102 | K39: 125 | L39: 142 | M39: 175 | O39: 127 | P39: 157 | Q39: 206 | R39: 244 | S39: 244 | U39: 0 | V39: 0 | W39: 0 | X39: 0 | Y39: 0 | AA39: 0 | AB39: 0 | AC39: 0 | AD39: 0 | AE39: 0 | AG39: 90 | AH39: 70 | AI39: 47 | AJ39: 30 | AK39: -3 | AM39: 45 | AN39: 15 | AO39: -34 | AP39: -72 | AQ39: -72
B40: SAMSUNG | C40: AURICULARES SAMSUNG GALAXY BUDS 3 PRO | D40: 240 | E40: 0 | F40: OC_AURICULARES | I40: 103 | J40: 123 | K40: 146 | L40: 163 | M40: 196 | O40: 148 | P40: 178 | Q40: 227 | R40: 292 | S40: 308 | U40: 0 | V40: 0 | W40: 0 | X40: 0 | Y40: 0 | AA40: 0 | AB40: 0 | AC40: 0 | AD40: 0 | AE40: 0 | AG40: 137 | AH40: 117 | AI40: 94 | AJ40: 77 | AK40: 44 | AM40: 92 | AN40: 62 | AO40: 13 | AP40: -52 | AQ40: -67.5
B41: SPC | C41: AURICULARES SPC BRAVE PRO | D41: 44 | E41: 0 | F41: OC_AURICULARES | I41: 44 | J41: 44 | K41: 44 | L41: 44 | M41: 44 | O41: 44 | P41: 44 | Q41: 44 | R41: 44 | S41: 44 | U41: 0 | V41: 0 | W41: 0 | X41: 0 | Y41: 0 | AA41: 0 | AB41: 0 | AC41: 0 | AD41: 0 | AE41: 0 | AG41: 0 | AH41: 0 | AI41: 0 | AJ41: 0 | AK41: 0 | AM41: 0 | AN41: 0 | AO41: 0 | AP41: 0 | AQ41: 0
B42: SPC | C42: AURICULARES SPC DREAMER PRO | D42: 77 | E42: 0 | F42: OC_AURICULARES | I42: 77 | J42: 77 | K42: 77 | L42: 77 | M42: 77 | O42: 77 | P42: 77 | Q42: 77 | R42: 77 | S42: 77 | U42: 0 | V42: 0 | W42: 0 | X42: 0 | Y42: 0 | AA42: 0 | AB42: 0 | AC42: 0 | AD42: 0 | AE42: 0 | AG42: 0 | AH42: 0 | AI42: 0 | AJ42: 0 | AK42: 0 | AM42: 0 | AN42: 0 | AO42: 0 | AP42: 0 | AQ42: 0
... B74: LENOVO | C74: LENOVO IDEAPAD 1 15ADA7 4120 8+256GB | D74: 462 | E74: 5.33 | F74: PC | I74: 169 | J74: 189 | K74: 212 | L74: 229 | M74: 262 | O74: 214 | P74: 244 | Q74: 293 | R74: 358 | S74: 470 | U74: -30 | V74: -30 | W74: -30 | X74: -30 | Y74: -30 | AA74: -30 | AB74: -30 | AC74: 6 | AD74: 104 | AE74: -8 | AG74: 293.33 | AH74: 273.33 | AI74: 250.33 | AJ74: 233.33 | AK74: 200.33 | AM74: 248.33 | AN74: 218.33 | AO74: 169.33 | AP74: 104.33 | AQ74: -7.67
B75: LENOVO | C75: LENOVO IDEAPAD 3 15IAH8 CI5 8+512GB | D75: 620 | E75: 5.33 | F75: PC | I75: 52 | J75: 138 | K75: 161 | L75: 178 | M75: 211 | O75: 97 | P75: 193 | Q75: 242 | R75: 307 | S75: 419 | U75: =NA() -> #N/A | V75: =NA() -> #N/A | W75: =NA() -> #N/A | X75: =NA() -> #N/A | Y75: =NA() -> #N/A | AA75: =NA() -> #N/A | AB75: =NA() -> #N/A | AC75: =NA() -> #N/A | AD75: =NA() -> #N/A | AE75: =NA() -> #N/A | AG75: 568 | AH75: 481.59 | AI75: 458.59 | AJ75: 441.59 | AK75: 408.59 | AM75: 523 | AN75: 426.59 | AO75: 377.59 | AP75: 312.59 | AQ75: 200.59
B76: LENOVO | C76: LENOVO IDEAPAD 3 15IAH8 CI5 8+512GB + TAB M11 WIFI | D76: 620 | E76: 5.33 | F76: PC | I76: 52 | J76: 138 | K76: 161 | L76: 178 | M76: 211 | O76: 97 | P76: 193 | Q76: 242 | R76: 307 | S76: 419 | U76: =NA() -> #N/A | V76: =NA() -> #N/A | W76: =NA() -> #N/A | X76: =NA() -> #N/A | Y76: =NA() -> #N/A | AA76: =NA() -> #N/A | AB76: =NA() -> #N/A | AC76: =NA() -> #N/A | AD76: =NA() -> #N/A | AE76: =NA() -> #N/A | AG76: 568 | AH76: 481.59 | AI76: 458.59 | AJ76: 441.59 | AK76: 408.59 | AM76: 523 | AN76: 426.59 | AO76: 377.59 | AP76: 312.59 | AQ76: 200.59
B77: LENOVO | C77: LENOVO IDEAPAD 3 15ITL6 CI5 | D77: 638 | E77: 5.33 | F77: PC | I77: 52 | J77: 156 | K77: 179 | L77: 196 | M77: 229 | O77: 97 | P77: 211 | Q77: 260 | R77: 419 | S77: 529 | U77: 0 | V77: 50 | W77: 50 | X77: 50 | Y77: 50 | AA77: 0 | AB77: 50 | AC77: 50 | AD77: 50 | AE77: 50 | AG77: 586 | AH77: 481.59 | AI77: 458.59 | AJ77: 441.59 | AK77: 408.59 | AM77: 541 | AN77: 426.59 | AO77: 377.59 | AP77: 218.59 | AQ77: 108.59
B78: LENOVO | C78: LENOVO IDEAPAD 5 16IRL8 I7 13GEN 16GB+1TB | D78: 915 | E78: 5.33 | F78: PC | I78: 52 | J78: 243 | K78: 266 | L78: 283 | M78: 316 | O78: 97 | P78: 298 | Q78: 347 | R78: 412 | S78: 524 | U78: 0 | V78: 0 | W78: 0 | X78: 0 | Y78: 0 | AA78: 0 | AB78: 0 | AC78: 0 | AD78: 0 | AE78: 0 | AG78: 863 | AH78: 672.33 | AI78: 649.33 | AJ78: 632.33 | AK78: 599.33 | AM78: 818 | AN78: 617.33 | AO78: 568.33 | AP78: 503.33 | AQ78: 391.33
B79: LENOVO | C79: LENOVO LOQ 3 15IRH8 i5 RTX 2050 | D79: 948 | E79: 5.33 | F79: PC | I79: 52 | J79: 220 | K79: 243 | L79: 260 | M79: 293 | O79: 97 | P79: 275 | Q79: 324 | R79: 389 | S79: 501 | U79: 0 | V79: 0 | W79: 0 | X79: 0 | Y79: 0 | AA79: 0 | AB79: 0 | AC79: 0 | AD79: 0 | AE79: 0 | AG79: 896 | AH79: 728.33 | AI79: 705.33 | AJ79: 688.33 | AK79: 655.33 | AM79: 851 | AN79: 673.33 | AO79: 624.33 | AP79: 559.33 | AQ79: 447.33
B80: LENOVO | C80: LENOVO P3 CHROMEBOOK PLUS 14" i3 8+256GB | D80: 525 | E80: 5.33 | F80: PC | I80: 218 | J80: 238 | K80: 261 | L80: 278 | M80: 311 | O80: 263 | P80: 293 | Q80: 342 | R80: 437 | S80: 549 | U80: 0 | V80: 0 | W80: 0 | X80: 0 | Y80: 0 | AA80: 0 | AB80: 0 | AC80: 0 | AD80: -30 | AE80: -30 | AG80: 306.59 | AH80: 286.59 | AI80: 263.59 | AJ80: 246.59 | AK80: 213.59 | AM80: 261.59 | AN80: 231.59 | AO80: 182.59 | AP80: 87.59 | AQ80: -24.41
B81: LG | C81: LG SMART TV 32" LQ | D81: 215 | E81: 0 | F81: SMART TV | I81: 84 | J81: 104 | K81: 127 | L81: 144 | M81: 177 | O81: 129 | P81: 159 | Q81: 208 | R81: 273 | S81: 280 | U81: 0 | V81: 0 | W81: 0 | X81: 0 | Y81: 0 | AA81: 0 | AB81: 0 | AC81: 0 | AD81: 0 | AE81: 0 | AG81: 131 | AH81: 111 | AI81: 88 | AJ81: 71 | AK81: 38 | AM81: 86 | AN81: 56 | AO81: 7 | AP81: -58 | AQ81: -64.5
B82: LG | C82: LG SMART TV 43" UR78 4K | D82: 396 | E82: 0 | F82: SMART TV | I82: 161 | J82: 181 | K82: 204 | L82: 221 | M82: 254 | O82: 206 | P82: 236 | Q82: 285 | R82: 350 | S82: 462 | U82: 0 | V82: 0 | W82: 0 | X82: 0 | Y82: 0 | AA82: 0 | AB82: 0 | AC82: 0 | AD82: 0 | AE82: 0 | AG82: 235 | AH82: 215 | AI82: 192 | AJ82: 175 | AK82: 142 | AM82: 190 | AN82: 160 | AO82: 111 | AP82: 46 | AQ82: -66
B83: LG | C83: LG SMART TV 50" UR78 4K | D83: 479 | E83: 0 | F83: SMART TV | I83: 191 | J83: 211 | K83: 234 | L83: 251 | M83: 284 | O83: 236 | P83: 266 | Q83: 315 | R83: 380 | S83: 492 | U83: 0 | V83: 0 | W83: 0 | X83: 0 | Y83: 0 | AA83: 0 | AB83: 0 | AC83: 0 | AD83: 0 | AE83: 0 | AG83: 288 | AH83: 268 | AI83: 245 | AJ83: 228 | AK83: 195 | AM83: 243 | AN83: 213 | AO83: 164 | AP83: 99 | AQ83: -13
B84: LG | C84: LG SMART TV 55" OLED C46 4K | D84: 1735 | E84: 0 | F84: SMART TV | I84: 52 | J84: 72 | K84: 875 | L84: 892 | M84: 925 | O84: 97 | P84: 127 | Q84: 956 | R84: 1021 | S84: 1133 | U84: 0 | V84: 0 | W84: 0 | X84: 0 | Y84: 0 | AA84: 0 | AB84: 0 | AC84: 0 | AD84: 0 | AE84: 0 | AG84: 1683 | AH84: 1663 | AI84: 859.8 | AJ84: 842.8 | AK84: 809.8 | AM84: 1638 | AN84: 1608 | AO84: 778.8 | AP84: 713.8 | AQ84: 601.8
...

Sheet PVP Subv - Optima Pyme 36
B2: OFERTA TÁCTICA EMPRESAS | I2: CAPTA | O2: PORTABILIDAD
B4: ='PVP VaP - Pyme'!B4 -> 45627 | C4: ='PVP VaP - Pyme'!C4 -> 01/12 al 31/12 | I4: ENTRADA PRO | J4: NORMAL PRO | K4: VALOR PRO | L4: PREMIUM PRO | M4: TOP PRO | O4: ENTRADA PRO | P4: NORMAL PRO | Q4: VALOR PRO | R4: PREMIUM PRO | S4: TOP PRO
B5: 1. CONDICIONES DE LA OFERTA SUBVENCIONADA (según tarifa y situación del cliente) | D5: Tarifas | I5: T. Optima Plus Empresas T. Optima Plus Empresas Big + Empresas Voz y Empresas 1 | J5: T. Optima Plus Empresas T. Optima Plus Empresas Big + Empresas 5 y Empresas Intranet | K5: T. Optima Plus Empresas T. Optima Plus Empresas Big + Empresas 20 | L5: T. Optima Plus Empresas T. Optima Plus Empresas Big + Empresas Infinita | M5: T. Optima Plus Empresas T. Optima Plus Empresas Big + Empresas Internacional | O5: T. Optima Plus Empresas T. Optima Plus Empresas Big + Empresas Voz y Empresas 1 | P5: T. Optima Plus Empresas T. Optima Plus Empresas Big + Empresas 5 y Empresas Intranet | Q5: T. Optima Plus Empresas T. Optima Plus Empresas Big + Empresas 20 | R5: T. Optima Plus Empresas T. Optima Plus Empresas Big + Empresas Infinita | S5: T. Optima Plus Empresas T. Optima Plus Empresas Big + Empresas Internacional
D12: Ampliaciones (meses antigüedad) | I12: Todos | J12: Todos | K12: Todos | L12: Todos | M12: Todos | O12: Todos | P12: Todos | Q12: Todos | R12: Todos | S12: Todos
D13: Origen (Portabilidad / Migración) | I13: Capta Prepago Migracion | J13: Capta Prepago Migracion | K13: Capta Prepago Migracion | L13: Capta Prepago Migracion | M13: Capta Prepago Migracion | O13: Pospago | P13: Pospago | Q13: Pospago | R13: Pospago | S13: Pospago
D14: CP Tarifa | I14: CPT136 | J14: CPT136 | K14: CPT136 | L14: CPT136 | M14: CPT136 | O14: CPT136 | P14: CPT136 | Q14: CPT136 | R14: CPT136 | S14: CPT136
D15: CP Terminal | I15: CPTE336 | J15: CPTE136 | K15: CPTE136 | L15: CPTE436 | M15: CPTE436 | O15: CPTE336 | P15: CPTE136 | Q15: CPTE136 | R15: CPTE436 | S15: CPTE436
I16: Las condiciones de los modulos Entrada Pro y Normal Pro aplican para los terminales VOZ y FIX tanto si activan sólo voz como si activan el paquete de voz + datos | U16: DIFERENCIAS Vs CP 24 MESES
B19: 2. PRECIO DEL TERMINAL POR GRUPO DE TARIFAS | I19: DxC CAPTA | O19: DxC PORTABILIDAD | U19: DxC CAPTA | AA19: DxC PORTABILIDAD | AG19: PVPR CAPTA | AM19: PVPR PORTABILIDAD
I21: GRUPOS DE TARIFAS MOVIL | O21: GRUPOS DE TARIFAS MOVIL | U21: GRUPOS DE TARIFAS MOVIL | AA21: GRUPOS DE TARIFAS MOVIL | AG21: GRUPOS DE TARIFAS MOVIL | AM21: GRUPOS DE TARIFAS MOVIL
I23: ENTRADA PRO | J23: NORMAL PRO | K23: VALOR PRO | L23: PREMIUM PRO | M23: TOP PRO | O23: ENTRADA PRO | P23: NORMAL PRO | Q23: VALOR PRO | R23: PREMIUM PRO | S23: TOP PRO | U23: ENTRADA PRO | V23: NORMAL PRO | W23: VALOR PRO | X23: PREMIUM PRO | Y23: TOP PRO | AA23: ENTRADA PRO | AB23: NORMAL PRO | AC23: VALOR PRO | AD23: PREMIUM PRO | AE23: TOP PRO | AG23: ENTRADA PRO | AH23: NORMAL PRO | AI23: VALOR PRO | AJ23: PREMIUM PRO | AK23: TOP PRO | AM23: ENTRADA PRO | AN23: NORMAL PRO | AO23: VALOR PRO | AP23: PREMIUM PRO | AQ23: TOP PRO
B25: MARCA | C25: Modelo (Novedades) | D25: Precio Cesión | E25: Canon Digital | F25: Gama | I25: DxC (sin IVA) | J25: DxC (sin IVA) | K25: DxC (sin IVA) | L25: DxC (sin IVA) | M25: DxC (sin IVA) | O25: DxC (sin IVA) | P25: DxC (sin IVA) | Q25: DxC (sin IVA) | R25: DxC (sin IVA) | S25: DxC (sin IVA) | U25: DxC (sin IVA) | V25: DxC (sin IVA) | W25: DxC (sin IVA) | X25: DxC (sin IVA) | Y25: DxC (sin IVA) | AA25: DxC (sin IVA) | AB25: DxC (sin IVA) | AC25: DxC (sin IVA) | AD25: DxC (sin IVA) | AE25: DxC (sin IVA) | AG25: PVP (sin IVA) | AH25: PVP (sin IVA) | AI25: PVP (sin IVA) | AJ25: PVP (sin IVA) | AK25: PVP (sin IVA) | AM25: PVP (sin IVA) | AN25: PVP (sin IVA) | AO25: PVP (sin IVA) | AP25: PVP (sin IVA) | AQ25: PVP (sin IVA)
B26: ORANGE | C26: AD HOC H3 CESIÓN | D26: 0 | E26: 1.1 | F26: FIXED STYLE | I26: 0 | J26: 0 | K26: 0 | L26: 0 | M26: 0 | O26: 0 | P26: 0 | Q26: 0 | R26: 0 | S26: 0 | U26: 0 | V26: 0 | W26: 0 | X26: 0 | Y26: 0 | Z26: 0 | AA26: 0 | AB26: 0 | AC26: 0 | AD26: 0 | AE26: 0 | AG26: - | AH26: - | AI26: - | AJ26: - | AK26: - | AM26: - | AN26: - | AO26: - | AP26: - | AQ26: -
B27: ORANGE | C27: ADOC D30 | D27: 239 | E27: 3.75 | F27: FIXED STYLE | I27: 116 | J27: 166 | K27: 215 | L27: 239 | M27: 239 | O27: 116 | P27: 166 | Q27: 215 | R27: 239 | S27: 239 | U27: 0 | V27: 0 | W27: 0 | X27: 0 | Y27: 0 | Z27: 0 | AA27: 0 | AB27: 0 | AC27: 0 | AD27: 0 | AE27: 0 | AG27: 123 | AH27: 73 | AI27: 24 | AJ27: 0 | AK27: 0 | AM27: 123 | AN27: 73 | AO27: 24 | AP27: 0 | AQ27: 0
B28: ORANGE | C28: ADOC D30 CESIÓN | D28: 0 | E28: 3.75 | F28: FIXED STYLE | I28: 0 | J28: 0 | K28: 0 | L28: 0 | M28: 0 | O28: 0 | P28: 0 | Q28: 0 | R28: 0 | S28: 0 | U28: 0 | V28: 0 | W28: 0 | X28: 0 | Y28: 0 | Z28: 0 | AA28: 0 | AB28: 0 | AC28: 0 | AD28: 0 | AE28: 0 | AG28: - | AH28: - | AI28: - | AJ28: - | AK28: - | AM28: - | AN28: - | AO28: - | AP28: - | AQ28: -
B29: AD HOC | C29: ADOC SC01 | D29: 64 | E29: 1.1 | F29: VOZ | I29: 64 | J29: 64 | K29: 0 | L29: 0 | M29: 0 | O29: 64 | P29: 64 | Q29: 0 | R29: 0 | S29: 0 | U29: 0 | V29: 0 | W29: 0 | X29: 0 | Y29: 0 | Z29: 0 | AA29: 0 | AB29: 0 | AC29: 0 | AD29: 0 | AE29: 0 | AG29: 0 | AH29: 0 | AI29: - | AJ29: - | AK29: - | AM29: 0 | AN29: 0 | AO29: - | AP29: - | AQ29: -
B30: ADOC | C30: ADOC SC04 | D30: 77 | E30: 1.1 | F30: VOZ | I30: 77 | J30: 77 | K30: 0 | L30: 0 | M30: 0 | O30: 77 | P30: 77 | Q30: 0 | R30: 0 | S30: 0 | U30: 0 | V30: 0 | W30: 0 | X30: 0 | Y30: 0 | Z30: 0 | AA30: 0 | AB30: 0 | AC30: 0 | AD30: 0 | AE30: 0 | AG30: 0 | AH30: 0 | AI30: - | AJ30: - | AK30: - | AM30: 0 | AN30: 0 | AO30: - | AP30: - | AQ30: -
B31: APPLE | C31: APPLE AIRPODS 4 | D31: 137 | E31: 0 | F31: OC_AURICULARES | I31: 52 | J31: 72 | K31: 95 | L31: 112 | M31: 145 | O31: 97 | P31: 127 | Q31: 176 | R31: 224 | S31: 224 | U31: 0 | V31: 0 | W31: 0 | X31: 0 | Y31: 0 | Z31: 0 | AA31: 0 | AB31: 0 | AC31: 0 | AD31: 0 | AE31: 0 | AG31: 85 | AH31: 65 | AI31: 42 | AJ31: 25 | AK31: -8 | AM31: 40 | AN31: 10 | AO31: -39 | AP31: -86.54 | AQ31: -86.54
B32: APPLE | C32: APPLE AIRPODS 4 CON CANCELACION ACTIVA RUIDO | D32: 184 | E32: 0 | F32: OC_AURICULARES | I32: 52 | J32: 72 | K32: 95 | L32: 112 | M32: 145 | O32: 97 | P32: 127 | Q32: 176 | R32: 241 | S32: 250 | U32: 0 | V32: 0 | W32: 0 | X32: 0 | Y32: 0 | Z32: 0 | AA32: 0 | AB32: 0 | AC32: 0 | AD32: 0 | AE32: 0 | AG32: 132 | AH32: 112 | AI32: 89 | AJ32: 72 | AK32: 39 | AM32: 87 | AN32: 57 | AO32: 8 | AP32: -57 | AQ32: -66.08
B33: APPLE | C33: APPLE AIRPODS PRO 2a GENERACION MAGSAFE USBC | D33: 279 | E33: 0 | F33: OC_AURICULARES | I33: 89 | J33: 109 | K33: 132 | L33: 149 | M33: 182 | O33: 134 | P33: 164 | Q33: 213 | R33: 278 | S33: 373 | U33: 0 | V33: 0 | W33: 0 | X33: 0 | Y33: 0 | Z33: 0 | AA33: 0 | AB33: 0 | AC33: 0 | AD33: 0 | AE33: 0 | AG33: 190.46 | AH33: 170.46 | AI33: 147.46 | AJ33: 130.46 | AK33: 97.46 | AM33: 145.46 | AN33: 115.46 | AO33: 66.46 | AP33: 1.46 | AQ33: -94.23
B34: APPLE | C34: APPLE WATCH S10 CELLULAR 42MM | D34: 532 | E34: 2.5 | F34: OC_SMART WATCH | I34: 52 | J34: 138 | K34: 161 | L34: 178 | M34: 211 | O34: 97 | P34: 223 | Q34: 292 | R34: 347 | S34: 479 | U34: 0 | V34: 0 | W34: 0 | X34: 0 | Y34: 0 | Z34: 0 | AA34: 0 | AB34: -30 | AC34: -50 | AD34: -40 | AE34: -60 | AG34: 480 | AH34: 393.81 | AI34: 370.81 | AJ34: 353.81 | AK34: 320.81 | AM34: 435 | AN34: 308.81 | AO34: 239.81 | AP34: 184.81 | AQ34: 52.81
B35: APPLE | C35: APPLE WATCH S10 CELLULAR 46MM | D35: 555 | E35: 2.5 | F35: OC_SMART WATCH | I35: 52 | J35: 139 | K35: 162 | L35: 179 | M35: 212 | O35: 97 | P35: 224 | Q35: 293 | R35: 348 | S35: 480 | U35: 0 | V35: 0 | W35: 0 | X35: 0 | Y35: 0 | Z35: 0 | AA35: 0 | AB35: -30 | AC35: -50 | AD35: -40 | AE35: -60 | AG35: 503 | AH35: 416.25 | AI35: 393.25 | AJ35: 376.25 | AK35: 343.25 | AM35: 458 | AN35: 331.25 | AO35: 262.25 | AP35: 207.25 | AQ35: 75.25
B36: APPLE | C36: APPLE WATCH S9 CELLULAR 45MM | D36: 555 | E36: 2.5 | F36: OC_SMART WATCH | I36: 52 | J36: 139 | K36: 162 | L36: 179 | M36: 212 | O36: 97 | P36: 224 | Q36: 293 | R36: 348 | S36: 480 | U36: 0 | V36: 0 | W36: 0 | X36: 0 | Y36: 0 | Z36: 0 | AA36: 0 | AB36: -30 | AC36: -50 | AD36: -40 | AE36: -60 | AG36: 503 | AH36: 416.25 | AI36: 393.25 | AJ36: 376.25 | AK36: 343.25 | AM36: 458 | AN36: 331.25 | AO36: 262.25 | AP36: 207.25 | AQ36: 75.25
B37: AD HOC | C37: AURICULARES AD HOC BT01 | D37: 71 | E37: 0 | F37: OC_AURICULARES | I37: 71 | J37: 71 | K37: 71 | L37: 71 | M37: 71 | O37: 71 | P37: 71 | Q37: 71 | R37: 71 | S37: 71 | U37: 0 | V37: 0 | W37: 0 | X37: 0 | Y37: 0 | Z37: 0 | AA37: 0 | AB37: 0 | AC37: 0 | AD37: 0 | AE37: 0 | AG37: 0 | AH37: 0 | AI37: 0 | AJ37: 0 | AK37: 0 | AM37: 0 | AN37: 0 | AO37: 0 | AP37: 0 | AQ37: 0
B38: AD HOC | C38: AURICULARES AD HOC HC01 | D38: 49 | E38: 0 | F38: OC_AURICULARES | I38: 49 | J38: 49 | K38: 49 | L38: 49 | M38: 49 | O38: 49 | P38: 49 | Q38: 49 | R38: 49 | S38: 49 | U38: 0 | V38: 0 | W38: 0 | X38: 0 | Y38: 0 | Z38: 0 | AA38: 0 | AB38: 0 | AC38: 0 | AD38: 0 | AE38: 0 | AG38: 0 | AH38: 0 | AI38: 0 | AJ38: 0 | AK38: 0 | AM38: 0 | AN38: 0 | AO38: 0 | AP38: 0 | AQ38: 0
B39: SAMSUNG | C39: AURICULARES SAMSUNG GALAXY BUDS 3 | D39: 172 | E39: 0 | F39: OC_AURICULARES | I39: 82 | J39: 102 | K39: 125 | L39: 142 | M39: 175 | O39: 127 | P39: 157 | Q39: 206 | R39: 244 | S39: 244 | U39: 0 | V39: 0 | W39: 0 | X39: 0 | Y39: 0 | Z39: 0 | AA39: 0 | AB39: 0 | AC39: 0 | AD39: 0 | AE39: 0 | AG39: 90 | AH39: 70 | AI39: 47 | AJ39: 30 | AK39: -3 | AM39: 45 | AN39: 15 | AO39: -34 | AP39: -72 | AQ39: -72
B40: SAMSUNG | C40: AURICULARES SAMSUNG GALAXY BUDS 3 PRO | D40: 240 | E40: 0 | F40: OC_AURICULARES | I40: 103 | J40: 123 | K40: 146 | L40: 163 | M40: 196 | O40: 148 | P40: 178 | Q40: 227 | R40: 292 | S40: 308 | U40: 0 | V40: 0 | W40: 0 | X40: 0 | Y40: 0 | Z40: 0 | AA40: 0 | AB40: 0 | AC40: 0 | AD40: 0 | AE40: 0 | AG40: 137 | AH40: 117 | AI40: 94 | AJ40: 77 | AK40: 44 | AM40: 92 | AN40: 62 | AO40: 13 | AP40: -52 | AQ40: -67.5
B41: SPC | C41: AURICULARES SPC BRAVE PRO | D41: 44 | E41: 0 | F41: OC_AURICULARES | I41: 44 | J41: 44 | K41: 44 | L41: 44 | M41: 44 | O41: 44 | P41: 44 | Q41: 44 | R41: 44 | S41: 44 | U41: 0 | V41: 0 | W41: 0 | X41: 0 | Y41: 0 | Z41: 0 | AA41: 0 | AB41: 0 | AC41: 0 | AD41: 0 | AE41: 0 | AG41: 0 | AH41: 0 | AI41: 0 | AJ41: 0 | AK41: 0 | AM41: 0 | AN41: 0 | AO41: 0 | AP41: 0 | AQ41: 0
B42: SPC | C42: AURICULARES SPC DREAMER PRO | D42: 77 | E42: 0 | F42: OC_AURICULARES | I42: 77 | J42: 77 | K42: 77 | L42: 77 | M42: 77 | O42: 77 | P42: 77 | Q42: 77 | R42: 77 | S42: 77 | U42: 0 | V42: 0 | W42: 0 | X42: 0 | Y42: 0 | Z42: 0 | AA42: 0 | AB42: 0 | AC42: 0 | AD42: 0 | AE42: 0 | AG42: 0 | AH42: 0 | AI42: 0 | AJ42: 0 | AK42: 0 | AM42: 0 | AN42: 0 | AO42: 0 | AP42: 0 | AQ42: 0
... B106: OPPO | C106: OPPO RENO12 PRO 512GB 5G | D106: 524 | E106: 3.25 | F106: SMARTPHONE | I106: 214 | J106: 234 | K106: 257 | L106: 274 | M106: 307 | O106: 259 | P106: 319 | Q106: 388 | R106: 443 | S106: 584 | U106: 0 | V106: 0 | W106: 0 | X106: 0 | Y106: 0 | Z106: 0 | AA106: 0 | AB106: -30 | AC106: -50 | AD106: -40 | AE106: -60 | AG106: 310.42 | AH106: 290.42 | AI106: 267.42 | AJ106: 250.42 | AK106: 217.42 | AM106: 265.42 | AN106: 205.42 | AO106: 136.42 | AP106: 81.42 | AQ106: -59.58
B107: ORANGE | C107: ORANGE GAMA 120 4G | D107: 74 | E107: 1.1 | F107: FIXED STYLE | I107: 74 | J107: 74 | K107: 74 | L107: 74 | M107: 74 | O107: 74 | P107: 0 | Q107: 0 | R107: 0 | S107: 0 | U107: 0 | V107: 0 | W107: 0 | X107: 0 | Y107: 0 | Z107: 0 | AA107: 0 | AB107: 0 | AC107: 0 | AD107: 0 | AE107: 0 | AG107: 0 | AH107: 0 | AI107: 0 | AJ107: 0 | AK107: 0 | AM107: 0 | AN107: - | AO107: - | AP107: - | AQ107: -
B108: ORANGE | C108: ORANGE GAMA 401 CESIÓN | D108: 0 | E108: 1.1 | F108: FIXED STYLE | I108: 0 | J108: 0 | K108: 0 | L108: 0 | M108: 0 | O108: 0 | P108: 0 | Q108: 0 | R108: 0 | S108: 0 | U108: 0 | V108: 0 | W108: 0 | X108: 0 | Y108: 0 | Z108: 0 | AA108: 0 | AB108: 0 | AC108: 0 | AD108: 0 | AE108: 0 | AG108: - | AH108: - | AI108: - | AJ108: - | AK108: - | AM108: - | AN108: - | AO108: - | AP108: - | AQ108: -
B109: ORANGE | C109: ORANGE GAMA 402 | D109: 70 | E109: 1.1 | F109: FIXED STYLE | I109: 70 | J109: 0 | K109: 0 | L109: 0 | M109: 0 | O109: 70 | P109: 0 | Q109: 0 | R109: 0 | S109: 0 | U109: 0 | V109: 0 | W109: 0 | X109: 0 | Y109: 0 | Z109: 0 | AA109: 0 | AB109: 0 | AC109: 0 | AD109: 0 | AE109: 0 | AG109: 0 | AH109: - | AI109: - | AJ109: - | AK109: - | AM109: 0 | AN109: - | AO109: - | AP109: - | AQ109: -
B110: ORANGE | C110: ORANGE GAMA 402 CESIÓN | D110: 0 | E110: 1.1 | F110: FIXED STYLE | I110: 0 | J110: 0 | K110: 0 | L110: 0 | M110: 0 | O110: 0 | P110: 0 | Q110: 0 | R110: 0 | S110: 0 | U110: 0 | V110: 0 | W110: 0 | X110: 0 | Y110: 0 | Z110: 0 | AA110: 0 | AB110: 0 | AC110: 0 | AD110: 0 | AE110: 0 | AG110: - | AH110: - | AI110: - | AJ110: - | AK110: - | AM110: - | AN110: - | AO110: - | AP110: - | AQ110: -
B111: ORANGE | C111: ORANGE GAMA 704 | D111: 104 | E111: 1.1 | F111: FIXED STYLE | I111: 80 | J111: 0 | K111: 0 | L111: 0 | M111: 0 | O111: 80 | P111: 0 | Q111: 0 | R111: 0 | S111: 0 | U111: 0 | V111: 0 | W111: 0 | X111: 0 | Y111: 0 | Z111: 0 | AA111: 0 | AB111: 0 | AC111: 0 | AD111: 0 | AE111: 0 | AG111: 24 | AH111: - | AI111: - | AJ111: - | AK111: - | AM111: 24 | AN111: - | AO111: - | AP111: - | AQ111: -
B112: ORANGE | C112: ORANGE GAMA 704 CESIÓN | D112: 0 | E112: 1.1 | F112: FIXED STYLE | I112: 0 | J112: 0 | K112: 0 | L112: 0 | M112: 0 | O112: 0 | P112: 0 | Q112: 0 | R112: 0 | S112: 0 | U112: 0 | V112: 0 | W112: 0 | X112: 0 | Y112: 0 | Z112: 0 | AA112: 0 | AB112: 0 | AC112: 0 | AD112: 0 | AE112: 0 | AG112: - | AH112: - | AI112: - | AJ112: - | AK112: - | AM112: - | AN112: - | AO112: - | AP112: - | AQ112: -
B113: ORANGE | C113: ORANGE GAMA 803 CESIÓN | D113: 0 | E113: 1.1 | F113: FIXED STYLE | I113: 0 | J113: 0 | K113: 0 | L113: 0 | M113: 0 | O113: 0 | P113: 0 | Q113: 0 | R113: 0 | S113: 0 | U113: 0 | V113: 0 | W113: 0 | X113: 0 | Y113: 0 | Z113: 0 | AA113: 0 | AB113: 0 | AC113: 0 | AD113: 0 | AE113: 0 | AG113: - | AH113: - | AI113: - | AJ113: - | AK113: - | AM113: - | AN113: - | AO113: - | AP113: - | AQ113: -
B114: DEF | C114: PACK BALIZA CONECTADA DGT 2 UNIDADES | D114: 96 | E114: 0 | F114: OC_OTROS DISPOSITIVOS | I114: 91 | J114: 96 | K114: 96 | L114: 96 | M114: 96 | O114: 91 | P114: 96 | Q114: 96 | R114: 96 | S114: 96 | U114: 0 | V114: 0 | W114: 0 | X114: 0 | Y114: 0 | Z114: 0 | AA114: 0 | AB114: 0 | AC114: 0 | AD114: 0 | AE114: 0 | AG114: 5 | AH114: 0 | AI114: 0 | AJ114: 0 | AK114: 0 | AM114: 5 | AN114: 0 | AO114: 0 | AP114: 0 | AQ114: 0
B115: NEXTIVITY | C115: REPETIDOR NEXTIVITY CELFI CONNECT C41 | D115: 547 | E115: 0 | F115: OC_OTROS DISPOSITIVOS | I115: 352 | J115: 352 | K115: 352 | L115: 352 | M115: 352 | O115: 352 | P115: 352 | Q115: 352 | R115: 352 | S115: 352 | U115: 0 | V115: 0 | W115: 0 | X115: 0 | Y115: 0 | Z115: 0 | AA115: 0 | AB115: 0 | AC115: 0 | AD115: 0 | AE115: 0 | AG115: 195 | AH115: 195 | AI115: 195 | AJ115: 195 | AK115: 195 | AM115: 195 | AN115: 195 | AO115: 195 | AP115: 195 | AQ115: 195
B116: SAMSUNG | C116: SAMSUNG GALAXY A15 | D116: 186 | E116: 3.25 | F116: SMARTPHONE | I116: 52 | J116: 72 | K116: 95 | L116: 112 | M116: 145 | O116: 97 | P116: 127 | Q116: 176 | R116: 241 | S116: 254 | U116: 0 | V116: 0 | W116: 0 | X116: 0 | Y116: 0 | Z116: 0 | AA116: 0 | AB116: 0 | AC116: 0 | AD116: 0 | AE116: 0 | AG116: 134 | AH116: 114 | AI116: 91 | AJ116: 74 | AK116: 41 | AM116: 89 | AN116: 59 | AO116: 10 | AP116: -55 | AQ116: -67.875
...

Sheet PVP Subv - Sol Pers Pyme
B2: OFERTA TÁCTICA EMPRESAS | I2: CAPTA | O2: PORTABILIDAD
B4: ='PVP VaP - Pyme'!B4 -> 45627 | C4: ='PVP VaP - Pyme'!C4 -> 01/12 al 31/12 | I4: ENTRADA PRO | J4: NORMAL PRO | K4: VALOR PRO | L4: PREMIUM PRO | M4: TOP PRO | O4: ENTRADA PRO | P4: NORMAL PRO | Q4: VALOR PRO | R4: PREMIUM PRO | S4: TOP PRO
B5: 1. CONDICIONES DE LA OFERTA SUBVENCIONADA (según tarifa y situación del cliente) | D5: Tarifas | I5: T. Optima Plus Empresas T. Optima Plus Empresas Big + Empresas Voz y Empresas 1 | J5: T. Optima Plus Empresas T. Optima Plus Empresas Big + Empresas 5 y Empresas Intranet | K5: T. Optima Plus Empresas T. Optima Plus Empresas Big + Empresas 20 | L5: T. Optima Plus Empresas T. Optima Plus Empresas Big + Empresas Infinita | M5: T. Optima Plus Empresas T. Optima Plus Empresas Big + Empresas Internacional | O5: T. Optima Plus Empresas T. Optima Plus Empresas Big + Empresas Voz y Empresas 1 | P5: T. Optima Plus Empresas T. Optima Plus Empresas Big + Empresas 5 y Empresas Intranet | Q5: T. Optima Plus Empresas T. Optima Plus Empresas Big + Empresas 20 | R5: T. Optima Plus Empresas T. Optima Plus Empresas Big + Empresas Infinita | S5: T. Optima Plus Empresas T. Optima Plus Empresas Big + Empresas Internacional
D12: Ampliaciones (meses antigüedad) | I12: Todos | J12: Todos | K12: Todos | L12: Todos | M12: Todos | O12: Todos | P12: Todos | Q12: Todos | R12: Todos | S12: Todos
D13: Origen (Portabilidad / Migración) | I13: Capta Prepago Migracion | J13: Capta Prepago Migracion | K13: Capta Prepago Migracion | L13: Capta Prepago Migracion | M13: Capta Prepago Migracion | O13: Pospago | P13: Pospago | Q13: Pospago | R13: Pospago | S13: Pospago
D14: CP Tarifa | I14: 24 M | J14: 24 M | K14: 24 M | L14: 24 M | M14: 24 M | O14: 24 M | P14: 24 M | Q14: 24 M | R14: 24 M | S14: 24 M
D15: CP Terminal | I15: 24 M | J15: 24 M | K15: 24 M | L15: 24 M | M15: 24 M | O15: 24 M | P15: 24 M | Q15: 24 M | R15: 24 M | S15: 24 M
I16: Las condiciones de los modulos Entrada Pro y Normal Pro aplican para los terminales VOZ y FIX tanto si activan sólo voz como si activan el paquete de voz + datos | U16: DIFERENCIAS Vs MES ANTERIOR
B19: 2. PRECIO DEL TERMINAL POR GRUPO DE TARIFAS | I19: DxC CAPTA | O19: DxC PORTABILIDAD | U19: DxC CAPTA | AA19: DxC PORTABILIDAD | AG19: PVPR CAPTA | AM19: PVPR PORTABILIDAD
I21: GRUPOS DE TARIFAS MOVIL | O21: GRUPOS DE TARIFAS MOVIL | U21: GRUPOS DE TARIFAS MOVIL | AA21: GRUPOS DE TARIFAS MOVIL | AG21: GRUPOS DE TARIFAS MOVIL | AM21: GRUPOS DE TARIFAS MOVIL
I23: ENTRADA PRO | J23: NORMAL PRO | K23: VALOR PRO | L23: PREMIUM PRO | M23: TOP PRO | O23: ENTRADA PRO | P23: NORMAL PRO | Q23: VALOR PRO | R23: PREMIUM PRO | S23: TOP PRO | U23: ENTRADA PRO | V23: NORMAL PRO | W23: VALOR PRO | X23: PREMIUM PRO | Y23: TOP PRO | AA23: ENTRADA PRO | AB23: NORMAL PRO | AC23: VALOR PRO | AD23: PREMIUM PRO | AE23: TOP PRO | AG23: ENTRADA PRO | AH23: NORMAL PRO | AI23: VALOR PRO | AJ23: PREMIUM PRO | AK23: TOP PRO | AM23: ENTRADA PRO | AN23: NORMAL PRO | AO23: VALOR PRO | AP23: PREMIUM PRO | AQ23: TOP PRO
B25: MARCA | C25: Modelo (Novedades) | D25: Precio Cesión | E25: Canon Digital | F25: Gama | I25: DxC (sin IVA) | J25: DxC (sin IVA) | K25: DxC (sin IVA) | L25: DxC (sin IVA) | M25: DxC (sin IVA) | O25: DxC (sin IVA) | P25: DxC (sin IVA) | Q25: DxC (sin IVA) | R25: DxC (sin IVA) | S25: DxC (sin IVA) | U25: DxC (sin IVA) | V25: DxC (sin IVA) | W25: DxC (sin IVA) | X25: DxC (sin IVA) | Y25: DxC (sin IVA) | AA25: DxC (sin IVA) | AB25: DxC (sin IVA) | AC25: DxC (sin IVA) | AD25: DxC (sin IVA) | AE25: DxC (sin IVA) | AG25: PVP (sin IVA) | AH25: PVP (sin IVA) | AI25: PVP (sin IVA) | AJ25: PVP (sin IVA) | AK25: PVP (sin IVA) | AM25: PVP (sin IVA) | AN25: PVP (sin IVA) | AO25: PVP (sin IVA) | AP25: PVP (sin IVA) | AQ25: PVP (sin IVA)
