Workbook
Name CeldadeinicioDxCcaptaCP36: 'PVP Subv - Optima Pyme'!$BE$18
Name CeldadeinicioDxCportaCP36: 'PVP Subv - Optima Pyme'!$BK$1
Name CeldaInicioDxCCapta: 'PVP Subv - Optima Pyme'!$U$1
Name CeldaInicioDxCCapta9MAS: 'PVP Subv - Sol Pers Pyme'!$U$1
Name CeldaInicioDxCCapta9MASAAPP: 'PVP Subv - Sol Pers Pyme AAPP'!$I$1
Name CeldaInicioDxCCaptaAAPP: 'PVP Subv - Optima Pyme AAPP'!$I$1
Name CeldaInicioDxCIEW: 'PVP Subv IEW - Pyme'!$N$1
Name CeldaInicioDxCIEWAAPP: 'PVP Subv IEW - Pyme AAPP'!$N$1
Name CeldaInicioDxCPorta: 'PVP Subv - Optima Pyme'!$AA$1
Name CeldaInicioDxCPorta_36: 'PVP Subv - Optima Pyme 36'!$O$1
Name CeldaInicioDxCPorta36: 'PVP Subv - Optima Pyme 36'!$O$18
Name CeldaInicioDxCPorta9MAS: 'PVP Subv - Sol Pers Pyme'!$AA$1
Name CeldaInicioDxCPorta9MASAAPP: 'PVP Subv - Sol Pers Pyme AAPP'!$O$1
Name CeldaInicioDxCPortaAAPP: 'PVP Subv - Optima Pyme AAPP'!$O$1
Name CeldaInicioDxCVAP: 'PVP VaP - Pyme'!$Z$1
Name CeldaInicioDxCVAPIEW: 'PVP VaP IEW Pro - Pyme'!$AA$1
Name CeldaInicioPrecioCesión: 'PVP Subv - Sol Pers Pyme'!$D$1
Name CeldaInicioPrecioCesión: 'PVP Subv - Optima Pyme'!$D$1
Name CeldaInicioPrecioCesiónIEW: 'PVP Subv IEW - Pyme'!$D$1
Name CeldaInicioPVPRCapta: 'PVP Subv - Sol Pers Pyme'!$I$1
Name CeldaInicioPVPRCapta: 'PVP Subv - Optima Pyme'!$I$1
Name CeldaInicioPVPRIEW: 'PVP Subv IEW - Pyme'!$I$1
Name CeldaInicioPVPRPorta: 'PVP Subv - Sol Pers Pyme'!$O$1
Name CeldaInicioPVPRPorta: 'PVP Subv - Optima Pyme'!$O$1
Name CeldaInicioPVPRVAP: 'PVP VaP - Pyme'!$J$1
Name CeldaInicioPVPRVAPIEW: 'PVP VaP IEW Pro - Pyme'!$M$1
Name cualquiera: MR!$W$5
Name k: Tabla3[]
Name MinoraciónPROMOS: #REF!
Name no_aplica: MR!$W$4
Name SIoNO: MR!$X$4:$X$5
Name ValoresPaqueteVozDatos: MR!$U$4:$U$11
Name ValoresSVA: MR!$V$4:$V$5
Name valoresTarifa: MR!$S$4:$S$15
Name valoresTerminal: 'PVP Subv - Sol Pers Pyme'!$C$26:$C$244
Name valoresTerminal: 'PVP Subv - Optima Pyme'!$C$26:$C$238
Name valoresTerminalIEW: 'PVP Subv IEW - Pyme'!$C$25:$C$48
Name valoresTipoAlta: MR!$T$4:$T$5

Sheet LEEME
B3: CONFIGURADOR DE MARGENES | I3: Mes: | L3: ENERO | O3: 01/01 al 31/01
I4: Versión: | L4: Tarifas nuevas v0 _SD
B7: Acerca del Configurador
B9: 1.- Este configurador es una herramienta de apoyo para el análisis y viabilidad de las operaciones
B10: 2.- La información que se obtenga de esta herramienta es meramente orientativa
B11: 3.- Los datos obtenidos de la utilización de esta herramienta en ningún caso tendrán carácter vinculante
B14: Condicionantes del Configurador. El configurador contempla la estructura de Marco Retributivo y de Oferta Táctica con las siguientes excepciones / supuestos:
B16: 1.- El configurador contempla tanto la oferta VAP como la oferta subvencionada para tarifas multilínea, independientemente del tamaño y tipo de cliente, y para tarifas iew pro e internet 4G en clientes CIF 10+ y NIF 10+
B17: 2.- El configurador sólo contempla comisiones de alta para captación y portabilidad. No contempla comisión de alta para migraciones
B18: 3.- La subvención para ampliaciones de clientes con antigüedad igual o superior a 4 meses en VAP es igual a la subvención para portabilidades
B19: 4.- El configurador no contempla la oferta de bundles ni segundos dispositivos
B20: 5.- SOLO LAS CELDAS MARCADAS EN AMARILLO SON MODIFICABLES PARA CONFIGURAR LA OFERTA
B21: 6.- ASEGURATE DE VOLVER CAMBIAR EL TIPO DE TERMINAL CUANDO CAMBIES ENTRE TARIFAS DE VOZ Y DATOS Y TARIFAS DE IEW
B22: 7.- POR FAVOR, COMUNICA A TU SUPERVISOR CUALQUIER POSIBLE ANOMALIA O ERROR DETECTADO

Sheet Configurador Operaciones
A1: RENTABILIDAD DE LA OPERACIÓN MÓVIL | D1: ¿ Es Administración Pública ? | F1: NO | G1: Tipo DHO | H1: TIPO1 | J1: RENTABILIDAD DE LA OPERACIÓN FIJO
B2: IMPORTE TOTAL (24 meses) | C2: IMPORTE TOTAL (36 meses) | D2: RESUMEN DE LA OPERACIÓN | J2: MARGEN FIJO | K2: =B111 -> 6
A3: COMISIONES | B3: =SUMIFS($B$12:$B$101,$A$12:$A$101,A3) -> 0 | C3: =B3+H19+H29+H39+H49+H59+H69+H79+H89+H99+F17+F27+F37+F47+F57+F67+F77+F87+F97 -> 0 | D3: PARQUE ESPERADO DEL CLIENTE A FINAL DE MES | G3: Cliente > 40 líneas | H3: =G5+G6+K4 -> 0 | J3: BIG PYME | K3: =P119+P126+P133+P140 -> 0 | L3: =IF(AND(K3>0,K4>1),1,0) -> 0
A4: SUBVENCIÓN TERMINAL | B4: =SUMIFS($B$12:$B$101,$A$12:$A$101,A4) -> 0 | C4: =$E$17+$B$4+$E$27+$E$37+$E$47+$E$57+$E$67+$E$77+$E$87+$E$97 -> 0 | D4: Nº TOTAL DE LÍNEAS VOZ | G4: =SUMIFS(B1:B101,A1:A101,"PERFIL DE ALTA") -> 0 | J4: Puestos BIG PYME | K4: =L119+L126+L133+L140 -> 0
A5: PVPR TERMINAL (sin IVA) | B5: =SUMIFS($B$12:$B$101,$A$12:$A$101,A5) -> 0 | D5: voz sin datos | G5: =SUMIFS(B1:B101,A1:A101,"PERFIL DE ALTA",D1:D101,"multilínea",F1:F101,"sin datos") -> 0 | J5: BIG PYME acceso Móvil | K5: =O119+O126+O133+O140 -> 0 | L5: =IF(K5>0,1,0) -> 0
A6: PRECIO CESIÓN TERMINAL | B6: =SUMIFS($B$12:$B$101,$A$12:$A$101,A6) -> 0 | C6: =B6 -> 0 | D6: voz con datos | G6: =SUMIFS(B1:B101,A1:A101,"PERFIL DE ALTA",D1:D101,"multilínea")-G5 -> 0 | J6: CONECTA PYMES | K6: =M119+M126+M133+M140 -> 0 | L6: =IF(K6>1,K6,0) -> 0
A7: MARGEN | B7: =SUMIFS($B$12:$B$101,$A$12:$A$101,A7) -> 0 | C7: =C3+C4+C6 -> 0 | D7: IEW Pro | G7: =G4-G5-G6 -> 0 | J7: NETWORKPLUS | K7: =N119+N126+N133+N140 -> 0 | L7: =IF(K7>0,1,0) -> 0
H8: =(G4+IF(K4>1,K4,0)-G7) -> 0 | I8: PUNTOS | J8: CONECTA EMPRESAS | K8: =Q119+Q126+Q133+Q140 -> 0 | L8: =IF(K8>0,1,0) -> 0
A9: CLIENTE EN CARTERA | C9: NO | D9: OPERACIÓN ESTRATEGICA | F9: =IF(AND(M13="SI",H8>99),"NO",IF(C9="NO",IF(H9>19,"SI",IF(L10>0.5,"SI","NO")),IF(H9>2,"SI",IF(K6+L7+L8+L5+L3+L9+L10>0,"SI","NO")))) -> NO | G9: LINEAS ESTRATEGIA | H9: =IF(M13="SI",IF(H8>99,99,H8),H8) -> 0 | I9: =($I$15*$B$13+$I$25*$B$23+$I$35*$B$33+$I$45*$B$43+$I$55*$B$53+$I$65*$B$63+$I$75*$B$73+$I$85*$B$83+$I$95*$B$93+$B$110)/MR!$I$13 -> 0 | J9: O365 / OTROS SVAS | K9: =S119+S126+S133+S140 -> 0 | L9: =IF(K9>1,1,0) -> 0
A10: MARGEN TOTAL DE LA OPERACIÓN F+M | B10: =B7+K2+I10 -> 6 | C10: =C7+K2+I10 -> 6 | E10: con tope de 6.000 € de estrategia | G10: TOTAL ESTRATEGIA | H10: =IF(AND(M13="SI",H8>99),0,IF(F9="NO",0,J15+J25+J35+J45+J55+J65+J75+J85+J95+B110)) -> 0 | I10: =IF(H10>6000,6000-H10,0) -> 0 | J10: SOLUCIONES DIGITALES | K10: =$T$120+$T$127+$T$134+$T$141 -> 0 | L10: =SUM(L3:L9)+K10 -> 0
B12: Nº ALTAS CON ESTE PERFIL | C12: TARIFA | D12: TIPO DE TARIFA | E12: TIPO DE ALTA | F12: PAQUETE DE VOZ Y DATOS | G12: CV USUARIO | H12: MFO CON FIJO PORTADO | I12: VENTA A PLAZOS | J12: TERMINAL | K12: GAMA | L12: MÓDULO OT | M12: ÓPTIMA | N12: O2O | O12: 36 m | P12: ESTRAT
A13: PERFIL DE ALTA | B13: 0 | D13: =IFERROR(INDEX(MR!Q:Q,MATCH(C13,MR!P:P,0)),"") | I13: NO | K13: =IF(J13="","SIN TERMINAL",IF(D13="IEW",INDEX('PVP Subv IEW - Pyme'!F:F,MATCH(J13,'PVP Subv IEW - Pyme'!C:C,0)),INDEX('PVP Subv - Optima Pyme'!F:F,MATCH(J13,'PVP Subv - Optima Pyme'!C:C,0)))) -> SIN TERMINAL | L13: =IFERROR(IF(D13="IEW",INDEX('MODULOS OT IEW'!D:D,MATCH(C13,'MODULOS OT IEW'!A:A,0)),INDEX('MODULOS OT MULTILINEA'!F:F,MATCH(E13&F13&K13,'MODULOS OT MULTILINEA'!A:A,0))),"") | M13: =+IF(C13="","",IF(OR(C13="Óptima Plus Empresas",C13="Óptima Plus Empresas BIG"),"SI","NO")) | N13: =+IF(C13="","",IF($C$9="SI","NO",IF(OR(C13="Óptima Plus Empresas",C13="Óptima Plus Empresas BIG"),"SI","NO"))) | O13: =+IF(N13="NO","NO",IF(AND(E13="portabilidad",L13<>"ENTRADA PRO"),"SI","NO")) -> NO | P13: =IF(AND(E13="capta",F13="EMPRESAS VOZ"),0,1) -> 1
B14: IMPORTE TOTAL | C14: IMPORTE UNITARIO | D14: PAQUETE DE VOZ Y DATOS | E14: ACTIVACION | F14: ACTIVACION CP 24 POR TERMINAL | G14: SVAs | H14: O2O | I14: ESTRATEGICA | N14: =IF(N13="SI",1,0) -> 0
A15: COMISIONES | B15: =C15*B13 -> 0 | C15: =D15+E15+F15+G15-H16*N14+I15 -> 0 | D15: =IFERROR(IF(AND(M13="SI",$G$3="Cliente 1-19 líneas"),SUMIFS(MR!$B$5:$B$13,MR!$A$5:$A$13,F13),IF(AND(M13="SI",$G$3="Cliente 20-39 líneas"),SUMIFS(MR!$C$5:$C$13,MR!$A$5:$A$13,F13),IF(AND(M13="SI",$G$3="Cliente > 40 líneas"),SUMIFS(MR!$D$5:$D$13,MR!$A$5:$A$13,F13),IF(AND(M13="NO",$G$3="Cliente 1-19 líneas"),SUMIFS(MR!$B$17:$B$25,MR!$A$17:$A$25,F13),IF(AND(M13="NO",$G$3="Cliente 20-39 líneas"),SUMIFS(MR!$C$17:$C$25,MR!$A$17:$A$25,F13),IF(AND(M13="NO",$G$3="Cliente > 40 líneas"),SUMIFS(MR!$D$17:$D$25,MR!$A$17:$A$25,F13),0)))))),)+IFERROR(IF(AND(M13="SI",$G$3="Cliente 1-19 líneas"),SUMIFS(MR!$B$30:$B$37,MR!$A$30:$A$37,F13),IF(AND(M13="SI",$G$3="Cliente 20-39 líneas"),SUMIFS(MR!$C$30:$C$37,MR!$A$30:$A$37,F13),IF(AND(M13="SI",$G$3="Cliente > 40 líneas"),SUMIFS(MR!$D$30:$D$37,MR!$A$30:$A$37,F13),IF(AND(M13="NO",$G$3="Cliente 1-19 líneas"),SUMIFS(MR!$B$41:$B$48,MR!$A$41:$A$48,F13),IF(AND(M13="NO",$G$3="Cliente 20-39 líneas"),SUMIFS(MR!$C$41:$C$48,MR!$A$41:$A$48,F13),IF(AND(M13="NO",$G$3="Cliente > 40 líneas"),SUMIFS(MR!$D$41:$D$48,MR!$A$41:$A$48,F13),0)))))),) -> 0 | E15: =IFERROR(IF(AND(M13="SI",E13="capta",D13="multilínea"),SUMIFS(MR!$E$5:$E$13,MR!$A$5:$A$13,F13),IF(AND(M13="SI",E13="portabilidad",D13="multilínea"),SUMIFS(MR!$F$5:$F$13,MR!$A$5:$A$13,F13),IF(AND(M13="NO",E13="capta",D13="multilínea"),SUMIFS(MR!$E$17:$E$25,MR!$A$17:$A$25,F13),IF(AND(M13="NO",E13="portabilidad",D13="multilínea"),SUMIFS(MR!$F$17:$F$25,MR!$A$17:$A$25,F13),IF(AND(M13="NO",E13="capta",D13="IEW"),SUMIFS(MR!$B$53:$B$61,MR!$A$53:$A$61,C13),IF(AND(M13="NO",E13="portabilidad",D13="IEW"),SUMIFS(MR!$B$53:$B$61,MR!$A$53:$A$61,C13),0)))))),)+IFERROR(IF(AND(M13="SI",E13="capta",D13="multilínea"),SUMIFS(MR!$E$30:$E$37,MR!$A$30:$A$37,F13),IF(AND(M13="SI",E13="portabilidad",D13="multilínea"),SUMIFS(MR!$F$30:$F$37,MR!$A$30:$A$37,F13),IF(AND(M13="NO",E13="capta",D13="multilínea"),SUMIFS(MR!$E$48:$E$398,MR!$A$41:$A$48,F13),IF(AND(M13="NO",E13="portabilidad",D13="multilínea"),SUMIFS(MR!$F$41:$F$48,MR!$A$41:$A$48,F13),0)))),) -> 0 | F15: =(IFERROR(IF(K13="SIN TERMINAL",0,IF(I13="SI",10,SUMIFS(MR!$G$6:$G$11,MR!$A$6:$A$11,F13))),0))*K15 -> 0 | G15: =IFERROR(IF(D13="multilínea",IF(G13="SI",MR!$N$4,0)+IF(H13="SI",MR!$N$5,0),0),0) -> 0 | I15: =(IF(D13="multilínea",IF($F$9="SI",IF($M13="SI",SUMIFS(MR!$I$6:$I$11,MR!$A$6:$A$11,F13),SUMIFS(MR!$I$18:$I$23,MR!$A$18:$A$23,F13))),SUMIFS(MR!$D$54:$D$61,MR!$A$54:$A$61,C13)))*P13 -> 0 | J15: =IF(M13="SI",IF(B13>99,99*I15,I15*B13),I15*B13) -> 0 | K15: =IF(IFERROR(SEARCH("CESIÓN",$J13,1),0)>0,0,1) -> 1
A16: SUBVENCIÓN TERMINAL | B16: =IFERROR(C16*B13,"SIN OFERTA") -> SIN OFERTA | C16: =IFERROR(IFERROR(IF($F$1="NO", IF(I13="SI",IF(E13="portabilidad", IF(D13="multilínea",IF(AND(C13<>"Soluciones Personalizadas RPV",C13<>"Soluciones Personalizadas Centrex"), OFFSET(CeldaInicioDxCVAP,MATCH(J13,'PVP VaP - Pyme'!C:C,0)-1,MATCH(L13,'PVP VaP - Pyme'!$Z$22:$AL$22,0)-1) +OFFSET(CeldaInicioDxCVAP,MATCH(J13,'PVP VaP - Pyme'!C:C,0)-1,MATCH(L13,'PVP VaP - Pyme'!$Z$22:$AL$22,0)))), IF(D13="IEW", OFFSET(CeldaInicioDxCVAPIEW,MATCH(J13,'PVP VaP IEW Pro - Pyme'!C:C,0)-1,MATCH(L13,'PVP VaP IEW Pro - Pyme'!$AA$22:$AH$22,0)-1) +OFFSET(CeldaInicioDxCVAPIEW,MATCH(J13,'PVP VaP IEW Pro - Pyme'!C:C,0)-1,MATCH(L13,'PVP VaP IEW Pro - Pyme'!$AA$22:$AH$22,0)), )), IF(M13="","SIN OFERTA",IF(M13="SI",IF(B17="SIN OFERTA",B17,IF(D13="IEW",OFFSET(CeldaInicioDxCIEW,MATCH(J13,'PVP Subv IEW - Pyme'!C:C,0)-1,MATCH(L13,'PVP Subv IEW - Pyme'!$I$4:$L$4,0)-1),OFFSET(IF(E13="portabilidad",CeldaInicioDxCPorta,CeldaInicioDxCCapta),MATCH(J13,'PVP Subv - Optima Pyme'!$C:$C,0)-1,MATCH(L13,'PVP Subv - Optima Pyme'!$I$4:$M$4,0)-1))), IF(B17="SIN OFERTA",B17,IF(D13="IEW",OFFSET(CeldaInicioDxCIEW,MATCH(J13,'PVP Subv IEW - Pyme'!C:C,0)-1,MATCH(L13,'PVP Subv IEW - Pyme'!$I$4:$L$4,0)-1),OFFSET(IF(E13="portabilidad",CeldaInicioDxCPorta9MAS,CeldaInicioDxCCapta9MAS),MATCH(J13,'PVP Subv - Sol Pers Pyme'!$C:$C,0)-1,MATCH(L13,'PVP Subv - Sol Pers Pyme'!$I$4:$M$4,0)-1))))))) +IF($F$1="SI", IF(I13="SI",IF(E13="portabilidad", IF(D13="multilínea",IF(AND(C13<>"Soluciones Personalizadas RPV",C13<>"Soluciones Personalizadas Centrex"), OFFSET(CeldaInicioDxCVAP,MATCH(J13,'PVP VaP - Pyme'!C:C,0)-1,MATCH(L13,'PVP VaP - Pyme'!$Z$22:$AL$22,0)-1) +OFFSET(CeldaInicioDxCVAP,MATCH(J13,'PVP VaP - Pyme'!C:C,0)-1,MATCH(L13,'PVP VaP - Pyme'!$Z$22:$AL$22,0)))), IF(D13="IEW", OFFSET(CeldaInicioDxCVAPIEW,MATCH(J13,'PVP VaP IEW Pro - Pyme'!C:C,0)-1,MATCH(L13,'PVP VaP IEW Pro - Pyme'!$AA$22:$AH$22,0)-1) +OFFSET(CeldaInicioDxCVAPIEW,MATCH(J13,'PVP VaP IEW Pro - Pyme'!C:C,0)-1,MATCH(L13,'PVP VaP IEW Pro - Pyme'!$AA$22:$AH$22,0)), )), IF(M13="","SIN OFERTA",IF(M13="SI",IF(B17="SIN OFERTA",B17,IF(D13="IEW",OFFSET(CeldaInicioDxCIEWAAPP,MATCH(J13,'PVP Subv IEW - Pyme AAPP'!C:C,0)-1,MATCH(L13,'PVP Subv IEW - Pyme AAPP'!$I$4:$L$4,0)-1),OFFSET(IF(E13="portabilidad",CeldaInicioDxCPortaAAPP,CeldaInicioDxCCaptaAAPP),MATCH(J13,'PVP Subv - Optima Pyme AAPP'!$C:$C,0)-1,MATCH(L13,'PVP Subv - Optima Pyme AAPP'!$I$4:$M$4,0)-1))), IF(B17="SIN OFERTA",B17,IF(D13="IEW",OFFSET(CeldaInicioDxCIEWAAPP,MATCH(J13,'PVP Subv IEW - Pyme AAPP'!C:C,0)-1,MATCH(L13,'PVP Subv IEW - Pyme AAPP'!$I$4:$L$4,0)-1),OFFSET(IF(E13="portabilidad",CeldaInicioDxCPorta9MASAAPP,CeldaInicioDxCCapta9MASAAPP),MATCH(J13,'PVP Subv - Sol Pers Pyme AAPP'!$C:$C,0)-1,MATCH(L13,'PVP Subv - Sol Pers Pyme AAPP'!$I$4:$M$4,0)-1))))))),"SIN OFERTA")+D16,"SIN OFERTA") -> SIN OFERTA | E16: =IFERROR(F16*B13,"SIN OFERTA") -> SIN OFERTA | F16: =IF(O13="SI",OFFSET(CeldadeinicioDxCportaCP36,MATCH(J13,'PVP Subv - Optima Pyme'!$C:$C,0)-1,MATCH(L13,'PVP Subv - Optima Pyme'!$BK$23:$BO$23,0)-1),"-") -> - | H16: =IFERROR(IF(N13="NO",0,SUMIFS(MR!$N$17:$N$21,MR!$M$17:$M$21,H15)),0) -> 0
A17: PVPR TERMINAL (sin IVA) | B17: =IFERROR(C17*B13,"SIN OFERTA") -> 0 | D17: Dif. CP 24 m | E17: =IF(E16="SIN OFERTA",0,(E16-B16)) -> 0 | F17: =IF(B16="SIN OFERTA",0,5*B13) -> 0 | G17: Válida en módulos: | H17: =IFERROR(INDEX(Tabla32[APLICA],MATCH(H15,Tabla32[PROMO],0)),"")
A18: PRECIO CESIÓN TERMINAL | B18: =IFERROR(C18*B13,"SIN OFERTA") -> SIN OFERTA | C18: =IF(M13="SI",IFERROR(-IF(D13="IEW",OFFSET(CeldaInicioPrecioCesiónIEW,MATCH(J13,'PVP Subv IEW - Pyme'!C:C,0)-1,0),OFFSET(CeldaInicioPrecioCesión,MATCH(J13,'PVP Subv - Optima Pyme'!$C:$C,0)-1,0)),"SIN OFERTA"), IFERROR(-IF(D13="IEW",OFFSET(CeldaInicioPrecioCesiónIEW,MATCH(J13,'PVP Subv IEW - Pyme'!C:C,0)-1,0),OFFSET(CeldaInicioPrecioCesión,MATCH(J13,'PVP Subv - Sol Pers Pyme'!$C:$C,0)-1,0)),"SIN OFERTA")) -> SIN OFERTA | H18: =IF(H16=12,H16+MR!$L$24,IF(H16=18,H16+MR!$L$23,IF(H16=48,H16+MR!$L$22,0))) -> 0
A19: MARGEN | B19: =IFERROR(B13*C19,"SIN OFERTA") -> 0 | C19: =IFERROR(C15+IF(NOT(ISNUMBER(C16)),0,C16)+IF(NOT(ISNUMBER(C17)),0,C17)+IF(NOT(ISNUMBER(C18)),0,C18),"SIN OFERTA") -> 0 | D19: MARGEN 36 | E19: =IFERROR(B13*F19,"SIN OFERTA") -> 0 | F19: =IFERROR(C19+(E17/B13),0) -> 0 | H19: =(H16-H18)*B13 -> 0 | I19: dif. Cp 24
A22: SUBVENCIÓN TERMINAL | B22: Nº ALTAS CON ESTE PERFIL | C22: TARIFA | D22: TIPO DE TARIFA | E22: TIPO DE ALTA | F22: PAQUETE DE VOZ Y DATOS | G22: CV USUARIO | H22: MFO CON FIJO PORTADO | I22: VENTA A PLAZOS | J22: TERMINAL | K22: GAMA | L22: MÓDULO OT | M22: ÓPTIMA | N22: O2O | O22: 36 m | P22: ESTRAT
A23: PERFIL DE ALTA | D23: =IFERROR(INDEX(MR!Q:Q,MATCH(C23,MR!P:P,0)),"") | I23: NO | K23: =IF(J23="","SIN TERMINAL",IF(D23="IEW",INDEX('PVP Subv IEW - Pyme'!F:F,MATCH(J23,'PVP Subv IEW - Pyme'!C:C,0)),INDEX('PVP Subv - Optima Pyme'!F:F,MATCH(J23,'PVP Subv - Optima Pyme'!C:C,0)))) -> SIN TERMINAL | L23: =IFERROR(IF(D23="IEW",INDEX('MODULOS OT IEW'!D:D,MATCH(C23,'MODULOS OT IEW'!A:A,0)),INDEX('MODULOS OT MULTILINEA'!F:F,MATCH(E23&F23&K23,'MODULOS OT MULTILINEA'!A:A,0))),"") | M23: =+IF(C23="","",IF(OR(C23="Óptima Plus Empresas",C23="Óptima Plus Empresas BIG"),"SI","NO")) | N23: =+IF(C23="","",IF($C$9="SI","NO",IF(OR(C23="Óptima Plus Empresas",C23="Óptima Plus Empresas BIG"),"SI","NO"))) | O23: =+IF(N23="NO","NO",IF(AND(E23="portabilidad",L23<>"ENTRADA PRO"),"SI","NO")) -> NO | P23: =IF(AND(E23="capta",F23="EMPRESAS VOZ"),0,1) -> 1
B24: IMPORTE TOTAL | C24: IMPORTE UNITARIO | D24: PAQUETE DE VOZ Y DATOS | E24: ACTIVACION | F24: ACTIVACION CP 24 POR TERMINAL | G24: SVAs | H24: O2O | I24: ESTRATEGICA | N24: =IF(N23="SI",1,0) -> 0
A25: COMISIONES | B25: =C25*B23 -> 0 | C25: =D25+E25+F25+G25-H26*N24+I25 -> 0 | D25: =IFERROR(IF(AND(M23="SI",$G$3="Cliente 1-19 líneas"),SUMIFS(MR!$B$5:$B$13,MR!$A$5:$A$13,F23),IF(AND(M23="SI",$G$3="Cliente 20-39 líneas"),SUMIFS(MR!$C$5:$C$13,MR!$A$5:$A$13,F23),IF(AND(M23="SI",$G$3="Cliente > 40 líneas"),SUMIFS(MR!$D$5:$D$13,MR!$A$5:$A$13,F23),IF(AND(M23="NO",$G$3="Cliente 1-19 líneas"),SUMIFS(MR!$B$17:$B$25,MR!$A$17:$A$25,F23),IF(AND(M23="NO",$G$3="Cliente 20-39 líneas"),SUMIFS(MR!$C$17:$C$25,MR!$A$17:$A$25,F23),IF(AND(M23="NO",$G$3="Cliente > 40 líneas"),SUMIFS(MR!$D$17:$D$25,MR!$A$17:$A$25,F23),0)))))),)+IFERROR(IF(AND(M23="SI",$G$3="Cliente 1-19 líneas"),SUMIFS(MR!$B$30:$B$37,MR!$A$30:$A$37,F23),IF(AND(M23="SI",$G$3="Cliente 20-39 líneas"),SUMIFS(MR!$C$30:$C$37,MR!$A$30:$A$37,F23),IF(AND(M23="SI",$G$3="Cliente > 40 líneas"),SUMIFS(MR!$D$30:$D$37,MR!$A$30:$A$37,F23),IF(AND(M23="NO",$G$3="Cliente 1-19 líneas"),SUMIFS(MR!$B$41:$B$48,MR!$A$41:$A$48,F23),IF(AND(M23="NO",$G$3="Cliente 20-39 líneas"),SUMIFS(MR!$C$41:$C$48,MR!$A$41:$A$48,F23),IF(AND(M23="NO",$G$3="Cliente > 40 líneas"),SUMIFS(MR!$D$41:$D$48,MR!$A$41:$A$48,F23),0)))))),) -> 0 | E25: =IFERROR(IF(AND(M23="SI",E23="capta",D23="multilínea"),SUMIFS(MR!$E$5:$E$13,MR!$A$5:$A$13,F23),IF(AND(M23="SI",E23="portabilidad",D23="multilínea"),SUMIFS(MR!$F$5:$F$13,MR!$A$5:$A$13,F23),IF(AND(M23="NO",E23="capta",D23="multilínea"),SUMIFS(MR!$E$17:$E$25,MR!$A$17:$A$25,F23),IF(AND(M23="NO",E23="portabilidad",D23="multilínea"),SUMIFS(MR!$F$17:$F$25,MR!$A$17:$A$25,F23),IF(AND(M23="NO",E23="capta",D23="IEW"),SUMIFS(MR!$B$53:$B$61,MR!$A$53:$A$61,C23),IF(AND(M23="NO",E23="portabilidad",D23="IEW"),SUMIFS(MR!$B$53:$B$61,MR!$A$53:$A$61,C23),0)))))),)+IFERROR(IF(AND(M23="SI",E23="capta",D23="multilínea"),SUMIFS(MR!$E$30:$E$37,MR!$A$30:$A$37,F23),IF(AND(M23="SI",E23="portabilidad",D23="multilínea"),SUMIFS(MR!$F$30:$F$37,MR!$A$30:$A$37,F23),IF(AND(M23="NO",E23="capta",D23="multilínea"),SUMIFS(MR!$E$48:$E$398,MR!$A$41:$A$48,F23),IF(AND(M23="NO",E23="portabilidad",D23="multilínea"),SUMIFS(MR!$F$41:$F$48,MR!$A$41:$A$48,F23),0)))),) -> 0 | F25: =(IFERROR(IF(K23="SIN TERMINAL",0,IF(I23="SI",10,SUMIFS(MR!$G$6:$G$11,MR!$A$6:$A$11,F23))),0))*K25 -> 0 | G25: =IFERROR(IF(D23="multilínea",IF(G23="SI",MR!$N$4,0)+IF(H23="SI",MR!$N$5,0),0),0) -> 0 | I25: =(IF(D23="multilínea",IF($F$9="SI",IF($M23="SI",SUMIFS(MR!$I$6:$I$11,MR!$A$6:$A$11,F23),SUMIFS(MR!$I$18:$I$23,MR!$A$18:$A$23,F23))),SUMIFS(MR!$D$54:$D$61,MR!$A$54:$A$61,C23)))*P23 -> 0 | J25: =IF(M23="SI",IF($B$13+$B$23>99,(99-$B$13)*I25,B23*I25),B23*I25) -> 0 | K25: =IF(IFERROR(SEARCH("CESIÓN",$J23,1),0)>0,0,1) -> 1
A26: SUBVENCIÓN TERMINAL | B26: =IFERROR(C26*B23,"SIN OFERTA") -> SIN OFERTA | C26: =IFERROR(IFERROR(IF($F$1="NO", IF(I23="SI",IF(E23="portabilidad", IF(D23="multilínea",IF(AND(C23<>"Soluciones Personalizadas RPV",C23<>"Soluciones Personalizadas Centrex"), OFFSET(CeldaInicioDxCVAP,MATCH(J23,'PVP VaP - Pyme'!C:C,0)-1,MATCH(L23,'PVP VaP - Pyme'!$Z$22:$AL$22,0)-1) +OFFSET(CeldaInicioDxCVAP,MATCH(J23,'PVP VaP - Pyme'!C:C,0)-1,MATCH(L23,'PVP VaP - Pyme'!$Z$22:$AL$22,0)))), IF(D23="IEW", OFFSET(CeldaInicioDxCVAPIEW,MATCH(J23,'PVP VaP IEW Pro - Pyme'!C:C,0)-1,MATCH(L23,'PVP VaP IEW Pro - Pyme'!$AA$22:$AH$22,0)-1) +OFFSET(CeldaInicioDxCVAPIEW,MATCH(J23,'PVP VaP IEW Pro - Pyme'!C:C,0)-1,MATCH(L23,'PVP VaP IEW Pro - Pyme'!$AA$22:$AH$22,0)), )), IF(M23="","SIN OFERTA",IF(M23="SI",IF(B27="SIN OFERTA",B27,IF(D23="IEW",OFFSET(CeldaInicioDxCIEW,MATCH(J23,'PVP Subv IEW - Pyme'!C:C,0)-1,MATCH(L23,'PVP Subv IEW - Pyme'!$I$4:$L$4,0)-1),OFFSET(IF(E23="portabilidad",CeldaInicioDxCPorta,CeldaInicioDxCCapta),MATCH(J23,'PVP Subv - Optima Pyme'!$C:$C,0)-1,MATCH(L23,'PVP Subv - Optima Pyme'!$I$4:$M$4,0)-1))), IF(B27="SIN OFERTA",B27,IF(D23="IEW",OFFSET(CeldaInicioDxCIEW,MATCH(J23,'PVP Subv IEW - Pyme'!C:C,0)-1,MATCH(L23,'PVP Subv IEW - Pyme'!$I$4:$L$4,0)-1),OFFSET(IF(E23="portabilidad",CeldaInicioDxCPorta9MAS,CeldaInicioDxCCapta9MAS),MATCH(J23,'PVP Subv - Sol Pers Pyme'!$C:$C,0)-1,MATCH(L23,'PVP Subv - Sol Pers Pyme'!$I$4:$M$4,0)-1))))))) +IF($F$1="SI", IF(I23="SI",IF(E23="portabilidad", IF(D23="multilínea",IF(AND(C23<>"Soluciones Personalizadas RPV",C23<>"Soluciones Personalizadas Centrex"), OFFSET(CeldaInicioDxCVAP,MATCH(J23,'PVP VaP - Pyme'!C:C,0)-1,MATCH(L23,'PVP VaP - Pyme'!$Z$22:$AL$22,0)-1) +OFFSET(CeldaInicioDxCVAP,MATCH(J23,'PVP VaP - Pyme'!C:C,0)-1,MATCH(L23,'PVP VaP - Pyme'!$Z$22:$AL$22,0)))), IF(D23="IEW", OFFSET(CeldaInicioDxCVAPIEW,MATCH(J23,'PVP VaP IEW Pro - Pyme'!C:C,0)-1,MATCH(L23,'PVP VaP IEW Pro - Pyme'!$AA$22:$AH$22,0)-1) +OFFSET(CeldaInicioDxCVAPIEW,MATCH(J23,'PVP VaP IEW Pro - Pyme'!C:C,0)-1,MATCH(L23,'PVP VaP IEW Pro - Pyme'!$AA$22:$AH$22,0)), )), IF(M23="","SIN OFERTA",IF(M23="SI",IF(B27="SIN OFERTA",B27,IF(D23="IEW",OFFSET(CeldaInicioDxCIEWAAPP,MATCH(J23,'PVP Subv IEW - Pyme AAPP'!C:C,0)-1,MATCH(L23,'PVP Subv IEW - Pyme AAPP'!$I$4:$L$4,0)-1),OFFSET(IF(E23="portabilidad",CeldaInicioDxCPortaAAPP,CeldaInicioDxCCaptaAAPP),MATCH(J23,'PVP Subv - Optima Pyme AAPP'!$C:$C,0)-1,MATCH(L23,'PVP Subv - Optima Pyme AAPP'!$I$4:$M$4,0)-1))), IF(B27="SIN OFERTA",B27,IF(D23="IEW",OFFSET(CeldaInicioDxCIEWAAPP,MATCH(J23,'PVP Subv IEW - Pyme AAPP'!C:C,0)-1,MATCH(L23,'PVP Subv IEW - Pyme AAPP'!$I$4:$L$4,0)-1),OFFSET(IF(E23="portabilidad",CeldaInicioDxCPorta9MASAAPP,CeldaInicioDxCCapta9MASAAPP),MATCH(J23,'PVP Subv - Sol Pers Pyme AAPP'!$C:$C,0)-1,MATCH(L23,'PVP Subv - Sol Pers Pyme AAPP'!$I$4:$M$4,0)-1))))))),"SIN OFERTA")+D26,"SIN OFERTA") -> SIN OFERTA | E26: =IFERROR(F26*B23,"SIN OFERTA") -> SIN OFERTA | F26: =IF(O23="SI",OFFSET(CeldadeinicioDxCportaCP36,MATCH(J23,'PVP Subv - Optima Pyme'!$C:$C,0)-1,MATCH(L23,'PVP Subv - Optima Pyme'!$BK$23:$BO$23,0)-1),"-") -> - | H26: =IFERROR(IF(N23="NO",0,SUMIFS(MR!$N$17:$N$21,MR!$M$17:$M$21,H25)),0) -> 0
A27: PVPR TERMINAL (sin IVA) | B27: =IFERROR(C27*B23,"SIN OFERTA") -> 0 | D27: Dif. CP 24 m | E27: =IF(E26="SIN OFERTA",0,(E26-B26)) -> 0 | F27: =IF(B26="SIN OFERTA",0,5*B23) -> 0 | G27: Válida en módulos: | H27: =IFERROR(INDEX(Tabla32[APLICA],MATCH(H25,Tabla32[PROMO],0)),"")
A28: PRECIO CESIÓN TERMINAL | B28: =IFERROR(C28*B23,"SIN OFERTA") -> SIN OFERTA | C28: =IF(M23="SI",IFERROR(-IF(D23="IEW",OFFSET(CeldaInicioPrecioCesiónIEW,MATCH(J23,'PVP Subv IEW - Pyme'!C:C,0)-1,0),OFFSET(CeldaInicioPrecioCesión,MATCH(J23,'PVP Subv - Optima Pyme'!$C:$C,0)-1,0)),"SIN OFERTA"), IFERROR(-IF(D23="IEW",OFFSET(CeldaInicioPrecioCesiónIEW,MATCH(J23,'PVP Subv IEW - Pyme'!C:C,0)-1,0),OFFSET(CeldaInicioPrecioCesión,MATCH(J23,'PVP Subv - Sol Pers Pyme'!$C:$C,0)-1,0)),"SIN OFERTA")) -> SIN OFERTA | H28: =IF(H26=12,H26+MR!$L$24,IF(H26=18,H26+MR!$L$23,IF(H26=48,H26+MR!$L$22,0))) -> 0
A29: MARGEN | B29: =IFERROR(B23*C29,"SIN OFERTA") -> 0 | C29: =IFERROR(C25+IF(NOT(ISNUMBER(C26)),0,C26)+IF(NOT(ISNUMBER(C27)),0,C27)+IF(NOT(ISNUMBER(C28)),0,C28),"SIN OFERTA") -> 0 | D29: MARGEN 36 | E29: =IFERROR(B23*F29,"SIN OFERTA") -> 0 | F29: =IFERROR(C29+(E27/B23),0) -> 0 | H29: =(H26-H28)*B23 -> 0 | I29: dif. Cp 24
B32: Nº ALTAS CON ESTE PERFIL | C32: TARIFA | D32: TIPO DE TARIFA | E32: TIPO DE ALTA | F32: PAQUETE DE VOZ Y DATOS | G32: CV USUARIO | H32: MFO CON FIJO PORTADO | I32: VENTA A PLAZOS | J32: TERMINAL | K32: GAMA | L32: MÓDULO OT | M32: ÓPTIMA | N32: O2O | O32: 36 m | P32: ESTRAT
A33: PERFIL DE ALTA | D33: =IFERROR(INDEX(MR!Q:Q,MATCH(C33,MR!P:P,0)),"") | I33: NO | K33: =IF(J33="","SIN TERMINAL",IF(D33="IEW",INDEX('PVP Subv IEW - Pyme'!F:F,MATCH(J33,'PVP Subv IEW - Pyme'!C:C,0)),INDEX('PVP Subv - Optima Pyme'!F:F,MATCH(J33,'PVP Subv - Optima Pyme'!C:C,0)))) -> SIN TERMINAL | L33: =IFERROR(IF(D33="IEW",INDEX('MODULOS OT IEW'!D:D,MATCH(C33,'MODULOS OT IEW'!A:A,0)),INDEX('MODULOS OT MULTILINEA'!F:F,MATCH(E33&F33&K33,'MODULOS OT MULTILINEA'!A:A,0))),"") | M33: =+IF(C33="","",IF(OR(C33="Óptima Plus Empresas",C33="Óptima Plus Empresas BIG"),"SI","NO")) | N33: =+IF(C33="","",IF($C$9="SI","NO",IF(OR(C33="Óptima Plus Empresas",C33="Óptima Plus Empresas BIG"),"SI","NO"))) | O33: =+IF(N33="NO","NO",IF(AND(E33="portabilidad",L33<>"ENTRADA PRO"),"SI","NO")) -> NO | P33: =IF(AND(E33="capta",F33="EMPRESAS VOZ"),0,1) -> 1
C34: IMPORTE UNITARIO | D34: PAQUETE DE VOZ Y DATOS | E34: ACTIVACION | F34: ACTIVACION CP 24 POR TERMINAL | G34: SVAs | H34: O2O | I34: ESTRATEGICA | N34: =IF(N33="SI",1,0) -> 0
A35: COMISIONES | B35: =C35*B33 -> 0 | C35: =D35+E35+F35+G35-H36*N34+I35 -> 0 | D35: =IFERROR(IF(AND(M33="SI",$G$3="Cliente 1-19 líneas"),SUMIFS(MR!$B$5:$B$13,MR!$A$5:$A$13,F33),IF(AND(M33="SI",$G$3="Cliente 20-39 líneas"),SUMIFS(MR!$C$5:$C$13,MR!$A$5:$A$13,F33),IF(AND(M33="SI",$G$3="Cliente > 40 líneas"),SUMIFS(MR!$D$5:$D$13,MR!$A$5:$A$13,F33),IF(AND(M33="NO",$G$3="Cliente 1-19 líneas"),SUMIFS(MR!$B$17:$B$25,MR!$A$17:$A$25,F33),IF(AND(M33="NO",$G$3="Cliente 20-39 líneas"),SUMIFS(MR!$C$17:$C$25,MR!$A$17:$A$25,F33),IF(AND(M33="NO",$G$3="Cliente > 40 líneas"),SUMIFS(MR!$D$17:$D$25,MR!$A$17:$A$25,F33),0)))))),)+IFERROR(IF(AND(M33="SI",$G$3="Cliente 1-19 líneas"),SUMIFS(MR!$B$30:$B$37,MR!$A$30:$A$37,F33),IF(AND(M33="SI",$G$3="Cliente 20-39 líneas"),SUMIFS(MR!$C$30:$C$37,MR!$A$30:$A$37,F33),IF(AND(M33="SI",$G$3="Cliente > 40 líneas"),SUMIFS(MR!$D$30:$D$37,MR!$A$30:$A$37,F33),IF(AND(M33="NO",$G$3="Cliente 1-19 líneas"),SUMIFS(MR!$B$41:$B$48,MR!$A$41:$A$48,F33),IF(AND(M33="NO",$G$3="Cliente 20-39 líneas"),SUMIFS(MR!$C$41:$C$48,MR!$A$41:$A$48,F33),IF(AND(M33="NO",$G$3="Cliente > 40 líneas"),SUMIFS(MR!$D$41:$D$48,MR!$A$41:$A$48,F33),0)))))),) -> 0 | E35: =IFERROR(IF(AND(M33="SI",E33="capta",D33="multilínea"),SUMIFS(MR!$E$5:$E$13,MR!$A$5:$A$13,F33),IF(AND(M33="SI",E33="portabilidad",D33="multilínea"),SUMIFS(MR!$F$5:$F$13,MR!$A$5:$A$13,F33),IF(AND(M33="NO",E33="capta",D33="multilínea"),SUMIFS(MR!$E$17:$E$25,MR!$A$17:$A$25,F33),IF(AND(M33="NO",E33="portabilidad",D33="multilínea"),SUMIFS(MR!$F$17:$F$25,MR!$A$17:$A$25,F33),IF(AND(M33="NO",E33="capta",D33="IEW"),SUMIFS(MR!$B$53:$B$61,MR!$A$53:$A$61,C33),IF(AND(M33="NO",E33="portabilidad",D33="IEW"),SUMIFS(MR!$B$53:$B$61,MR!$A$53:$A$61,C33),0)))))),)+IFERROR(IF(AND(M33="SI",E33="capta",D33="multilínea"),SUMIFS(MR!$E$30:$E$37,MR!$A$30:$A$37,F33),IF(AND(M33="SI",E33="portabilidad",D33="multilínea"),SUMIFS(MR!$F$30:$F$37,MR!$A$30:$A$37,F33),IF(AND(M33="NO",E33="capta",D33="multilínea"),SUMIFS(MR!$E$48:$E$398,MR!$A$41:$A$48,F33),IF(AND(M33="NO",E33="portabilidad",D33="multilínea"),SUMIFS(MR!$F$41:$F$48,MR!$A$41:$A$48,F33),0)))),) -> 0 | F35: =(IFERROR(IF(K33="SIN TERMINAL",0,IF(I33="SI",10,SUMIFS(MR!$G$6:$G$11,MR!$A$6:$A$11,F33))),0))*K35 -> 0 | G35: =IFERROR(IF(D33="multilínea",IF(G33="SI",MR!$N$4,0)+IF(H33="SI",MR!$N$5,0),0),0) -> 0 | I35: =(IF(D33="multilínea",IF($F$9="SI",IF($M33="SI",SUMIFS(MR!$I$6:$I$11,MR!$A$6:$A$11,F33),SUMIFS(MR!$I$18:$I$23,MR!$A$18:$A$23,F33))),SUMIFS(MR!$D$54:$D$61,MR!$A$54:$A$61,C33)))*P33 -> 0 | J35: =IF(M33="SI",IF($B$13+$B$23+$B$33>99,(99-$B$13-$B$23)*I35,B33*I35),B33*I35) -> 0 | K35: =IF(IFERROR(SEARCH("CESIÓN",$J33,1),0)>0,0,1) -> 1
A36: SUBVENCIÓN TERMINAL | B36: =IFERROR(C36*B33,"SIN OFERTA") -> SIN OFERTA | C36: =IFERROR(IFERROR(IF($F$1="NO", IF(I33="SI",IF(E33="portabilidad", IF(D33="multilínea",IF(AND(C33<>"Soluciones Personalizadas RPV",C33<>"Soluciones Personalizadas Centrex"), OFFSET(CeldaInicioDxCVAP,MATCH(J33,'PVP VaP - Pyme'!C:C,0)-1,MATCH(L33,'PVP VaP - Pyme'!$Z$22:$AL$22,0)-1) +OFFSET(CeldaInicioDxCVAP,MATCH(J33,'PVP VaP - Pyme'!C:C,0)-1,MATCH(L33,'PVP VaP - Pyme'!$Z$22:$AL$22,0)))), IF(D33="IEW", OFFSET(CeldaInicioDxCVAPIEW,MATCH(J33,'PVP VaP IEW Pro - Pyme'!C:C,0)-1,MATCH(L33,'PVP VaP IEW Pro - Pyme'!$AA$22:$AH$22,0)-1) +OFFSET(CeldaInicioDxCVAPIEW,MATCH(J33,'PVP VaP IEW Pro - Pyme'!C:C,0)-1,MATCH(L33,'PVP VaP IEW Pro - Pyme'!$AA$22:$AH$22,0)), )), IF(M33="","SIN OFERTA",IF(M33="SI",IF(B37="SIN OFERTA",B37,IF(D33="IEW",OFFSET(CeldaInicioDxCIEW,MATCH(J33,'PVP Subv IEW - Pyme'!C:C,0)-1,MATCH(L33,'PVP Subv IEW - Pyme'!$I$4:$L$4,0)-1),OFFSET(IF(E33="portabilidad",CeldaInicioDxCPorta,CeldaInicioDxCCapta),MATCH(J33,'PVP Subv - Optima Pyme'!$C:$C,0)-1,MATCH(L33,'PVP Subv - Optima Pyme'!$I$4:$M$4,0)-1))), IF(B37="SIN OFERTA",B37,IF(D33="IEW",OFFSET(CeldaInicioDxCIEW,MATCH(J33,'PVP Subv IEW - Pyme'!C:C,0)-1,MATCH(L33,'PVP Subv IEW - Pyme'!$I$4:$L$4,0)-1),OFFSET(IF(E33="portabilidad",CeldaInicioDxCPorta9MAS,CeldaInicioDxCCapta9MAS),MATCH(J33,'PVP Subv - Sol Pers Pyme'!$C:$C,0)-1,MATCH(L33,'PVP Subv - Sol Pers Pyme'!$I$4:$M$4,0)-1))))))) +IF($F$1="SI", IF(I33="SI",IF(E33="portabilidad", IF(D33="multilínea",IF(AND(C33<>"Soluciones Personalizadas RPV",C33<>"Soluciones Personalizadas Centrex"), OFFSET(CeldaInicioDxCVAP,MATCH(J33,'PVP VaP - Pyme'!C:C,0)-1,MATCH(L33,'PVP VaP - Pyme'!$Z$22:$AL$22,0)-1) +OFFSET(CeldaInicioDxCVAP,MATCH(J33,'PVP VaP - Pyme'!C:C,0)-1,MATCH(L33,'PVP VaP - Pyme'!$Z$22:$AL$22,0)))), IF(D33="IEW", OFFSET(CeldaInicioDxCVAPIEW,MATCH(J33,'PVP VaP IEW Pro - Pyme'!C:C,0)-1,MATCH(L33,'PVP VaP IEW Pro - Pyme'!$AA$22:$AH$22,0)-1) +OFFSET(CeldaInicioDxCVAPIEW,MATCH(J33,'PVP VaP IEW Pro - Pyme'!C:C,0)-1,MATCH(L33,'PVP VaP IEW Pro - Pyme'!$AA$22:$AH$22,0)), )), IF(M33="","SIN OFERTA",IF(M33="SI",IF(B37="SIN OFERTA",B37,IF(D33="IEW",OFFSET(CeldaInicioDxCIEWAAPP,MATCH(J33,'PVP Subv IEW - Pyme AAPP'!C:C,0)-1,MATCH(L33,'PVP Subv IEW - Pyme AAPP'!$I$4:$L$4,0)-1),OFFSET(IF(E33="portabilidad",CeldaInicioDxCPortaAAPP,CeldaInicioDxCCaptaAAPP),MATCH(J33,'PVP Subv - Optima Pyme AAPP'!$C:$C,0)-1,MATCH(L33,'PVP Subv - Optima Pyme AAPP'!$I$4:$M$4,0)-1))), IF(B37="SIN OFERTA",B37,IF(D33="IEW",OFFSET(CeldaInicioDxCIEWAAPP,MATCH(J33,'PVP Subv IEW - Pyme AAPP'!C:C,0)-1,MATCH(L33,'PVP Subv IEW - Pyme AAPP'!$I$4:$L$4,0)-1),OFFSET(IF(E33="portabilidad",CeldaInicioDxCPorta9MASAAPP,CeldaInicioDxCCapta9MASAAPP),MATCH(J33,'PVP Subv - Sol Pers Pyme AAPP'!$C:$C,0)-1,MATCH(L33,'PVP Subv - Sol Pers Pyme AAPP'!$I$4:$M$4,0)-1))))))),"SIN OFERTA")+D36,"SIN OFERTA") -> SIN OFERTA | E36: =IFERROR(F36*B33,"SIN OFERTA") -> SIN OFERTA | F36: =IF(O33="SI",OFFSET(CeldadeinicioDxCportaCP36,MATCH(J33,'PVP Subv - Optima Pyme'!$C:$C,0)-1,MATCH(L33,'PVP Subv - Optima Pyme'!$BK$23:$BO$23,0)-1),"-") -> - | H36: =IFERROR(IF(N33="NO",0,SUMIFS(MR!$N$17:$N$21,MR!$M$17:$M$21,H35)),0) -> 0
A37: PVPR TERMINAL (sin IVA) | B37: =IFERROR(C37*B33,"SIN OFERTA") -> 0 | D37: Dif. CP 24 m | E37: =IF(E36="SIN OFERTA",0,(E36-B36)) -> 0 | F37: =IF(B36="SIN OFERTA",0,5*B33) -> 0 | G37: Válida en módulos: | H37: =IFERROR(INDEX(Tabla32[APLICA],MATCH(H35,Tabla32[PROMO],0)),"")
A38: PRECIO CESIÓN TERMINAL | B38: =IFERROR(C38*B33,"SIN OFERTA") -> SIN OFERTA | C38: =IF(M33="SI",IFERROR(-IF(D33="IEW",OFFSET(CeldaInicioPrecioCesiónIEW,MATCH(J33,'PVP Subv IEW - Pyme'!C:C,0)-1,0),OFFSET(CeldaInicioPrecioCesión,MATCH(J33,'PVP Subv - Optima Pyme'!$C:$C,0)-1,0)),"SIN OFERTA"), IFERROR(-IF(D33="IEW",OFFSET(CeldaInicioPrecioCesiónIEW,MATCH(J33,'PVP Subv IEW - Pyme'!C:C,0)-1,0),OFFSET(CeldaInicioPrecioCesión,MATCH(J33,'PVP Subv - Sol Pers Pyme'!$C:$C,0)-1,0)),"SIN OFERTA")) -> SIN OFERTA | H38: =IF(H36=12,H36+MR!$L$24,IF(H36=18,H36+MR!$L$23,IF(H36=48,H36+MR!$L$22,0))) -> 0
A39: MARGEN | B39: =IFERROR(B33*C39,"SIN OFERTA") -> 0 | C39: =IFERROR(C35+IF(NOT(ISNUMBER(C36)),0,C36)+IF(NOT(ISNUMBER(C37)),0,C37)+IF(NOT(ISNUMBER(C38)),0,C38),"SIN OFERTA") -> 0 | D39: MARGEN 36 | E39: =IFERROR(B33*F39,"SIN OFERTA") -> 0 | F39: =IFERROR(C39+(E37/B33),0) -> 0 | H39: =(H36-H38)*B33 -> 0 | I39: dif. Cp 24
B42: Nº ALTAS CON ESTE PERFIL | C42: TARIFA | D42: TIPO DE TARIFA | E42: TIPO DE ALTA | F42: PAQUETE DE VOZ Y DATOS | G42: CV USUARIO | H42: MFO CON FIJO PORTADO | I42: VENTA A PLAZOS | J42: TERMINAL | K42: GAMA | L42: MÓDULO OT | M42: ÓPTIMA | N42: O2O | O42: 36 m | P42: ESTRAT
A43: PERFIL DE ALTA | D43: =IFERROR(INDEX(MR!Q:Q,MATCH(C43,MR!P:P,0)),"") | K43: =IF(J43="","SIN TERMINAL",IF(D43="IEW",INDEX('PVP Subv IEW - Pyme'!F:F,MATCH(J43,'PVP Subv IEW - Pyme'!C:C,0)),INDEX('PVP Subv - Optima Pyme'!F:F,MATCH(J43,'PVP Subv - Optima Pyme'!C:C,0)))) -> SIN TERMINAL | L43: =IFERROR(IF(D43="IEW",INDEX('MODULOS OT IEW'!D:D,MATCH(C43,'MODULOS OT IEW'!A:A,0)),INDEX('MODULOS OT MULTILINEA'!F:F,MATCH(E43&F43&K43,'MODULOS OT MULTILINEA'!A:A,0))),"") | M43: =+IF(C43="","",IF(OR(C43="Óptima Plus Empresas",C43="Óptima Plus Empresas BIG"),"SI","NO")) | N43: =+IF(C43="","",IF($C$9="SI","NO",IF(OR(C43="Óptima Plus Empresas",C43="Óptima Plus Empresas BIG"),"SI","NO"))) | O43: =+IF(N43="NO","NO",IF(AND(E43="portabilidad",L43<>"ENTRADA PRO"),"SI","NO")) -> NO | P43: =IF(AND(E43="capta",F43="EMPRESAS VOZ"),0,1) -> 1
B44: IMPORTE TOTAL | C44: IMPORTE UNITARIO | D44: PAQUETE DE VOZ Y DATOS | E44: ACTIVACION | F44: ACTIVACION CP 24 POR TERMINAL | G44: SVAs | H44: O2O | I44: ESTRATEGICA | N44: =IF(N43="SI",1,0) -> 0
A45: COMISIONES | B45: =C45*B43 -> 0 | C45: =D45+E45+F45+G45-H46*N44+I45 -> 0 | D45: =IFERROR(IF(AND(M43="SI",$G$3="Cliente 1-19 líneas"),SUMIFS(MR!$B$5:$B$13,MR!$A$5:$A$13,F43),IF(AND(M43="SI",$G$3="Cliente 20-39 líneas"),SUMIFS(MR!$C$5:$C$13,MR!$A$5:$A$13,F43),IF(AND(M43="SI",$G$3="Cliente > 40 líneas"),SUMIFS(MR!$D$5:$D$13,MR!$A$5:$A$13,F43),IF(AND(M43="NO",$G$3="Cliente 1-19 líneas"),SUMIFS(MR!$B$17:$B$25,MR!$A$17:$A$25,F43),IF(AND(M43="NO",$G$3="Cliente 20-39 líneas"),SUMIFS(MR!$C$17:$C$25,MR!$A$17:$A$25,F43),IF(AND(M43="NO",$G$3="Cliente > 40 líneas"),SUMIFS(MR!$D$17:$D$25,MR!$A$17:$A$25,F43),0)))))),)+IFERROR(IF(AND(M43="SI",$G$3="Cliente 1-19 líneas"),SUMIFS(MR!$B$30:$B$37,MR!$A$30:$A$37,F43),IF(AND(M43="SI",$G$3="Cliente 20-39 líneas"),SUMIFS(MR!$C$30:$C$37,MR!$A$30:$A$37,F43),IF(AND(M43="SI",$G$3="Cliente > 40 líneas"),SUMIFS(MR!$D$30:$D$37,MR!$A$30:$A$37,F43),IF(AND(M43="NO",$G$3="Cliente 1-19 líneas"),SUMIFS(MR!$B$41:$B$48,MR!$A$41:$A$48,F43),IF(AND(M43="NO",$G$3="Cliente 20-39 líneas"),SUMIFS(MR!$C$41:$C$48,MR!$A$41:$A$48,F43),IF(AND(M43="NO",$G$3="Cliente > 40 líneas"),SUMIFS(MR!$D$41:$D$48,MR!$A$41:$A$48,F43),0)))))),) -> 0 | E45: =IFERROR(IF(AND(M43="SI",E43="capta",D43="multilínea"),SUMIFS(MR!$E$5:$E$13,MR!$A$5:$A$13,F43),IF(AND(M43="SI",E43="portabilidad",D43="multilínea"),SUMIFS(MR!$F$5:$F$13,MR!$A$5:$A$13,F43),IF(AND(M43="NO",E43="capta",D43="multilínea"),SUMIFS(MR!$E$17:$E$25,MR!$A$17:$A$25,F43),IF(AND(M43="NO",E43="portabilidad",D43="multilínea"),SUMIFS(MR!$F$17:$F$25,MR!$A$17:$A$25,F43),IF(AND(M43="NO",E43="capta",D43="IEW"),SUMIFS(MR!$B$53:$B$61,MR!$A$53:$A$61,C43),IF(AND(M43="NO",E43="portabilidad",D43="IEW"),SUMIFS(MR!$B$53:$B$61,MR!$A$53:$A$61,C43),0)))))),)+IFERROR(IF(AND(M43="SI",E43="capta",D43="multilínea"),SUMIFS(MR!$E$30:$E$37,MR!$A$30:$A$37,F43),IF(AND(M43="SI",E43="portabilidad",D43="multilínea"),SUMIFS(MR!$F$30:$F$37,MR!$A$30:$A$37,F43),IF(AND(M43="NO",E43="capta",D43="multilínea"),SUMIFS(MR!$E$48:$E$398,MR!$A$41:$A$48,F43),IF(AND(M43="NO",E43="portabilidad",D43="multilínea"),SUMIFS(MR!$F$41:$F$48,MR!$A$41:$A$48,F43),0)))),) -> 0 | F45: =(IFERROR(IF(K43="SIN TERMINAL",0,IF(I43="SI",10,SUMIFS(MR!$G$6:$G$11,MR!$A$6:$A$11,F43))),0))*K45 -> 0 | G45: =IFERROR(IF(D43="multilínea",IF(G43="SI",MR!$N$4,0)+IF(H43="SI",MR!$N$5,0),0),0) -> 0 | I45: =(IF(D43="multilínea",IF($F$9="SI",IF($M43="SI",SUMIFS(MR!$I$6:$I$11,MR!$A$6:$A$11,F43),SUMIFS(MR!$I$18:$I$23,MR!$A$18:$A$23,F43))),SUMIFS(MR!$D$54:$D$61,MR!$A$54:$A$61,C43)))*P43 -> 0 | J45: =IF(M43="SI",IF($B$13+$B$23+$B$33+$B$43>99,(99-$B$13-$B$23-$B$33)*I45,B43*I45),B43*I45) -> 0 | K45: =IF(IFERROR(SEARCH("CESIÓN",$J43,1),0)>0,0,1) -> 1
A46: SUBVENCIÓN TERMINAL | B46: =IFERROR(C46*B43,"SIN OFERTA") -> SIN OFERTA | C46: =IFERROR(IFERROR(IF($F$1="NO", IF(I43="SI",IF(E43="portabilidad", IF(D43="multilínea",IF(AND(C43<>"Soluciones Personalizadas RPV",C43<>"Soluciones Personalizadas Centrex"), OFFSET(CeldaInicioDxCVAP,MATCH(J43,'PVP VaP - Pyme'!C:C,0)-1,MATCH(L43,'PVP VaP - Pyme'!$Z$22:$AL$22,0)-1) +OFFSET(CeldaInicioDxCVAP,MATCH(J43,'PVP VaP - Pyme'!C:C,0)-1,MATCH(L43,'PVP VaP - Pyme'!$Z$22:$AL$22,0)))), IF(D43="IEW", OFFSET(CeldaInicioDxCVAPIEW,MATCH(J43,'PVP VaP IEW Pro - Pyme'!C:C,0)-1,MATCH(L43,'PVP VaP IEW Pro - Pyme'!$AA$22:$AH$22,0)-1) +OFFSET(CeldaInicioDxCVAPIEW,MATCH(J43,'PVP VaP IEW Pro - Pyme'!C:C,0)-1,MATCH(L43,'PVP VaP IEW Pro - Pyme'!$AA$22:$AH$22,0)), )), IF(M43="","SIN OFERTA",IF(M43="SI",IF(B47="SIN OFERTA",B47,IF(D43="IEW",OFFSET(CeldaInicioDxCIEW,MATCH(J43,'PVP Subv IEW - Pyme'!C:C,0)-1,MATCH(L43,'PVP Subv IEW - Pyme'!$I$4:$L$4,0)-1),OFFSET(IF(E43="portabilidad",CeldaInicioDxCPorta,CeldaInicioDxCCapta),MATCH(J43,'PVP Subv - Optima Pyme'!$C:$C,0)-1,MATCH(L43,'PVP Subv - Optima Pyme'!$I$4:$M$4,0)-1))), IF(B47="SIN OFERTA",B47,IF(D43="IEW",OFFSET(CeldaInicioDxCIEW,MATCH(J43,'PVP Subv IEW - Pyme'!C:C,0)-1,MATCH(L43,'PVP Subv IEW - Pyme'!$I$4:$L$4,0)-1),OFFSET(IF(E43="portabilidad",CeldaInicioDxCPorta9MAS,CeldaInicioDxCCapta9MAS),MATCH(J43,'PVP Subv - Sol Pers Pyme'!$C:$C,0)-1,MATCH(L43,'PVP Subv - Sol Pers Pyme'!$I$4:$M$4,0)-1))))))) +IF($F$1="SI", IF(I43="SI",IF(E43="portabilidad", IF(D43="multilínea",IF(AND(C43<>"Soluciones Personalizadas RPV",C43<>"Soluciones Personalizadas Centrex"), OFFSET(CeldaInicioDxCVAP,MATCH(J43,'PVP VaP - Pyme'!C:C,0)-1,MATCH(L43,'PVP VaP - Pyme'!$Z$22:$AL$22,0)-1) +OFFSET(CeldaInicioDxCVAP,MATCH(J43,'PVP VaP - Pyme'!C:C,0)-1,MATCH(L43,'PVP VaP - Pyme'!$Z$22:$AL$22,0)))), IF(D43="IEW", OFFSET(CeldaInicioDxCVAPIEW,MATCH(J43,'PVP VaP IEW Pro - Pyme'!C:C,0)-1,MATCH(L43,'PVP VaP IEW Pro - Pyme'!$AA$22:$AH$22,0)-1) +OFFSET(CeldaInicioDxCVAPIEW,MATCH(J43,'PVP VaP IEW Pro - Pyme'!C:C,0)-1,MATCH(L43,'PVP VaP IEW Pro - Pyme'!$AA$22:$AH$22,0)), )), IF(M43="","SIN OFERTA",IF(M43="SI",IF(B47="SIN OFERTA",B47,IF(D43="IEW",OFFSET(CeldaInicioDxCIEWAAPP,MATCH(J43,'PVP Subv IEW - Pyme AAPP'!C:C,0)-1,MATCH(L43,'PVP Subv IEW - Pyme AAPP'!$I$4:$L$4,0)-1),OFFSET(IF(E43="portabilidad",CeldaInicioDxCPortaAAPP,CeldaInicioDxCCaptaAAPP),MATCH(J43,'PVP Subv - Optima Pyme AAPP'!$C:$C,0)-1,MATCH(L43,'PVP Subv - Optima Pyme AAPP'!$I$4:$M$4,0)-1))), IF(B47="SIN OFERTA",B47,IF(D43="IEW",OFFSET(CeldaInicioDxCIEWAAPP,MATCH(J43,'PVP Subv IEW - Pyme AAPP'!C:C,0)-1,MATCH(L43,'PVP Subv IEW - Pyme AAPP'!$I$4:$L$4,0)-1),OFFSET(IF(E43="portabilidad",CeldaInicioDxCPorta9MASAAPP,CeldaInicioDxCCapta9MASAAPP),MATCH(J43,'PVP Subv - Sol Pers Pyme AAPP'!$C:$C,0)-1,MATCH(L43,'PVP Subv - Sol Pers Pyme AAPP'!$I$4:$M$4,0)-1))))))),"SIN OFERTA")+D46,"SIN OFERTA") -> SIN OFERTA | E46: =IFERROR(F46*B43,"SIN OFERTA") -> SIN OFERTA | F46: =IF(O43="SI",OFFSET(CeldadeinicioDxCportaCP36,MATCH(J43,'PVP Subv - Optima Pyme'!$C:$C,0)-1,MATCH(L43,'PVP Subv - Optima Pyme'!$BK$23:$BO$23,0)-1),"-") -> - | H46: =IFERROR(IF(N43="NO",0,SUMIFS(MR!$N$17:$N$21,MR!$M$17:$M$21,H45)),0) -> 0
A47: PVPR TERMINAL (sin IVA) | B47: =IFERROR(C47*B43,"SIN OFERTA") -> 0 | D47: Dif. CP 24 m | E47: =IF(E46="SIN OFERTA",0,(E46-B46)) -> 0 | F47: =IF(B46="SIN OFERTA",0,5*B43) -> 0 | G47: Válida en módulos: | H47: =IFERROR(INDEX(Tabla32[APLICA],MATCH(H45,Tabla32[PROMO],0)),"")
...

Sheet PVP VaP - Pyme
B2: OFERTA TÁCTICA EMPRESAS | H2: Pago Único | J2: CAPTA | M2: PORTABILIDAD
B4: 45658 | C4: 01/01 al 31/01 | J4: - | M4: ENTRADA PRO | O4: NORMAL PRO | Q4: VALOR PRO | S4: PREMIUM PRO | U4: TOP PRO
B5: 1. CONDICIONES DE LA OFERTA VENTA A PLAZOS (según tarifa y situación del cliente) | D5: Tarifas | H5: Todas Tarifas | J5: - | M5: T. Optima Plus Empresas T. Optima Plus Empresas Big + Empresas Voz y Empresas 1 | O5: T. Optima Plus Empresas T. Optima Plus Empresas Big + Empresas 5 y Empresas Intranet | Q5: T. Optima Plus Empresas T. Optima Plus Empresas Big + Empresas 20 | S5: T. Optima Plus Empresas T. Optima Plus Empresas Big + Empresas Infinita | U5: T. Optima Plus Empresas T. Optima Plus Empresas Big + Empresas Internacional
D13: Ampliaciones (meses antigüedad) | H13: Todos | J13: cliente -4 M, solo accede a Pago Único | M13: + 4 M | O13: + 4 M | Q13: + 4 M | S13: + 4 M | U13: + 4 M
D14: Origen (Portabilidad / Migración) | H14: Pos | J14: Capta de cliente nuevo, solo accede a Pago Único | M14: Pospago | O14: Pospago | Q14: Pospago | S14: Pospago | U14: Pospago
D15: CP Tarifa Voz | H15: 12 M | J15: - | M15: 24 M | O15: 24 M | Q15: 24 M | S15: 24 M | U15: 24 M
D16: CP Tarifa Datos | H16: - | J16: - | M16: 24 M | O16: 24 M Plus | Q16: 24 M Plus | S16: 24 M Plus | U16: 24 M Plus | AN16: DIFERENCIAS Vs MES ANTERIOR
AN17: 6 | AO17: 7 | AP17: 8 | AQ17: 9 | AR17: 10 | AS17: 11 | AT17: 12 | AU17: 13 | AV17: 14 | AW17: 15 | AX17: 16 | AY17: 17 | AZ17: 18 | BA17: 19 | BB17: 20
B18: 2. PRECIO DEL TERMINAL POR GRUPO DE TARIFAS | H18: Pago Único | J18: PVPR CAPTA (tarifas móvil y convergentes) | M18: PVPR PORTABILIDAD | X18: DxC Pago Único | Z18: DxC CAPTA (tarifas móvil y convergentes) | AC18: DxC PORTABILIDAD | AN18: Pago Único | AP18: PVPR CAPTA (tarifas móvil y convergentes) | AS18: PVPR PORTABILIDAD
M20: GRUPOS DE TARIFAS MÓVIL | AC20: GRUPOS DE TARIFAS MÓVIL | AS20: GRUPOS DE TARIFAS MÓVIL
J22: - | M22: ENTRADA PRO | O22: NORMAL PRO | Q22: VALOR PRO | S22: PREMIUM PRO | U22: TOP PRO | Z22: - | AC22: ENTRADA PRO | AE22: NORMAL PRO | AG22: VALOR PRO | AI22: PREMIUM PRO | AK22: TOP PRO | AP22: ENTRADA PRO | AS22: ENTRADA PRO | AU22: NORMAL PRO | AW22: VALOR PRO | AY22: PREMIUM PRO | BA22: TOP PRO
B24: MARCA | C24: Modelo (Novedades) | D24: Precio Cesión | E24: Canon Digital | F24: Gama | G24: Meses Cuota | H24: Pago Unico (sin IVA) | J24: Pago Inicial (sin IVA) | K24: Cuota Mes (sin IVA) | M24: Pago Inicial (sin IVA) | N24: Cuota Mes (sin IVA) | O24: Pago Inicial (sin IVA) | P24: Cuota Mes (sin IVA) | Q24: Pago Inicial (sin IVA) | R24: Cuota Mes (sin IVA) | S24: Pago Inicial (sin IVA) | T24: Cuota Mes (sin IVA) | U24: Pago Inicial (sin IVA) | V24: Cuota Mes (sin IVA) | X24: DxC Pago Unico | Z24: DxC Precio | AA24: DxC VaP | AC24: DxC Precio | AD24: DxC VaP | AE24: DxC Precio | AF24: DxC VaP | AG24: DxC Precio | AH24: DxC VaP | AI24: DxC Precio | AJ24: DxC VaP | AK24: DxC Precio | AL24: DxC VaP | AN24: Pago Unico (sin IVA) | AP24: Pago Inicial (sin IVA) | AQ24: Cuota Mes (sin IVA) | AS24: Pago Inicial (sin IVA) | AT24: Cuota Mes (sin IVA) | AU24: Pago Inicial (sin IVA) | AV24: Cuota Mes (sin IVA) | AW24: Pago Inicial (sin IVA) | AX24: Cuota Mes (sin IVA) | AY24: Pago Inicial (sin IVA) | AZ24: Cuota Mes (sin IVA) | BA24: Pago Inicial (sin IVA) | BB24: Cuota Mes (sin IVA)
B25: ORANGE | C25: AD HOC H3 CESIÓN | D25: 0 | E25: 1.1 | F25: FIXED STYLE | G25: - | H25: - | J25: - | K25: - | M25: - | N25: - | O25: - | P25: - | Q25: - | R25: - | S25: - | T25: - | U25: - | V25: - | X25: 0 | Z25: 0 | AA25: 0 | AC25: 0 | AD25: 0 | AE25: 0 | AF25: 0 | AG25: 0 | AH25: 0 | AI25: 0 | AJ25: 0 | AK25: 0 | AL25: 0 | AN25: 0 | AP25: 0 | AQ25: 0 | AS25: 0 | AT25: 0 | AU25: 0 | AV25: 0 | AW25: 0 | AX25: 0 | AY25: 0 | AZ25: 0 | BA25: 0 | BB25: 0
B26: ORANGE | C26: ADOC D30 | D26: 239 | E26: 3.75 | F26: FIXED STYLE | G26: 24 | H26: 280 | J26: - | K26: - | M26: 0 | N26: 7.3 | O26: 0 | P26: 5.9 | Q26: 0 | R26: 2.5 | S26: 0 | T26: 0 | U26: 0 | V26: 0 | X26: -41 | Z26: 0 | AA26: 0 | AC26: 64 | AD26: 175 | AE26: 97 | AF26: 142 | AG26: 179 | AH26: 60 | AI26: 239 | AJ26: 0 | AK26: 239 | AL26: 0 | AN26: 0 | AP26: 0 | AQ26: 0 | AS26: 0 | AT26: 0 | AU26: 0 | AV26: 0 | AW26: 0 | AX26: 0 | AY26: 0 | AZ26: 0 | BA26: 0 | BB26: 0
B27: ORANGE | C27: ADOC D30 CESIÓN | D27: 0 | E27: 3.75 | F27: FIXED STYLE | G27: - | H27: - | J27: - | K27: - | M27: - | N27: - | O27: - | P27: - | Q27: - | R27: - | S27: - | T27: - | U27: - | V27: - | X27: 0 | Z27: 0 | AA27: 0 | AC27: 0 | AD27: 0 | AE27: 0 | AF27: 0 | AG27: 0 | AH27: 0 | AI27: 0 | AJ27: 0 | AK27: 0 | AL27: 0 | AN27: 0 | AP27: 0 | AQ27: 0 | AS27: 0 | AT27: 0 | AU27: 0 | AV27: 0 | AW27: 0 | AX27: 0 | AY27: 0 | AZ27: 0 | BA27: 0 | BB27: 0
B28: AD HOC | C28: ADOC SC01 | D28: 64 | E28: 1.1 | F28: VOZ | G28: - | H28: - | J28: - | K28: - | M28: - | N28: - | O28: - | P28: - | Q28: - | R28: - | S28: - | T28: - | U28: - | V28: - | X28: 0 | Z28: 0 | AA28: 0 | AC28: 0 | AD28: 0 | AE28: 0 | AF28: 0 | AG28: 0 | AH28: 0 | AI28: 0 | AJ28: 0 | AK28: 0 | AL28: 0 | AN28: 0 | AP28: 0 | AQ28: 0 | AS28: 0 | AT28: 0 | AU28: 0 | AV28: 0 | AW28: 0 | AX28: 0 | AY28: 0 | AZ28: 0 | BA28: 0 | BB28: 0
B29: ADOC | C29: ADOC SC04 | D29: 77 | E29: 1.1 | F29: VOZ | G29: 24 | H29: 93 | J29: - | K29: - | M29: 0 | N29: 0 | O29: 0 | P29: 0 | Q29: 0 | R29: 0 | S29: 0 | T29: 0 | U29: 0 | V29: 0 | X29: -16 | Z29: 0 | AA29: 0 | AC29: 77 | AD29: 0 | AE29: 77 | AF29: 0 | AG29: 77 | AH29: 0 | AI29: 77 | AJ29: 0 | AK29: 77 | AL29: 0 | AN29: 0 | AP29: 0 | AQ29: 0 | AS29: 0 | AT29: 0 | AU29: 0 | AV29: 0 | AW29: 0 | AX29: 0 | AY29: 0 | AZ29: 0 | BA29: 0 | BB29: 0
B30: APPLE | C30: APPLE AIRPODS 4 | D30: 137 | E30: 0 | F30: OC_AURICULARES | G30: 24 | H30: 165 | J30: - | K30: - | M30: 0 | N30: 4 | O30: 0 | P30: 2.6 | Q30: 0 | R30: 0 | S30: 0 | T30: 0 | U30: 0 | V30: 0 | X30: -28 | Z30: 0 | AA30: 0 | AC30: 41 | AD30: 96 | AE30: 75 | AF30: 62 | AG30: 137 | AH30: 0 | AI30: 137 | AJ30: 0 | AK30: 137 | AL30: 0 | AN30: 0 | AP30: 0 | AQ30: 0 | AS30: 0 | AT30: 0 | AU30: 0 | AV30: 0 | AW30: 0 | AX30: 0 | AY30: 0 | AZ30: 0 | BA30: 0 | BB30: 0
B31: APPLE | C31: APPLE AIRPODS 4 CON CANCELACION ACTIVA RUIDO | D31: 184 | E31: 0 | F31: OC_AURICULARES | G31: 24 | H31: 222 | J31: - | K31: - | M31: 0 | N31: 5.6 | O31: 0 | P31: 4.2 | Q31: 0 | R31: 0 | S31: 0 | T31: 0 | U31: 0 | V31: 0 | X31: -38 | Z31: 0 | AA31: 0 | AC31: 50 | AD31: 134 | AE31: 83 | AF31: 101 | AG31: 184 | AH31: 0 | AI31: 184 | AJ31: 0 | AK31: 184 | AL31: 0 | AN31: 0 | AP31: 0 | AQ31: 0 | AS31: 0 | AT31: 0 | AU31: 0 | AV31: 0 | AW31: 0 | AX31: 0 | AY31: 0 | AZ31: 0 | BA31: 0 | BB31: 0
B32: APPLE | C32: APPLE AIRPODS PRO 2a GENERACION MAGSAFE USBC | D32: 279 | E32: 0 | F32: OC_AURICULARES | G32: 24 | H32: 336 | J32: - | K32: - | M32: 0 | N32: 8.1 | O32: 0 | P32: 6.7 | Q32: 0 | R32: 3.4 | S32: 0 | T32: 1.8 | U32: 0 | V32: 0 | X32: -57 | Z32: 0 | AA32: 0 | AC32: 85 | AD32: 194 | AE32: 118 | AF32: 161 | AG32: 197 | AH32: 82 | AI32: 236 | AJ32: 43 | AK32: 279 | AL32: 0 | AN32: 0 | AP32: 0 | AQ32: 0 | AS32: 0 | AT32: 0 | AU32: 0 | AV32: 0 | AW32: 0 | AX32: 0 | AY32: 0 | AZ32: 0 | BA32: 0 | BB32: 0
B33: APPLE | C33: APPLE WATCH S10 CELLULAR 42MM | D33: 532 | E33: 2.5 | F33: OC_SMART WATCH | G33: 24 | H33: 643 | J33: - | K33: - | M33: 39 | N33: 16.4 | O33: 19 | P33: 15.6 | Q33: 0 | R33: 13.1 | S33: 0 | T33: 11.5 | U33: 0 | V33: 6.8 | X33: -111 | Z33: 0 | AA33: 0 | AC33: 99 | AD33: 394 | AE33: 139 | AF33: 374 | AG33: 218 | AH33: 314 | AI33: 256 | AJ33: 276 | AK33: 369 | AL33: 163 | AN33: 0 | AP33: 0 | AQ33: 0 | AS33: 0 | AT33: 0 | AU33: 0 | AV33: 0 | AW33: 0 | AX33: 0 | AY33: 0 | AZ33: 0 | BA33: 0 | BB33: 0
B34: APPLE | C34: APPLE WATCH S10 CELLULAR 46MM | D34: 555 | E34: 2.5 | F34: OC_SMART WATCH | G34: 24 | H34: 671 | J34: - | K34: - | M34: 39 | N34: 17.4 | O34: 19 | P34: 16.6 | Q34: 0 | R34: 14.1 | S34: 0 | T34: 12.4 | U34: 0 | V34: 7.8 | X34: -116 | Z34: 0 | AA34: 0 | AC34: 98 | AD34: 418 | AE34: 138 | AF34: 398 | AG34: 217 | AH34: 338 | AI34: 257 | AJ34: 298 | AK34: 368 | AL34: 187 | AN34: 0 | AP34: 0 | AQ34: 0 | AS34: 0 | AT34: 0 | AU34: 0 | AV34: 0 | AW34: 0 | AX34: 0 | AY34: 0 | AZ34: 0 | BA34: 0 | BB34: 0
B35: AD HOC | C35: AURICULARES AD HOC BT01 | D35: 71 | E35: 0 | F35: OC_AURICULARES | G35: 24 | H35: 57.024793 | J35: - | K35: - | M35: 0 | N35: 0 | O35: 0 | P35: 0 | Q35: 0 | R35: 0 | S35: 0 | T35: 0 | U35: 0 | V35: 0 | X35: 14 | Z35: 0 | AA35: 0 | AC35: 71 | AD35: 0 | AE35: 71 | AF35: 0 | AG35: 71 | AH35: 0 | AI35: 71 | AJ35: 0 | AK35: 71 | AL35: 0 | AN35: 0 | AP35: 0 | AQ35: 0 | AS35: 0 | AT35: 0 | AU35: 0 | AV35: 0 | AW35: 0 | AX35: 0 | AY35: 0 | AZ35: 0 | BA35: 0 | BB35: 0
B36: AD HOC | C36: AURICULARES AD HOC HC01 | D36: 49 | E36: 0 | F36: OC_AURICULARES | G36: 24 | H36: 35.53719 | J36: - | K36: - | M36: 0 | N36: 0 | O36: 0 | P36: 0 | Q36: 0 | R36: 0 | S36: 0 | T36: 0 | U36: 0 | V36: 0 | X36: 13 | Z36: 0 | AA36: 0 | AC36: 49 | AD36: 0 | AE36: 49 | AF36: 0 | AG36: 49 | AH36: 0 | AI36: 49 | AJ36: 0 | AK36: 49 | AL36: 0 | AN36: 0 | AP36: 0 | AQ36: 0 | AS36: 0 | AT36: 0 | AU36: 0 | AV36: 0 | AW36: 0 | AX36: 0 | AY36: 0 | AZ36: 0 | BA36: 0 | BB36: 0
B37: SAMSUNG | C37: AURICULARES SAMSUNG GALAXY BUDS 3 | D37: 172 | E37: 0 | F37: OC_AURICULARES | G37: 24 | H37: 158 | J37: - | K37: - | M37: 0 | N37: 3.7 | O37: 0 | P37: 2.3 | Q37: 0 | R37: 0 | S37: 0 | T37: 0 | U37: 0 | V37: 0 | X37: 14 | Z37: 0 | AA37: 0 | AC37: 83 | AD37: 89 | AE37: 117 | AF37: 55 | AG37: 172 | AH37: 0 | AI37: 172 | AJ37: 0 | AK37: 172 | AL37: 0 | AN37: 0 | AP37: 0 | AQ37: 0 | AS37: 0 | AT37: 0 | AU37: 0 | AV37: 0 | AW37: 0 | AX37: 0 | AY37: 0 | AZ37: 0 | BA37: 0 | BB37: 0
B38: SAMSUNG | C38: AURICULARES SAMSUNG GALAXY BUDS 3 PRO | D38: 240 | E38: 0 | F38: OC_AURICULARES | G38: 24 | H38: 227 | J38: - | K38: - | M38: 0 | N38: 5.8 | O38: 0 | P38: 4.4 | Q38: 0 | R38: 1 | S38: 0 | T38: 0 | U38: 0 | V38: 0 | X38: 13 | Z38: 0 | AA38: 0 | AC38: 101 | AD38: 139 | AE38: 134 | AF38: 106 | AG38: 216 | AH38: 24 | AI38: 240 | AJ38: 0 | AK38: 240 | AL38: 0 | AN38: 0 | AP38: 0 | AQ38: 0 | AS38: 0 | AT38: 0 | AU38: 0 | AV38: 0 | AW38: 0 | AX38: 0 | AY38: 0 | AZ38: 0 | BA38: 0 | BB38: 0
B39: SPC | C39: AURICULARES SPC BRAVE PRO | D39: 44 | E39: 0 | F39: OC_AURICULARES | G39: 24 | H39: 47.933884 | J39: - | K39: - | M39: 0 | N39: 0 | O39: 0 | P39: 0 | Q39: 0 | R39: 0 | S39: 0 | T39: 0 | U39: 0 | V39: 0 | X39: -4 | Z39: 0 | AA39: 0 | AC39: 44 | AD39: 0 | AE39: 44 | AF39: 0 | AG39: 44 | AH39: 0 | AI39: 44 | AJ39: 0 | AK39: 44 | AL39: 0 | AN39: 0 | AP39: 0 | AQ39: 0 | AS39: 0 | AT39: 0 | AU39: 0 | AV39: 0 | AW39: 0 | AX39: 0 | AY39: 0 | AZ39: 0 | BA39: 0 | BB39: 0
B40: SPC | C40: AURICULARES SPC DREAMER PRO | D40: 77 | E40: 0 | F40: OC_AURICULARES | G40: 24 | H40: 59.504132 | J40: - | K40: - | M40: 0 | N40: 0 | O40: 0 | P40: 0 | Q40: 0 | R40: 0 | S40: 0 | T40: 0 | U40: 0 | V40: 0 | X40: 17 | Z40: 0 | AA40: 0 | AC40: 77 | AD40: 0 | AE40: 77 | AF40: 0 | AG40: 77 | AH40: 0 | AI40: 77 | AJ40: 0 | AK40: 77 | AL40: 0 | AN40: 0 | AP40: 0 | AQ40: 0 | AS40: 0 | AT40: 0 | AU40: 0 | AV40: 0 | AW40: 0 | AX40: 0 | AY40: 0 | AZ40: 0 | BA40: 0 | BB40: 0
... B44: GOOGLE | C44: GOOGLE PIXEL 8A 256GB 5G | D44: 564 | E44: 3.25 | F44: SMARTPHONE | G44: 24 | H44: 549 | J44: - | K44: - | M44: 39 | N44: 13.9 | O44: 19 | P44: 13.1 | Q44: 0 | R44: 10.6 | S44: 0 | T44: 9 | U44: 0 | V44: 4.3 | X44: 15 | Z44: 0 | AA44: 0 | AC44: 191 | AD44: 334 | AE44: 231 | AF44: 314 | AG44: 310 | AH44: 254 | AI44: 348 | AJ44: 216 | AK44: 461 | AL44: 103 | AN44: 0 | AP44: 0 | AQ44: 0 | AS44: 0 | AT44: 0 | AU44: 0 | AV44: 0 | AW44: 0 | AX44: 0 | AY44: 0 | AZ44: 0 | BA44: 0 | BB44: 0
B45: GOOGLE | C45: GOOGLE PIXEL 9 128GB 5G | D45: 823 | E45: 3.25 | F45: SMARTPHONE | G45: 24 | H45: 795 | J45: - | K45: - | M45: - | N45: - | O45: 19 | P45: 21 | Q45: 0 | R45: 18.5 | S45: 0 | T45: 15.8 | U45: 0 | V45: 10.9 | X45: 28 | Z45: 0 | AA45: 0 | AC45: 0 | AD45: 0 | AE45: 300 | AF45: 504 | AG45: 379 | AH45: 444 | AI45: 444 | AJ45: 379 | AK45: 561 | AL45: 262 | AN45: 0 | AP45: 0 | AQ45: 0 | AS45: 0 | AT45: 0 | AU45: 0 | AV45: 0 | AW45: 0 | AX45: 0 | AY45: 0 | AZ45: 0 | BA45: 0 | BB45: 0
B46: GOOGLE | C46: GOOGLE PIXEL 9 PRO 256GB 5G | D46: 1062 | E46: 3.25 | F46: SMARTPHONE | G46: 24 | H46: 1060 | J46: - | K46: - | M46: - | N46: - | O46: 49 | P46: 26.9 | Q46: 39 | R46: 24 | S46: 0 | T46: 23 | U46: 0 | V46: 18.1 | X46: 2 | Z46: 0 | AA46: 0 | AC46: 0 | AD46: 0 | AE46: 367 | AF46: 646 | AG46: 447 | AH46: 576 | AI46: 510 | AJ46: 552 | AK46: 628 | AL46: 434 | AN46: 0 | AP46: 0 | AQ46: 0 | AS46: 0 | AT46: 0 | AU46: 0 | AV46: 0 | AW46: 0 | AX46: 0 | AY46: 0 | AZ46: 0 | BA46: 0 | BB46: 0
B47: GOOGLE | C47: GOOGLE PIXEL 9 PRO XL 512GB 5G | D47: 1234 | E47: 3.25 | F47: SMARTPHONE | G47: 24 | H47: 1233 | J47: - | K47: - | M47: - | N47: - | O47: 79 | P47: 31.9 | Q47: 39 | R47: 30.2 | S47: 0 | T47: 29.2 | U47: 0 | V47: 24.3 | X47: 1 | Z47: 0 | AA47: 0 | AC47: 0 | AD47: 0 | AE47: 389 | AF47: 766 | AG47: 470 | AH47: 725 | AI47: 533 | AJ47: 701 | AK47: 651 | AL47: 583 | AN47: 0 | AP47: 0 | AQ47: 0 | AS47: 0 | AT47: 0 | AU47: 0 | AV47: 0 | AW47: 0 | AX47: 0 | AY47: 0 | AZ47: 0 | BA47: 0 | BB47: 0
B48: HONOR | C48: HONOR 200 512GB 5G | D48: 539 | E48: 3.25 | F48: SMARTPHONE | G48: 24 | H48: 518 | J48: - | K48: - | M48: 0 | N48: 9.2 | O48: 0 | P48: 7.8 | Q48: 0 | R48: 4.4 | S48: 0 | T48: 2.8 | U48: 0 | V48: 0 | X48: 21 | Z48: 0 | AA48: 0 | AC48: 318 | AD48: 221 | AE48: 352 | AF48: 187 | AG48: 433 | AH48: 106 | AI48: 472 | AJ48: 67 | AK48: 539 | AL48: 0 | AN48: 0 | AP48: 0 | AQ48: 0 | AS48: 0 | AT48: 0 | AU48: 0 | AV48: 0 | AW48: 0 | AX48: 0 | AY48: 0 | AZ48: 0 | BA48: 0 | BB48: 0
B49: HONOR | C49: HONOR 200 LITE 256GB 5G | D49: 309 | E49: 3.25 | F49: SMARTPHONE | G49: 24 | H49: 291 | J49: - | K49: - | M49: 0 | N49: 5.8 | O49: 0 | P49: 4.4 | Q49: 0 | R49: 1.1 | S49: 0 | T49: 0 | U49: 0 | V49: 0 | X49: 18 | Z49: 0 | AA49: 0 | AC49: 170 | AD49: 139 | AE49: 203 | AF49: 106 | AG49: 283 | AH49: 26 | AI49: 309 | AJ49: 0 | AK49: 309 | AL49: 0 | AN49: 0 | AP49: 0 | AQ49: 0 | AS49: 0 | AT49: 0.6 | AU49: 0 | AV49: 0.6 | AW49: 0 | AX49: 1.1 | AY49: 0 | AZ49: 0 | BA49: 0 | BB49: 0
B50: HONOR | C50: HONOR 200 PRO 512GB 5G | D50: 661 | E50: 3.25 | F50: SMARTPHONE | G50: 24 | H50: 663 | J50: - | K50: - | M50: 39 | N50: 12.8 | O50: 19 | P50: 12 | Q50: 0 | R50: 9.4 | S50: 0 | T50: 7.8 | U50: 0 | V50: 3.1 | X50: -2 | Z50: 0 | AA50: 0 | AC50: 315 | AD50: 307 | AE50: 354 | AF50: 288 | AG50: 435 | AH50: 226 | AI50: 474 | AJ50: 187 | AK50: 587 | AL50: 74 | AN50: 0 | AP50: 0 | AQ50: 0 | AS50: 0 | AT50: -2.6 | AU50: 0 | AV50: -2.6 | AW50: 0 | AX50: -2.7 | AY50: 0 | AZ50: -2.6 | BA50: 0 | BB50: -2.7
B51: HONOR | C51: HONOR 200 SMART 256GB 5G | D51: 181 | E51: 3.25 | F51: SMARTPHONE | G51: 24 | H51: 134 | J51: - | K51: - | M51: 0 | N51: 3.3 | O51: 0 | P51: 1.9 | Q51: 0 | R51: 0 | S51: 0 | T51: 0 | U51: 0 | V51: 0 | X51: 47 | Z51: 0 | AA51: 0 | AC51: 102 | AD51: 79 | AE51: 135 | AF51: 46 | AG51: 181 | AH51: 0 | AI51: 181 | AJ51: 0 | AK51: 181 | AL51: 0 | AN51: 15 | AP51: 0 | AQ51: 0 | AS51: 0 | AT51: 0.5 | AU51: 0 | AV51: 0.5 | AW51: 0 | AX51: 0 | AY51: 0 | AZ51: 0 | BA51: 0 | BB51: 0
B52: HONOR | C52: HONOR MAGIC V3 512GB 5G | D52: 1653 | E52: 3.25 | F52: SMARTPHONE | G52: 24 | H52: 1552 | J52: - | K52: - | M52: - | N52: - | O52: 129 | P52: 41.1 | Q52: 99 | R52: 39.1 | S52: 49 | T52: 38.6 | U52: 29 | V52: 34.5 | X52: 101 | Z52: 0 | AA52: 0 | AC52: 0 | AD52: 0 | AE52: 538 | AF52: 986 | AG52: 616 | AH52: 938 | AI52: 678 | AJ52: 926 | AK52: 796 | AL52: 828 | AN52: 121 | AP52: 0 | AQ52: 0 | AS52: 0 | AT52: 0 | AU52: 0 | AV52: 4.3 | AW52: 0 | AX52: 4.3 | AY52: 0 | AZ52: 4.4 | BA52: 0 | BB52: 4.3
B53: HONOR | C53: HONOR MAGIC6 LITE 256GB 5G | D53: 358 | E53: 3.25 | F53: SMARTPHONE | G53: 24 | H53: 360 | J53: - | K53: - | M53: 0 | N53: 9 | O53: 0 | P53: 7.6 | Q53: 0 | R53: 4.2 | S53: 0 | T53: 2.6 | U53: 0 | V53: 0 | X53: -2 | Z53: 0 | AA53: 0 | AC53: 142 | AD53: 216 | AE53: 176 | AF53: 182 | AG53: 257 | AH53: 101 | AI53: 296 | AJ53: 62 | AK53: 358 | AL53: 0 | AN53: 0 | AP53: 0 | AQ53: 0 | AS53: 0 | AT53: 0 | AU53: 0 | AV53: 0 | AW53: 0 | AX53: 0 | AY53: 0 | AZ53: 0 | BA53: 0 | BB53: 0
B54: HONOR | C54: HONOR MAGIC6 PRO 5G | D54: 1074 | E54: 3.25 | F54: SMARTPHONE | G54: 24 | H54: 978 | J54: - | K54: - | M54: - | N54: - | O54: 39 | P54: 25 | Q54: 39 | R54: 21.7 | S54: 0 | T54: 20.7 | U54: 0 | V54: 15.8 | X54: 96 | Z54: 0 | AA54: 0 | AC54: 0 | AD54: 0 | AE54: 435 | AF54: 600 | AG54: 514 | AH54: 521 | AI54: 577 | AJ54: 497 | AK54: 695 | AL54: 379 | AN54: 0 | AP54: 0 | AQ54: 0 | AS54: 0 | AT54: 0 | AU54: 0 | AV54: 0 | AW54: 0 | AX54: 0 | AY54: 0 | AZ54: 0 | BA54: 0 | BB54: 0
B55: HONOR | C55: HONOR PAD X8a 11" 4+128GB WIFI | D55: 137 | E55: 3.75 | F55: TABLETS | G55: 24 | H55: 165 | J55: - | K55: - | M55: 0 | N55: 4 | O55: 0 | P55: 2.6 | Q55: 0 | R55: 0 | S55: 0 | T55: 0 | U55: 0 | V55: 0 | X55: -28 | Z55: 0 | AA55: 0 | AC55: 41 | AD55: 96 | AE55: 75 | AF55: 62 | AG55: 137 | AH55: 0 | AI55: 137 | AJ55: 0 | AK55: 137 | AL55: 0 | AN55: 0 | AP55: 0 | AQ55: 0 | AS55: #N/A | AT55: #N/A | AU55: #N/A | AV55: #N/A | AW55: #N/A | AX55: #N/A | AY55: #N/A | AZ55: #N/A | BA55: #N/A | BB55: #N/A
...

Sheet PVP VaP IEW Pro - Pyme
B2: OFERTA TÁCTICA EMPRESAS | H2: Pago Único | J2: CAPTA | M2: PORTABILIDAD
B4: ='PVP VaP - Pyme'!B4 -> 45658 | C4: 01/01 al 31/01 | J4: - | M4: ENTRADA PRO | O4: NORMAL PRO | Q4: VALOR PRO | S4: PREMIUM PRO
B5: 1. CONDICIONES DE LA OFERTA VENTA A PLAZOS (según tarifa y situación del cliente) | D5: Tarifas | H5: Todas Tarifas | J5: Todas Tarifas | M5: Internet Movil 3GB Empresa | O5: Internet Movil 10GB Empresa | Q5: Internet Movil 25GB Empresa Fibra Oro (**) | S5: Internet Movil 90GB Empresa Internet 4G en tu Negocio (excepto router) Internet Empresa Ilimitado
D13: Ampliaciones (meses antigüedad) | H13: - | J13: - | M13: + 4 M - 4 M doble capta | O13: + 4 M - 4 M doble capta | Q13: + 4 M - 4 M doble capta | S13: + 4 M - 4 M doble capta
D14: Origen (Portabilidad / Migración) | H14: Capta Pos / Pre Migra | J14: (*) Capta de cliente nuevo o de cliente -4 M, solo tienen acceso a Pago Único | M14: Pos / Migra | O14: Pos / Migra | Q14: Pos / Migra | S14: Pos / Migra
D15: CP Tarifa | H15: - | J15: - | M15: 12 M / 24 M | O15: 12 M / 24 M | Q15: 12 M / 24 M | S15: 12 M / 24 M
D16: (*) Para Capta de cliente nuevo o cliente de -4 meses que activen en el mismo acto comercial tarifas de voz y tarifas de IEW Pro, aplican las condiciones de Portabilidad origen Pospago
D17: (**) La tarifa Fibra Oro solo puede activarse con el router Alctel Airbox 4G MW40 2018
B18: 2. PRECIO DEL TERMINAL POR GRUPO DE TARIFAS | H18: Pago Único | J18: PVPR CAPTA | M18: PVPR PORTABILIDAD | V18: DxC Pago Único | X18: DxC CAPTA | AA18: DxC PORTABILIDAD
M20: GRUPOS DE TARIFAS IEW Pro | AA20: GRUPOS DE TARIFAS IEW Pro
J22: - | M22: ENTRADA PRO | O22: NORMAL PRO | Q22: VALOR PRO | S22: PREMIUM PRO | X22: - | AA22: ENTRADA PRO | AC22: NORMAL PRO | AE22: VALOR PRO | AG22: PREMIUM PRO
B24: MARCA | C24: Modelo (Novedades) | D24: Precio Cesión | E24: Canon Digital | F24: Gama | G24: Meses Cuota | H24: Pago Unico (sin IVA) | J24: Pago Inicial (sin IVA) | K24: Cuota Mes (sin IVA) | M24: Pago Inicial (sin IVA) | N24: Cuota Mes (sin IVA) | O24: Pago Inicial (sin IVA) | P24: Cuota Mes (sin IVA) | Q24: Pago Inicial (sin IVA) | R24: Cuota Mes (sin IVA) | S24: Pago Inicial (sin IVA) | T24: Cuota Mes (sin IVA) | V24: DxC Pago Unico | X24: DxC Precio | Y24: DxC VaP | AA24: DxC Precio | AB24: DxC VaP | AC24: DxC Precio | AD24: DxC VaP | AE24: DxC Precio | AF24: DxC VaP | AG24: DxC Precio | AH24: DxC VaP
B25: ALCATEL | C25: ALCATEL AIRBOX 4G MW45 | D25: 49 | E25: 0 | F25: MBB | G25: 12 | H25: 42.14876 | J25: - | K25: - | M25: 0 | N25: 3 | O25: 0 | P25: 1 | Q25: 0 | R25: 1 | S25: 0 | T25: 0 | V25: 6.8512397 | X25: - | Y25: - | AA25: 13 | AB25: 36 | AC25: 37 | AD25: 12 | AE25: 37 | AF25: 12 | AG25: 49 | AH25: 0
B26: HUAWEI | C26: HUAWEI AIRBOX E5576-320 IEW 4G | D26: 66 | E26: 0 | F26: MBB | G26: 12 | H26: 57.024793 | J26: - | K26: - | M26: 0 | N26: 3 | O26: 0 | P26: 2 | Q26: 0 | R26: 2 | S26: 0 | T26: 0 | V26: 8.9752066 | X26: - | Y26: - | AA26: 30 | AB26: 36 | AC26: 42 | AD26: 24 | AE26: 42 | AF26: 24 | AG26: 66 | AH26: 0
B27: TP-LINK | C27: ROUTER TPLINK MR200 IEW 4G | D27: 58 | E27: 0 | F27: MBB | G27: 12 | H27: 48 | J27: - | K27: - | M27: 0 | N27: 4 | O27: 0 | P27: 2 | Q27: 0 | R27: 2 | S27: 0 | T27: 1 | V27: 10 | X27: - | Y27: - | AA27: 10 | AB27: 48 | AC27: 34 | AD27: 24 | AE27: 34 | AF27: 24 | AG27: 46 | AH27: 12
B28: TP-LINK | C28: ROUTER TPLINK MR200 IEW 4G (2) | D28: 58 | E28: 0 | F28: MBB | G28: - | H28: 48 | J28: - | K28: - | M28: - | N28: - | O28: - | P28: - | Q28: - | R28: - | S28: - | T28: - | V28: 10 | X28: - | Y28: - | AA28: - | AB28: - | AC28: - | AD28: - | AE28: - | AF28: - | AG28: - | AH28: -
B29: TP-LINK | C29: TP-LINK FLYBOX 4G (1) | D29: 0 | E29: 0 | F29: MBB | G29: 12 | H29: 0 | J29: - | K29: - | M29: - | N29: - | O29: - | P29: - | Q29: - | R29: - | S29: 0 | T29: 0 | V29: 0 | X29: - | Y29: - | AA29: - | AB29: - | AC29: - | AD29: - | AE29: - | AF29: - | AG29: 0 | AH29: 0
B30: ZTE | C30: ZTE AIRBOX MF920U 4G | D30: 66 | E30: 0 | F30: MBB | G30: 12 | H30: 45.454545 | J30: - | K30: - | M30: 0 | N30: 3 | O30: 0 | P30: 2 | Q30: 0 | R30: 2 | S30: 0 | T30: 0 | V30: 20.545455 | X30: - | Y30: - | AA30: 30 | AB30: 36 | AC30: 42 | AD30: 24 | AE30: 42 | AF30: 24 | AG30: 66 | AH30: 0
